Workbook

Sheet 表紙
B1: 三菱ケミカルグループ（4188） シナリオ財務モデル
B2: 作成 2026-10-30。単位は億円（株数・1株指標を除く）。年度＝翌年3月期（2026年度＝2027年3月期）
B4: 目的
B5: ・会社予算（2026年度）を起点に、SM 本体は会社計画経路（切替で保守経路）とし、半導体材料（合成石英・リソマックス）・Zoox 向け CFRP・石化の再編（丸善千葉停止、水島停止、分社化と他社との合併）の上振れと下振れを数式で積み上げ、2029年度の中期経営計画の達成可否を JSR なし（ケースA）と JSR あり（ケースB）で比べる。 | H5: DESIGN
B6: ・入力は「前提」シートだけ。合併年度（2028／2029）、BM 公正価値の求め方、Zoox 単価、合成石英・リソマックスの基準売上は前提シートで切り替えられる。 | H6: DESIGN
B8: 2029年度の中計達成状況（中計判定シートの数式参照）
B9: 指標 | C9: 目標 | D9: ケースA | E9: ケースB | F9: 判定A | G9: 判定B
B10: =中計判定!B5&"（"&中計判定!C5&"）" -> 売上収益（億円） | C10: =中計判定!D5 -> 45060 | D10: =中計判定!E5 -> 36452.356 | E10: =中計判定!F5 -> 36452.356 | F10: =中計判定!I5 -> 未達 | G10: =中計判定!J5 -> 未達
B11: =中計判定!B6&"（"&中計判定!C6&"）" -> コア営業利益（億円） | C11: =中計判定!D6 -> 4600 | D11: =中計判定!E6 -> 4101.4401 | E11: =中計判定!F6 -> 4234.8575 | F11: =中計判定!I6 -> 未達 | G11: =中計判定!J6 -> 未達
B12: =中計判定!B7&"（"&中計判定!C7&"）" -> EPS（円） | C12: =中計判定!D7 -> 152 | D12: =中計判定!E7 -> 132.74552 | E12: =中計判定!F7 -> 140.03707 | F12: =中計判定!I7 -> 未達 | G12: =中計判定!J7 -> 未達
B13: =中計判定!B8&"（"&中計判定!C8&"）" -> ROIC（%） | C13: =中計判定!D8 -> 0.07 | D13: =中計判定!E8 -> 0.06803135 | E13: =中計判定!F8 -> 0.067379141 | F13: =中計判定!I8 -> 未達 | G13: =中計判定!J8 -> 未達
B14: =中計判定!B9&"（"&中計判定!C9&"）" -> ネットD/E（以下）（倍） | C14: =中計判定!D9 -> 0.8 | D14: =中計判定!E9 -> 0.54899901 | E14: =中計判定!F9 -> 0.67249423 | F14: =中計判定!I9 -> 達成 | G14: =中計判定!J9 -> 達成
B15: ="・ケースA は5項目中"&中計判定!I10&"項目、ケースB は"&中計判定!J10&"項目を達成。JSR コール："&中計判定!F16&"。BM 合併年度："&中計判定!E17&"年度" -> ・ケースA は5項目中1項目、ケースB は1項目を達成。JSR コール：未到達（44.9%で据え置き）。BM 合併年度：2028年度
B17: 主要前提（前提シートの値）
B18: 前提 | C18: 値 | D18: 単位
B19: BM の合併年度（期首） | C19: =前提!$D$25 -> 2028 | D19: 年度
B20: BM 合弁株式の公正価値（1＝倍率法、2＝簿価） | C20: =前提!$D$26 -> 1 | D20: 番号
B21: 合弁 EV の EV/EBITDA 倍率 | C21: =前提!$D$107 -> 6 | D21: 倍
B22: Zoox 1台あたり売上 | C22: =前提!$D$27 -> 1000 | D22: 万円
B23: Zoox 台数（2027年度以降） | C23: =前提!F10 -> 2500 | D23: 台
B24: 合成石英 2026年度売上（基準） | C24: =前提!$D$28 -> 70 | D24: 億円
B25: リソマックス 2026年度売上（基準） | C25: =前提!$D$29 -> 120 | D25: 億円
B26: WFE 成長率（2027年度） | C26: =前提!F9 -> 0.218 | D26: %
B27: SM 本体の基礎コア利益率（2029年度） | C27: =前提!H7 -> 0.088 | D27: %
B28: MMA&D コア営業利益（2029年度） | C28: =前提!H11 -> 160 | D28: 億円
B29: 産業ガス コア営業利益（2029年度） | C29: =前提!H15 -> 2370 | D29: 億円
B30: 税率（会社予想当期利益に較正） | C30: =前提!$D$122 -> 0.27 | D30: %
B31: 金融費用率 | C31: =前提!$D$121 -> 0.02 | D31: %
B32: JSR 株式価値（報道、二次） | C32: =前提!$D$135 -> 10000 | D32: 億円
B33: SM 本体の基礎経路（1＝会社計画、2＝保守） | C33: =前提!$D$30 -> 1 | D33: 番号
B34: 持分法利益の二重課税を除く（1＝除く） | C34: =前提!$D$32 -> 1 | D34: 番号
B35: JSR 第1段の取得比率 | C35: =前提!$D$138 -> 0.2 | D35: %
B36: JSR 持分法の上限 | C36: =前提!$D$139 -> 0.49 | D36: %
B37: JSR 取得の余力の基準（ネットD/E） | C37: =前提!$D$145 -> 0.8 | D37: 倍
B38: ハイブリッド債で調達（1＝する） | C38: =前提!$D$33 -> 0 | D38: 番号
B40: 読むときの注意
B41: ・2027年度の EPS 低下は、非経常▲400（分社化費用込み）と炭素撤退期の BM 赤字（▲120）による。 | H41: DESIGN
B42: ・合併時の除外損（BM の連結除外）は、実務上は合併前の減損として先行計上されうる。計上年度と区分がずれる可能性がある。 | H42: DIR2
B43: ・BM の公正価値（中間 EBITDA×6倍）は資産規模6,000と見合わない。この差そのものが減損リスクである。 | H43: DIR2
B44: ・JSR の取得（ケースB）は、20%取得後、期首ごとにネットD/E 0.8 の余力の範囲で49%まで買い増し、余力が残り代金＋JSR 純有利子負債を上回った年度に全額取得する。ハイブリッド債の扱いは会社で未確認（切替の既定は使わない）。 | H44: DIR2
...

Sheet 前提
B1: 前提（入力はこのシートだけ）
B2: 単位は億円（株数・株価・1株指標を除く）。年度＝翌年3月期（2026年度＝2027年3月期）。青字＝入力。区分：一次／二次／推計／仮定／設計（設計書が置いた値）／切替
B4: 年度別の前提
B5: 項目 | C5: 単位 | D5: 2025年度 | E5: 2026年度 | F5: 2027年度 | G5: 2028年度 | H5: 2029年度 | I5: 2030年度 | J5: 出典ID | K5: 区分 | L5: 備考
B6: 年度（数値） | C6: 年度 | D6: 2025 | E6: 2026 | F6: 2027 | G6: 2028 | H6: 2029 | I6: 2030 | K6: — | L6: 数式の年度判定に使う
B7: SM 本体の基礎コア利益率 | C7: % | E7: 0.073 | F7: 0.078 | G7: 0.083 | H7: 0.088 | I7: 0.09 | J7: DESIGN,M01,M02 | K7: 設計 | L7: 会社中計（新区分2029年度 15,700/1,550、9.9%）より保守的。2026年度は会社予算の900（7.28%）を使い、7.3%は参考表示
B8: ウエハ出荷面積の成長率 | C8: % | F8: 0.06 | G8: 0.06 | H8: 0.05 | I8: 0.05 | J8: SEMI-WAFER,RS-SEMI | K8: 二次 | L8: SEMI 2026-10（2026→29年 年+5.7%）を設計書が年別に配分
B9: WFE（前工程装置）の成長率 | C9: % | F9: 0.218 | G9: 0.141 | H9: 0.05 | I9: 0.03 | J9: SEMI-WFE,DESIGN | K9: 一次（2027〜28）／仮定（2029〜30） | L9: 2027・2028年は SEMI 年央予測。2029・2030年は仮定
B10: Zoox 向け台数 | C10: 台 | E10: 1500 | F10: 2500 | G10: 2500 | H10: 2500 | I10: 2500 | J10: NHTSA-555,QA01,DESIGN | K10: 仮定（上限は二次） | L10: 2026年度1,500台は会社予算に含まれると仮定。2027年度以降は NHTSA 免除上限の年2,500台
B11: MMA&D コア営業利益 | C11: 億円 | E11: 110 | F11: 120 | G11: 140 | H11: 160 | I11: 170 | J11: M03,M08,M42,QA02,DESIGN | K11: 一次（2026）／設計 | L11: 根拠は下の注記（MMA&D）
B12: BM 基礎コア営業利益（市況・稼働率改善前） | C12: 億円 | E12: -50 | F12: -150 | G12: -110 | H12: -90 | I12: -80 | J12: M03,M36,DESIGN | K12: 一次（2026）／設計 | L12: 2028年度で炭素撤退が完了
B13: BM 売上の増減（炭素撤退） | C13: 億円 | F13: -500 | G13: -500 | J13: M36,DESIGN | K13: 設計 | L13: 炭素の下期撤退で2027年度▲500、2028年度▲500
B14: BM 売上の成長率（2029年度以降） | C14: % | H14: -0.02 | I14: -0.02 | J14: DESIGN | K14: 設計
B15: 産業ガス コア営業利益 | C15: 億円 | E15: 2050 | F15: 2150 | G15: 2260 | H15: 2370 | I15: 2480 | J15: M03,G02,DESIGN | K15: 一次（2026）／設計 | L15: 日本酸素 NI2030 の2,500〜2,750より保守的
B16: その他 コア営業利益 | C16: 億円 | E16: 40 | F16: 0 | G16: 0 | H16: 0 | I16: 0 | J16: M03,DESIGN | K16: 一次（2026）／設計
B17: 非経常損益（分社化費用・合併除外損益を除く） | C17: 億円 | E17: -50 | F17: -350 | G17: -400 | H17: -300 | I17: -300 | J17: M03,DESIGN | K17: 一次（2026）／設計 | L17: 設計書の2027年度▲400は分社化費用▲50込み。ここでは▲350＋分社化費用（下の単一値）に分けた
B18: 設備投資（BM 控除前。合併年度以降▲280） | C18: 億円 | E18: 3391 | F18: 3300 | G18: 3200 | H18: 3000 | I18: 3000 | J18: M03,DESIGN | K18: 一次（2026）／設計 | L18: 合併年度以降は BM 分を控除（単一値）
B19: 減価償却（2028年度以降は BM 分を除いた後の値） | C19: 億円 | E19: 2794 | F19: 2850 | G19: 2600 | H19: 2650 | I19: 2700 | J19: M03,DESIGN,DIR2 | K19: 一次（2026）／設計 | L19: 2028年度以降の列は BM 控除後。合併年度を2029にすると、2028年度に BM 分270を足し戻す
B20: JSR コア営業利益（基礎、フォトレジスト上振れ前） | C20: 億円 | E20: 600 | F20: 680 | G20: 760 | H20: 840 | I20: 920 | J20: JSR-YUHO,DESIGN | K20: 設計 | L20: 2025年度 405＋減損116＝521から成長。2030年までにコア1,000の目標を8%割引
B21: 注1：MMA&D の経路（110→170）の根拠：中国の能力が年16%増（2021〜25年）で需要を上回る。欧州撤退で生産が中国へ移り、地域分断で約30%シェアの事業モデルが崩れたと会社自身が認める（M08）。ルイジアナ新工場は長期契約が取れず2025年1月に中止（M42）。価格は紛争前1,400ドル弱→足元1,600〜1,700ドルだが中東要因の一時性が高い（QA02・QA01）。サウジ停止・台湾売却で当社能力も縮む。中計の MMA 450（利益率14%）には遠い。
B23: 切替（感応度・シナリオ）
B24: 項目 | C24: 単位 | D24: 値 | J24: 出典ID | K24: 区分 | L24: 備考
B25: BM の他社との合併年度（期首。2028 または 2029） | C25: 年度 | D25: 2028 | J25: DESIGN | K25: 切替 | L25: IF で連結範囲・持分法・除外損益・設備投資控除が切り替わる
B26: BM 合弁株式の公正価値の求め方（1＝倍率法、2＝簿価） | C26: 番号 | D26: 1 | J26: DESIGN | K26: 切替 | L26: 2＝簿価は再測定損益ゼロの比較用（追加の仮定）
B27: Zoox 1台あたり売上 | C27: 万円 | D27: 1000 | J27: RS-ZOOX,M01,DESIGN | K27: 推計 | L27: 幅600〜1,600万円。1Q のサブセグメント増収+102億円と生産ペースからの逆算
B28: 合成石英 2026年度売上（基準） | C28: 億円 | D28: 70 | J28: RS-SEMI,DESIGN | K28: 仮定 | L28: 開示なし。推計幅30〜150
B29: リソマックス 2026年度売上（基準） | C29: 億円 | D29: 120 | J29: RS-SEMI,DESIGN | K29: 仮定 | L29: 開示なし。幅60〜200
B30: SM 本体の基礎経路（1＝会社計画、2＝保守経路） | C30: 番号 | D30: 1 | J30: DIR2,M01,M02 | K30: 切替 | L30: 会社計画：2029年度 15,700/1,550 へ線形。保守：+4%/年・利益率7.8〜9.0%
B31: JSR 全額取得年度の上書き（0＝自動判定） | C31: 年度 | D31: 0 | J31: DIR2 | K31: 切替（追加） | L31: 0 以外を入れるとその年度の期首に残り全株を取得（比較用）
B32: 持分法利益への法人税の二重課税を除く（1＝除く、0＝設計書の当初式） | C32: 番号 | D32: 1 | J32: DIR2 | K32: 切替 | L32: 持分法利益は税後の値なので連結の27%を掛けない。ROIC の分子も（コア−持分法）×(1−30%)＋持分法
B33: JSR 取得資金をハイブリッド債で一部調達（0＝しない、1＝する） | C33: 番号 | D33: 0 | J33: DIR2 | K33: 切替（仮定） | L33: 会社のハイブリッド債の扱い（発行有無・資本性評価）は未確認（M01・M03・M24・M15 を検索して記載なし）
B34: 2026年度 会社予算（セグメント、M03 p20）
B35: 項目 | C35: 単位 | D35: 値 | J35: 出典ID | K35: 区分 | L35: 備考
B36: スペシャリティ（SM）売上 | C36: 億円 | D36: 12370 | J36: M03 | K36: 一次
B37: スペシャリティ（SM）コア営業利益 | C37: 億円 | D37: 900 | J37: M03 | K37: 一次
B38: MMA&D 売上 | C38: 億円 | D38: 3490 | J38: M03 | K38: 一次
B39: ベーシック（BM）売上 | C39: 億円 | D39: 6830 | J39: M03 | K39: 一次
B40: その他 売上 | C40: 億円 | D40: 1590 | J40: M03 | K40: 一次
B41: 産業ガス 売上 | C41: 億円 | D41: 13720 | J41: M03 | K41: 一次
B42: 会社予算 売上合計 | C42: 億円 | D42: 38000 | J42: M03 | K42: 一次 | L42: 検証用
...

Sheet D_半導体
B1: D_半導体（合成石英・リソマックス）
B2: 上振れは「会社計画経路に対する増分」。2026年度は計画と同じ（上振れゼロ）
B4: 項目 | C4: 単位 | D4: 2025年度 | E4: 2026年度 | F4: 2027年度 | G4: 2028年度 | H4: 2029年度 | I4: 2030年度 | J4: 出所・算式
B5: 合成石英
B6: ウエハ出荷面積の成長率 | C6: % | F6: =前提!F8 -> 0.06 | G6: =前提!G8 -> 0.06 | H6: =前提!H8 -> 0.05 | I6: =前提!I8 -> 0.05 | J6: SEMI-WAFER
B7: WFE の成長率 | C7: % | F7: =前提!F9 -> 0.218 | G7: =前提!G9 -> 0.141 | H7: =前提!H9 -> 0.05 | I7: =前提!I9 -> 0.03 | J7: SEMI-WFE（2029〜30は仮定）
B8: 需要の成長率 | C8: % | F8: =F6+前提!$D$61*F7 -> 0.1145 | G8: =G6+前提!$D$61*G7 -> 0.09525 | H8: =H6+前提!$D$61*H7 -> 0.0625 | I8: =I6+前提!$D$61*I7 -> 0.0575 | J8: ウエハ面積成長＋係数×WFE 成長
B9: 需要指数（2026年度＝1） | C9: 指数 | E9: =前提!$D$62 -> 1 | F9: =E9*(1+F8) -> 1.1145 | G9: =F9*(1+G8) -> 1.2206561 | H9: =G9*(1+H8) -> 1.2969471 | I9: =H9*(1+I8) -> 1.3715216 | J9: 前年×(1＋需要の成長率)
B10: 能力指数 | C10: 指数 | E10: =前提!$D$62+IF(前提!E$6>=前提!$D$64,前提!$D$63,0)+IF(前提!E$6=前提!$D$66,前提!$D$65*前提!$D$67,IF(前提!E$6>前提!$D$66,前提!$D$65,0)) -> 1 | F10: =前提!$D$62+IF(前提!F$6>=前提!$D$64,前提!$D$63,0)+IF(前提!F$6=前提!$D$66,前提!$D$65*前提!$D$67,IF(前提!F$6>前提!$D$66,前提!$D$65,0)) -> 1.05 | G10: =前提!$D$62+IF(前提!G$6>=前提!$D$64,前提!$D$63,0)+IF(前提!G$6=前提!$D$66,前提!$D$65*前提!$D$67,IF(前提!G$6>前提!$D$66,前提!$D$65,0)) -> 1.225 | H10: =前提!$D$62+IF(前提!H$6>=前提!$D$64,前提!$D$63,0)+IF(前提!H$6=前提!$D$66,前提!$D$65*前提!$D$67,IF(前提!H$6>前提!$D$66,前提!$D$65,0)) -> 1.4 | I10: =前提!$D$62+IF(前提!I$6>=前提!$D$64,前提!$D$63,0)+IF(前提!I$6=前提!$D$66,前提!$D$65*前提!$D$67,IF(前提!I$6>前提!$D$66,前提!$D$65,0)) -> 1.4 | J10: 2026＝1.00、小改良＋0.05、2028年9月稼働の+0.35は初年度半分
B11: 数量指数 | C11: 指数 | E11: =MIN(E9,E10) -> 1 | F11: =MIN(F9,F10) -> 1.05 | G11: =MIN(G9,G10) -> 1.2206561 | H11: =MIN(H9,H10) -> 1.2969471 | I11: =MIN(I9,I10) -> 1.3715216 | J11: MIN(需要, 能力)
B12: 価格指数 | C12: 指数 | E12: =(1+前提!$D$68)^(前提!E$6-前提!E$6) -> 1 | F12: =(1+前提!$D$68)^(前提!F$6-前提!E$6) -> 1.04 | G12: =(1+前提!$D$68)^(前提!G$6-前提!E$6) -> 1.0816 | H12: =(1+前提!$D$68)^(前提!H$6-前提!E$6) -> 1.124864 | I12: =(1+前提!$D$68)^(前提!I$6-前提!E$6) -> 1.1698586 | J12: +4%/年
B13: 当社経路の売上 | C13: 億円 | E13: =前提!$D$28*E11*E12 -> 70 | F13: =前提!$D$28*F11*F12 -> 76.44 | G13: =前提!$D$28*G11*G12 -> 92.418317 | H13: =前提!$D$28*H11*H12 -> 102.12224 | I13: =前提!$D$28*I11*I12 -> 112.31404 | J13: 基準売上×数量指数×価格指数
B14: 会社計画経路の売上 | C14: 億円 | E14: =前提!$D$28*(1+前提!$D$60)^(前提!E$6-前提!E$6) -> 70 | F14: =前提!$D$28*(1+前提!$D$60)^(前提!F$6-前提!E$6) -> 75.39 | G14: =前提!$D$28*(1+前提!$D$60)^(前提!G$6-前提!E$6) -> 81.19503 | H14: =前提!$D$28*(1+前提!$D$60)^(前提!H$6-前提!E$6) -> 87.447047 | I14: =前提!$D$28*(1+前提!$D$60)^(前提!I$6-前提!E$6) -> 94.18047 | J14: M02 p36（+7.7%/年）
B15: 上振れ売上（当社−計画） | C15: 億円 | E15: =E13-E14 -> 0 | F15: =F13-F14 -> 1.05 | G15: =G13-G14 -> 11.223287 | H15: =H13-H14 -> 14.675192 | I15: =I13-I14 -> 18.133569
B16: 上振れコア利益（限界利益率） | C16: 億円 | E16: =E15*前提!$D$69 -> 0 | F16: =F15*前提!$D$69 -> 0.4725 | G16: =G15*前提!$D$69 -> 5.0504789 | H16: =H15*前提!$D$69 -> 6.6038366 | I16: =I15*前提!$D$69 -> 8.1601062 | J16: 売上差×45%
B17: 取り逃し需要（能力超過分の売上） | C17: 億円 | E17: =MAX(0,E9-E10)*前提!$D$28*E12 -> 0 | F17: =MAX(0,F9-F10)*前提!$D$28*F12 -> 4.6956 | G17: =MAX(0,G9-G10)*前提!$D$28*G12 -> 0 | H17: =MAX(0,H9-H10)*前提!$D$28*H12 -> 0 | I17: =MAX(0,I9-I10)*前提!$D$28*I12 -> 0
B18: 参考：当社経路のコア利益（利益率20%） | C18: 億円 | E18: =E13*前提!$D$59 -> 14 | F18: =F13*前提!$D$59 -> 15.288 | G18: =G13*前提!$D$59 -> 18.483663 | H18: =H13*前提!$D$59 -> 20.424448 | I18: =I13*前提!$D$59 -> 22.462808
B20: リソマックス
B21: EUV・先端ミックスの上乗せ | C21: % | F21: =IF(前提!F$6>=前提!$D$75,前提!$D$74,0) -> 0.03 | G21: =IF(前提!G$6>=前提!$D$75,前提!$D$74,0) -> 0.03 | H21: =IF(前提!H$6>=前提!$D$75,前提!$D$74,0) -> 0.03 | I21: =IF(前提!I$6>=前提!$D$75,前提!$D$74,0) -> 0.03 | J21: 2027年度から+3pt（福岡 EUV 新設）
B22: 当社経路の成長率 | C22: % | F22: =F6+F21+前提!$D$76*F7 -> 0.1336 | G22: =G6+G21+前提!$D$76*G7 -> 0.1182 | H22: =H6+H21+前提!$D$76*H7 -> 0.09 | I22: =I6+I21+前提!$D$76*I7 -> 0.086 | J22: ウエハ面積成長＋ミックス＋0.20×WFE 成長
B23: 当社経路の売上 | C23: 億円 | E23: =前提!$D$29 -> 120 | F23: =E23*(1+F22) -> 136.032 | G23: =F23*(1+G22) -> 152.11098 | H23: =G23*(1+H22) -> 165.80097 | I23: =H23*(1+I22) -> 180.05985
B24: 会社計画経路の売上 | C24: 億円 | E24: =前提!$D$29*(1+前提!$D$73)^(前提!E$6-前提!E$6) -> 120 | F24: =前提!$D$29*(1+前提!$D$73)^(前提!F$6-前提!E$6) -> 128.4 | G24: =前提!$D$29*(1+前提!$D$73)^(前提!G$6-前提!E$6) -> 137.388 | H24: =前提!$D$29*(1+前提!$D$73)^(前提!H$6-前提!E$6) -> 147.00516 | I24: =前提!$D$29*(1+前提!$D$73)^(前提!I$6-前提!E$6) -> 157.29552 | J24: +7%/年
B25: 上振れ売上（当社−計画） | C25: 億円 | E25: =E23-E24 -> 0 | F25: =F23-F24 -> 7.632 | G25: =G23-G24 -> 14.722982 | H25: =H23-H24 -> 18.795811 | I25: =I23-I24 -> 22.764333
B26: 上振れコア利益（限界利益率） | C26: 億円 | E26: =E25*前提!$D$77 -> 0 | F26: =F25*前提!$D$77 -> 2.6712 | G26: =G25*前提!$D$77 -> 5.1530438 | H26: =H25*前提!$D$77 -> 6.5785338 | I26: =I25*前提!$D$77 -> 7.9675166 | J26: 売上差×35%
B27: 参考：当社経路のコア利益（利益率15%） | C27: 億円 | E27: =E23*前提!$D$72 -> 18 | F27: =F23*前提!$D$72 -> 20.4048 | G27: =G23*前提!$D$72 -> 22.816647 | H27: =H23*前提!$D$72 -> 24.870146 | I27: =I23*前提!$D$72 -> 27.008978
B28: 注1：合成石英・リソマックスの売上と利益は会社の開示が無い。基準売上（70・120）は感応度用の仮定で、前提シートで変えられる。
B29: 注2：WFE とウエハ面積は暦年の値を年度に当てている（設計書どおり）。

Sheet D_Zoox
B1: D_Zoox（Zoox 向け CFRP）
B2: 上振れ＝(台数−会社予算に含まれる1,500台)×1台売上
B4: 項目 | C4: 単位 | D4: 2025年度 | E4: 2026年度 | F4: 2027年度 | G4: 2028年度 | H4: 2029年度 | I4: 2030年度 | J4: 出所・算式
B5: 台数 | C5: 台 | E5: =前提!E10 -> 1500 | F5: =前提!F10 -> 2500 | G5: =前提!G10 -> 2500 | H5: =前提!H10 -> 2500 | I5: =前提!I10 -> 2500 | J5: NHTSA-555（上限）・仮定
B6: 会社予算に含まれる台数 | C6: 台 | E6: =前提!$D$80 -> 1500 | F6: =前提!$D$80 -> 1500 | G6: =前提!$D$80 -> 1500 | H6: =前提!$D$80 -> 1500 | I6: =前提!$D$80 -> 1500 | J6: 仮定
B7: 1台あたり売上 | C7: 億円/台 | E7: =前提!$D$27/10000 -> 0.1 | F7: =前提!$D$27/10000 -> 0.1 | G7: =前提!$D$27/10000 -> 0.1 | H7: =前提!$D$27/10000 -> 0.1 | I7: =前提!$D$27/10000 -> 0.1 | J7: 1,000万円（推計）
B8: 参考：Zoox 向け売上 | C8: 億円 | E8: =E5*E7 -> 150 | F8: =F5*F7 -> 250 | G8: =G5*G7 -> 250 | H8: =H5*H7 -> 250 | I8: =I5*I7 -> 250
B9: 上振れ売上 | C9: 億円 | E9: =(E5-E6)*E7 -> 0 | F9: =(F5-F6)*F7 -> 100 | G9: =(G5-G6)*G7 -> 100 | H9: =(H5-H6)*H7 -> 100 | I9: =(I5-I6)*I7 -> 100
B10: 上振れコア利益 | C10: 億円 | E10: =E9*前提!$D$81 -> 0 | F10: =F9*前提!$D$81 -> 15 | G10: =G9*前提!$D$81 -> 15 | H10: =H9*前提!$D$81 -> 15 | I10: =I9*前提!$D$81 -> 15 | J10: 売上差×15%
B11: 注1：年2,500台は工場能力ではなく NHTSA の免除上限（二次。年か累計かは一次で未確定）。

Sheet D_石化
B1: D_石化（ベーシック、当社単体ベース＝合併前）
B2: 丸善千葉停止・水島停止の効果を基礎経路に足す。合併後の連結範囲は「分社化・合併」シート
B4: 項目 | C4: 単位 | D4: 2025年度 | E4: 2026年度 | F4: 2027年度 | G4: 2028年度 | H4: 2029年度 | I4: 2030年度 | J4: 出所・算式
B5: 基礎コア営業利益 | C5: 億円 | E5: =前提!E12 -> -50 | F5: =前提!F12 -> -150 | G5: =前提!G12 -> -110 | H5: =前提!H12 -> -90 | I5: =前提!I12 -> -80 | J5: 設計
B6: 売上/千t（2025年度） | C6: 億円/千t | E6: =前提!$D$85/前提!$D$86 -> 9.3993453 | F6: =前提!$D$85/前提!$D$86 -> 9.3993453 | G6: =前提!$D$85/前提!$D$86 -> 9.3993453 | H6: =前提!$D$85/前提!$D$86 -> 9.3993453 | I6: =前提!$D$85/前提!$D$86 -> 9.3993453 | J6: 5,743÷611
B7: 稼働率1ptあたり利益 | C7: 億円/pt | E7: =前提!$D$84*0.01*E6*前提!$D$87 -> 5.0613595 | F7: =前提!$D$84*0.01*F6*前提!$D$87 -> 5.0613595 | G7: =前提!$D$84*0.01*G6*前提!$D$87 -> 5.0613595 | H7: =前提!$D$84*0.01*H6*前提!$D$87 -> 5.0613595 | I7: =前提!$D$84*0.01*I6*前提!$D$87 -> 5.0613595 | J7: 848千t×1%×売上/千t×限界利益率6.35%
B8: 丸善千葉停止（稼働率+6pt） | C8: 億円 | E8: =IF(前提!E$6>=前提!$D$89,前提!$D$88*E7,0) -> 0 | F8: =IF(前提!F$6>=前提!$D$89,前提!$D$88*F7,0) -> 30.368157 | G8: =IF(前提!G$6>=前提!$D$89,前提!$D$88*G7,0) -> 30.368157 | H8: =IF(前提!H$6>=前提!$D$89,前提!$D$88*H7,0) -> 30.368157 | I8: =IF(前提!I$6>=前提!$D$89,前提!$D$88*I7,0) -> 30.368157 | J8: 2027年度から
B9: 水島停止：固定費削減 | C9: 億円 | E9: =IF(前提!E$6>=前提!$D$94,前提!$D$90*前提!$D$91,0) -> 0 | F9: =IF(前提!F$6>=前提!$D$94,前提!$D$90*前提!$D$91,0) -> 0 | G9: =IF(前提!G$6>=前提!$D$94,前提!$D$90*前提!$D$91,0) -> 0 | H9: =IF(前提!H$6>=前提!$D$94,前提!$D$90*前提!$D$91,0) -> 0 | I9: =IF(前提!I$6>=前提!$D$94,前提!$D$90*前提!$D$91,0) -> 80 | J9: 160×50%
B10: 水島停止：残存設備の稼働率上昇 | C10: 億円 | E10: =IF(前提!E$6>=前提!$D$94,前提!$D$92*E7,0) -> 0 | F10: =IF(前提!F$6>=前提!$D$94,前提!$D$92*F7,0) -> 0 | G10: =IF(前提!G$6>=前提!$D$94,前提!$D$92*G7,0) -> 0 | H10: =IF(前提!H$6>=前提!$D$94,前提!$D$92*H7,0) -> 0 | I10: =IF(前提!I$6>=前提!$D$94,前提!$D$92*I7,0) -> 20.245438 | J10: +4pt×1pt利益
B11: 水島停止：能力減による限界利益減 | C11: 億円 | E11: =IF(前提!E$6>=前提!$D$94,-前提!$D$84*前提!$D$93*E6*前提!$D$87,0) -> 0 | F11: =IF(前提!F$6>=前提!$D$94,-前提!$D$84*前提!$D$93*F6*前提!$D$87,0) -> 0 | G11: =IF(前提!G$6>=前提!$D$94,-前提!$D$84*前提!$D$93*G6*前提!$D$87,0) -> 0 | H11: =IF(前提!H$6>=前提!$D$94,-前提!$D$84*前提!$D$93*H6*前提!$D$87,0) -> 0 | I11: =IF(前提!I$6>=前提!$D$94,-前提!$D$84*前提!$D$93*I6*前提!$D$87,0) -> -35.429516 | J11: −848千t×7%×売上/千t×6.35%
B12: 水島停止の効果 計 | C12: 億円 | E12: =E9+E10+E11 -> 0 | F12: =F9+F10+F11 -> 0 | G12: =G9+G10+G11 -> 0 | H12: =H9+H10+H11 -> 0 | I12: =I9+I10+I11 -> 64.815922
B13: BM コア営業利益（当社単体ベース） | C13: 億円 | E13: =E5+E8+E12 -> -50 | F13: =F5+F8+F12 -> -119.63184 | G13: =G5+G8+G12 -> -79.631843 | H13: =H5+H8+H12 -> -59.631843 | I13: =I5+I8+I12 -> 15.184078
B14: BM 売上（当社単体ベース） | C14: 億円 | E14: =前提!$D$39 -> 6830 | F14: =E14*(1+前提!F14)+前提!F13 -> 6330 | G14: =F14*(1+前提!G14)+前提!G13 -> 5830 | H14: =G14*(1+前提!H14)+前提!H13 -> 5713.4 | I14: =H14*(1+前提!I14)+前提!I13 -> 5599.132 | J14: 2027・2028年度は炭素撤退で各▲500、以後▲2%/年
B15: 注1：限界利益率・固定費はクラサス単体の原価明細で代用（MCG は未開示。代替宣言は前提シート）。
B16: 注2：合併後は、この単体ベースの BM コアが合弁利益の算定に使われる（合弁利益＝単体 BM コア×2＋統合効果）。

Sheet D_JSR
B1: D_JSR（ケースBのみ）
B2: 取得年度の下期に20%を取得（持分法）。2028〜30年度の各期首に、余力の範囲で49%まで追加取得（コール）。49%到達後、余力が残り株式の代金＋JSR 純有利子負債以上になった最初の年度に全額取得（連結）。満たさなければ49%で据え置き
B4: 項目 | C4: 単位 | D4: 2025年度 | E4: 2026年度 | F4: 2027年度 | G4: 2028年度 | H4: 2029年度 | I4: 2030年度 | J4: 出所・算式
B5: JSR の業績とフォトレジスト上振れ
B6: JSR 売上（基礎） | C6: 億円 | E6: =前提!$D$149*(1+前提!$D$150)^(前提!E$6-前提!D$6) -> 4715.49 | F6: =前提!$D$149*(1+前提!$D$150)^(前提!F$6-前提!D$6) -> 5045.5743 | G6: =前提!$D$149*(1+前提!$D$150)^(前提!G$6-前提!D$6) -> 5398.7645 | H6: =前提!$D$149*(1+前提!$D$150)^(前提!H$6-前提!D$6) -> 5776.678 | I6: =前提!$D$149*(1+前提!$D$150)^(前提!I$6-前提!D$6) -> 6181.0455 | J6: 4,407×1.07^n
B7: 電子材料売上（基礎、+10%/年） | C7: 億円 | E7: =前提!$D$153*(1+前提!$D$154)^(前提!E$6-前提!D$6) -> 2156 | F7: =前提!$D$153*(1+前提!$D$154)^(前提!F$6-前提!D$6) -> 2371.6 | G7: =前提!$D$153*(1+前提!$D$154)^(前提!G$6-前提!D$6) -> 2608.76 | H7: =前提!$D$153*(1+前提!$D$154)^(前提!H$6-前提!D$6) -> 2869.636 | I7: =前提!$D$153*(1+前提!$D$154)^(前提!I$6-前提!D$6) -> 3156.5996
B8: 電子材料の当社経路の成長率 | C8: % | E8: =前提!$D$154 -> 0.1 | F8: =前提!F8+前提!$D$155*前提!F9+前提!$D$156 -> 0.1563 | G8: =前提!G8+前提!$D$155*前提!G9+前提!$D$156 -> 0.12935 | H8: =前提!H8+前提!$D$155*前提!H9+前提!$D$156 -> 0.0875 | I8: =前提!I8+前提!$D$155*前提!I9+前提!$D$156 -> 0.0805 | J8: ウエハ面積＋0.35×WFE＋EUV 2pt（2026は基礎と同じ）
B9: 電子材料売上（当社経路） | C9: 億円 | E9: =前提!$D$153*(1+E8) -> 2156 | F9: =E9*(1+F8) -> 2492.9828 | G9: =F9*(1+G8) -> 2815.4501 | H9: =G9*(1+H8) -> 3061.802 | I9: =H9*(1+I8) -> 3308.2771
B10: 電子材料の上振れ売上 | C10: 億円 | E10: =E9-E7 -> 0 | F10: =F9-F7 -> 121.3828 | G10: =G9-G7 -> 206.69013 | H10: =H9-H7 -> 192.16601 | I10: =I9-I7 -> 151.67747
B11: フォトレジスト上振れ（コア） | C11: 億円 | E11: =E10*前提!$D$157 -> 0 | F11: =F10*前提!$D$157 -> 36.41484 | G11: =G10*前提!$D$157 -> 62.007038 | H11: =H10*前提!$D$157 -> 57.649803 | I11: =I10*前提!$D$157 -> 45.503242 | J11: 差分×30%
B12: JSR コア営業利益（基礎） | C12: 億円 | E12: =前提!E20 -> 600 | F12: =前提!F20 -> 680 | G12: =前提!G20 -> 760 | H12: =前提!H20 -> 840 | I12: =前提!I20 -> 920
B13: JSR コア営業利益（上振れ込み） | C13: 億円 | E13: =E12+E11 -> 600 | F13: =F12+F11 -> 716.41484 | G13: =G12+G11 -> 822.00704 | H13: =H12+H11 -> 897.6498 | I13: =I12+I11 -> 965.50324
B14: JSR 売上（上振れ込み） | C14: 億円 | E14: =E6+E10 -> 4715.49 | F14: =F6+F10 -> 5166.9571 | G14: =G6+G10 -> 5605.4546 | H14: =H6+H10 -> 5968.844 | I14: =I6+I10 -> 6332.723 | J14: 上振れ売上も加える（追加の仮定）
B16: 取得の判定（期首、前期末のケースB の BS で判定）
B17: 第1段 取得年度フラグ | E17: =IF(前提!E$6=前提!$D$140,1,0) -> 0 | F17: =IF(前提!F$6=前提!$D$140,1,0) -> 1 | G17: =IF(前提!G$6=前提!$D$140,1,0) -> 0 | H17: =IF(前提!H$6=前提!$D$140,1,0) -> 0 | I17: =IF(前提!I$6=前提!$D$140,1,0) -> 0
B18: 保有フラグ | E18: =IF(前提!E$6>=前提!$D$140,1,0) -> 0 | F18: =IF(前提!F$6>=前提!$D$140,1,0) -> 1 | G18: =IF(前提!G$6>=前提!$D$140,1,0) -> 1 | H18: =IF(前提!H$6>=前提!$D$140,1,0) -> 1 | I18: =IF(前提!I$6>=前提!$D$140,1,0) -> 1
B19: コール行使可能期間フラグ（各期首） | E19: =IF(AND(前提!E$6>=前提!$D$143,前提!E$6<=前提!$D$144),1,0) -> 0 | F19: =IF(AND(前提!F$6>=前提!$D$143,前提!F$6<=前提!$D$144),1,0) -> 0 | G19: =IF(AND(前提!G$6>=前提!$D$143,前提!G$6<=前提!$D$144),1,0) -> 1 | H19: =IF(AND(前提!H$6>=前提!$D$143,前提!H$6<=前提!$D$144),1,0) -> 1 | I19: =IF(AND(前提!I$6>=前提!$D$143,前提!I$6<=前提!$D$144),1,0) -> 1
B20: 行使価格（100%分の株式価値） | C20: 億円 | E20: =前提!$D$135*(1+前提!$D$142)^MAX(0,前提!E$6-前提!$D$140) -> 10000 | F20: =前提!$D$135*(1+前提!$D$142)^MAX(0,前提!F$6-前提!$D$140) -> 10000 | G20: =前提!$D$135*(1+前提!$D$142)^MAX(0,前提!G$6-前提!$D$140) -> 10300 | H20: =前提!$D$135*(1+前提!$D$142)^MAX(0,前提!H$6-前提!$D$140) -> 10609 | I20: =前提!$D$135*(1+前提!$D$142)^MAX(0,前提!I$6-前提!$D$140) -> 10927.27 | J20: 1兆×(1+3%)^経過年数
B21: ハイブリッド債で調達する比率 | C21: % | E21: =前提!$D$33*前提!$D$146 -> 0 | F21: =前提!$D$33*前提!$D$146 -> 0 | G21: =前提!$D$33*前提!$D$146 -> 0 | H21: =前提!$D$33*前提!$D$146 -> 0 | I21: =前提!$D$33*前提!$D$146 -> 0 | J21: 切替0なら0%
B22: 取得額のうち資本扱いになる割合 | C22: % | E22: =E21*前提!$D$147 -> 0 | F22: =F21*前提!$D$147 -> 0 | G22: =G21*前提!$D$147 -> 0 | H22: =H21*前提!$D$147 -> 0 | I22: =I21*前提!$D$147 -> 0
B23: 0.8 の余力（0.8×前期末親会社持分−前期末純有利子負債） | C23: 億円 | E23: =前提!$D$145*連結BS!D45-連結BS!D44 -> -554.4 | F23: =前提!$D$145*連結BS!E45-連結BS!E44 -> 757.14679 | G23: =前提!$D$145*連結BS!F45-連結BS!F44 -> 31.108804 | H23: =前提!$D$145*連結BS!G45-連結BS!G44 -> 276.97324 | I23: =前提!$D$145*連結BS!H45-連結BS!H44 -> 2402.7571 | J23: ハイブリッド債があれば資本性調整後の値で計算
B24: 余力で取得できる額 | C24: 億円 | E24: =MAX(0,E23)/(1-(1+前提!$D$145)*E22) -> 0 | F24: =MAX(0,F23)/(1-(1+前提!$D$145)*F22) -> 757.14679 | G24: =MAX(0,G23)/(1-(1+前提!$D$145)*G22) -> 31.108804 | H24: =MAX(0,H23)/(1-(1+前提!$D$145)*H22) -> 276.97324 | I24: =MAX(0,I23)/(1-(1+前提!$D$145)*I22) -> 2402.7571 | J24: 余力÷(1−(1+0.8)×資本扱い割合)。切替0なら余力そのもの
B25: 全額取得の自動判定（49%到達済み・余力≧残り代金＋JSR 純有利子負債） | E25: =IF(AND(E19=1,N(D29)=0,N(D28)>=前提!$D$139-0.000001,E23>=(1-N(D28))*E20*(1-(1+前提!$D$145)*E22)+前提!$D$136),1,0) -> 0 | F25: =IF(AND(F19=1,N(E29)=0,N(E28)>=前提!$D$139-0.000001,F23>=(1-N(E28))*F20*(1-(1+前提!$D$145)*F22)+前提!$D$136),1,0) -> 0 | G25: =IF(AND(G19=1,N(F29)=0,N(F28)>=前提!$D$139-0.000001,G23>=(1-N(F28))*G20*(1-(1+前提!$D$145)*G22)+前提!$D$136),1,0) -> 0 | H25: =IF(AND(H19=1,N(G29)=0,N(G28)>=前提!$D$139-0.000001,H23>=(1-N(G28))*H20*(1-(1+前提!$D$145)*H22)+前提!$D$136),1,0) -> 0 | I25: =IF(AND(I19=1,N(H29)=0,N(H28)>=前提!$D$139-0.000001,I23>=(1-N(H28))*I20*(1-(1+前提!$D$145)*I22)+前提!$D$136),1,0) -> 0
B26: 全額取得（期首、連結開始） | E26: =IF(前提!$D$31>0,IF(AND(前提!E$6=前提!$D$31,N(D29)=0,N(D28)>0),1,0),E25) -> 0 | F26: =IF(前提!$D$31>0,IF(AND(前提!F$6=前提!$D$31,N(E29)=0,N(E28)>0),1,0),F25) -> 0 | G26: =IF(前提!$D$31>0,IF(AND(前提!G$6=前提!$D$31,N(F29)=0,N(F28)>0),1,0),G25) -> 0 | H26: =IF(前提!$D$31>0,IF(AND(前提!H$6=前提!$D$31,N(G29)=0,N(G28)>0),1,0),H25) -> 0 | I26: =IF(前提!$D$31>0,IF(AND(前提!I$6=前提!$D$31,N(H29)=0,N(H28)>0),1,0),I25) -> 0 | J26: 前提の上書きが0なら自動判定
B27: 追加取得の持分（期首、49%まで） | C27: % | E27: =IF(AND(E19=1,N(D29)=0,E26=0,N(D28)>0),MIN(MAX(0,前提!$D$139-N(D28)),E24/E20),0) -> 0 | F27: =IF(AND(F19=1,N(E29)=0,F26=0,N(E28)>0),MIN(MAX(0,前提!$D$139-N(E28)),F24/F20),0) -> 0 | G27: =IF(AND(G19=1,N(F29)=0,G26=0,N(F28)>0),MIN(MAX(0,前提!$D$139-N(F28)),G24/G20),0) -> 0.0030202722 | H27: =IF(AND(H19=1,N(G29)=0,H26=0,N(G28)>0),MIN(MAX(0,前提!$D$139-N(G28)),H24/H20),0) -> 0.026107385 | I27: =IF(AND(I19=1,N(H29)=0,I26=0,N(H28)>0),MIN(MAX(0,前提!$D$139-N(H28)),I24/I20),0) -> 0.21988631 | J27: MIN(49%−前期末持分, 取得できる額÷行使価格)
B28: 持分比率（期末） | C28: % | E28: =IF(E26=1,1,N(D28)+E17*前提!$D$138+E27) -> 0 | F28: =IF(F26=1,1,N(E28)+F17*前提!$D$138+F27) -> 0.2 | G28: =IF(G26=1,1,N(F28)+G17*前提!$D$138+G27) -> 0.20302027 | H28: =IF(H26=1,1,N(G28)+H17*前提!$D$138+H27) -> 0.22912766 | I28: =IF(I26=1,1,N(H28)+I17*前提!$D$138+I27) -> 0.44901397
B29: 連結フラグ | E29: =MAX(N(D29),E26) -> 0 | F29: =MAX(N(E29),F26) -> 0 | G29: =MAX(N(F29),G26) -> 0 | H29: =MAX(N(G29),H26) -> 0 | I29: =MAX(N(H29),I26) -> 0
B31: 支払額と資金調達
B32: 第1段の取得額（下期） | C32: 億円 | E32: =E17*前提!$D$138*E20 -> 0 | F32: =F17*前提!$D$138*F20 -> 2000 | G32: =G17*前提!$D$138*G20 -> 0 | H32: =H17*前提!$D$138*H20 -> 0 | I32: =I17*前提!$D$138*I20 -> 0 | J32: 1兆×20%
B33: 追加取得額（期首） | C33: 億円 | E33: =E27*E20 -> 0 | F33: =F27*F20 -> 0 | G33: =G27*G20 -> 31.108804 | H33: =H27*H20 -> 276.97324 | I33: =I27*I20 -> 2402.7571
B34: 全額取得の代金（期首、残り株式） | C34: 億円 | E34: =E26*(1-N(D28))*E20 -> 0 | F34: =F26*(1-N(E28))*F20 -> 0 | G34: =G26*(1-N(F28))*G20 -> 0 | H34: =H26*(1-N(G28))*H20 -> 0 | I34: =I26*(1-N(H28))*I20 -> 0
B35: 持分法投資への払込（第1段＋追加取得） | C35: 億円 | E35: =E32+E33 -> 0 | F35: =F32+F33 -> 2000 | G35: =G32+G33 -> 31.108804 | H35: =H32+H33 -> 276.97324 | I35: =I32+I33 -> 2402.7571
B36: 支払額 計 | C36: 億円 | E36: =E35+E34 -> 0 | F36: =F35+F34 -> 2000 | G36: =G35+G34 -> 31.108804 | H36: =H35+H34 -> 276.97324 | I36: =I35+I34 -> 2402.7571
B37: うちハイブリッド債による調達 | C37: 億円 | E37: =E36*E21 -> 0 | F37: =F36*F21 -> 0 | G37: =G36*G21 -> 0 | H37: =H36*H21 -> 0 | I37: =I36*I21 -> 0
B38: ハイブリッド債の残高（期末） | C38: 億円 | E38: =N(D38)+E37 -> 0 | F38: =N(E38)+F37 -> 0 | G38: =N(F38)+G37 -> 0 | H38: =N(G38)+H37 -> 0 | I38: =N(H38)+I37 -> 0
B39: ハイブリッド債の上乗せ金利 | C39: 億円 | E39: =前提!$D$148*(N(D38)+E21*(E33+E34+E32*前提!$D$141)) -> 0 | F39: =前提!$D$148*(N(E38)+F21*(F33+F34+F32*前提!$D$141)) -> 0 | G39: =前提!$D$148*(N(F38)+G21*(G33+G34+G32*前提!$D$141)) -> 0 | H39: =前提!$D$148*(N(G38)+H21*(H33+H34+H32*前提!$D$141)) -> 0 | I39: =前提!$D$148*(N(H38)+I21*(I33+I34+I32*前提!$D$141)) -> 0
B41: 持分法期間と連結後
B42: 持分法期間フラグ | E42: =E18*(1-E29) -> 0 | F42: =F18*(1-F29) -> 1 | G42: =G18*(1-G29) -> 1 | H42: =H18*(1-H29) -> 1 | I42: =I18*(1-I29) -> 1
B43: 期間係数（取得年度は下期のみ） | C43: 倍 | E43: =IF(E17=1,前提!$D$141,1) -> 1 | F43: =IF(F17=1,前提!$D$141,1) -> 0.5 | G43: =IF(G17=1,前提!$D$141,1) -> 1 | H43: =IF(H17=1,前提!$D$141,1) -> 1 | I43: =IF(I17=1,前提!$D$141,1) -> 1
B44: 当社持分法利益（持分×(コア−金融費用100)×(1−27%)） | C44: 億円 | E44: =E42*E43*E28*(E13-前提!$D$158)*(1-前提!$D$159) -> 0 | F44: =F42*F43*F28*(F13-前提!$D$158)*(1-前提!$D$159) -> 44.998283 | G44: =G42*G43*G28*(G13-前提!$D$158)*(1-前提!$D$159) -> 107.00491 | H44: =H42*H43*H28*(H13-前提!$D$158)*(1-前提!$D$159) -> 133.41745 | I44: =I42*I43*I28*(I13-前提!$D$158)*(1-前提!$D$159) -> 283.69482 | J44: 期首取得なので期末持分を通年に当てる
...

Sheet セグメント
B1: セグメント（ケースA＝JSRなし）
B2: 2026年度は会社予算（M03 p20）。SM は基礎経路（既定＝会社計画）に上振れ（会社計画比の増分）を足す
B4: 項目 | C4: 単位 | D4: 2025年度 | E4: 2026年度 | F4: 2027年度 | G4: 2028年度 | H4: 2029年度 | I4: 2030年度 | J4: 出所・算式
B5: スペシャリティ（SM）
B6: 保守経路：売上 | C6: 億円 | E6: =前提!$D$36 -> 12370 | F6: =E6*(1+前提!$D$48) -> 12864.8 | G6: =F6*(1+前提!$D$48) -> 13379.392 | H6: =G6*(1+前提!$D$48) -> 13914.568 | I6: =H6*(1+前提!$D$48) -> 14471.15 | J6: 2026＝会社予算、以後+4%/年
B7: 保守経路：コア営業利益 | C7: 億円 | E7: =前提!$D$37 -> 900 | F7: =F6*前提!F7 -> 1003.4544 | G7: =G6*前提!G7 -> 1110.4895 | H7: =H6*前提!H7 -> 1224.482 | I7: =I6*前提!I7 -> 1302.4035 | J7: 利益率7.8→9.0%
B8: 会社計画経路：売上 | C8: 億円 | E8: =前提!$D$36 -> 12370 | F8: =IF(前提!F$6<=前提!$D$51,前提!$D$36+(前提!$D$49-前提!$D$36)*(前提!F$6-前提!E$6)/(前提!$D$51-前提!E$6),E8*(1+前提!$D$52)) -> 13480 | G8: =IF(前提!G$6<=前提!$D$51,前提!$D$36+(前提!$D$49-前提!$D$36)*(前提!G$6-前提!E$6)/(前提!$D$51-前提!E$6),F8*(1+前提!$D$52)) -> 14590 | H8: =IF(前提!H$6<=前提!$D$51,前提!$D$36+(前提!$D$49-前提!$D$36)*(前提!H$6-前提!E$6)/(前提!$D$51-前提!E$6),G8*(1+前提!$D$52)) -> 15700 | I8: =IF(前提!I$6<=前提!$D$51,前提!$D$36+(前提!$D$49-前提!$D$36)*(前提!I$6-前提!E$6)/(前提!$D$51-前提!E$6),H8*(1+前提!$D$52)) -> 16328 | J8: 12,370→15,700（2029）を線形、以後+4%
B9: 会社計画経路：コア営業利益 | C9: 億円 | E9: =前提!$D$37 -> 900 | F9: =IF(前提!F$6<=前提!$D$51,前提!$D$37+(前提!$D$50-前提!$D$37)*(前提!F$6-前提!E$6)/(前提!$D$51-前提!E$6),F8*前提!$D$53) -> 1116.6667 | G9: =IF(前提!G$6<=前提!$D$51,前提!$D$37+(前提!$D$50-前提!$D$37)*(前提!G$6-前提!E$6)/(前提!$D$51-前提!E$6),G8*前提!$D$53) -> 1333.3333 | H9: =IF(前提!H$6<=前提!$D$51,前提!$D$37+(前提!$D$50-前提!$D$37)*(前提!H$6-前提!E$6)/(前提!$D$51-前提!E$6),H8*前提!$D$53) -> 1550 | I9: =IF(前提!I$6<=前提!$D$51,前提!$D$37+(前提!$D$50-前提!$D$37)*(前提!I$6-前提!E$6)/(前提!$D$51-前提!E$6),I8*前提!$D$53) -> 1632.8 | J9: 900→1,550（2029）を線形、以後利益率10.0%
B10: SM 本体 基礎売上（選択した経路） | C10: 億円 | E10: =IF(前提!$D$30=1,E8,E6) -> 12370 | F10: =IF(前提!$D$30=1,F8,F6) -> 13480 | G10: =IF(前提!$D$30=1,G8,G6) -> 14590 | H10: =IF(前提!$D$30=1,H8,H6) -> 15700 | I10: =IF(前提!$D$30=1,I8,I6) -> 16328 | J10: 前提の切替（1＝会社計画）
B11: SM 本体 基礎コア営業利益（選択した経路） | C11: 億円 | E11: =IF(前提!$D$30=1,E9,E7) -> 900 | F11: =IF(前提!$D$30=1,F9,F7) -> 1116.6667 | G11: =IF(前提!$D$30=1,G9,G7) -> 1333.3333 | H11: =IF(前提!$D$30=1,H9,H7) -> 1550 | I11: =IF(前提!$D$30=1,I9,I7) -> 1632.8
B12: SM 本体 基礎コア利益率 | C12: % | E12: =E11/E10 -> 0.072756669 | F12: =F11/F10 -> 0.082838773 | G12: =G11/G10 -> 0.091386795 | H12: =H11/H10 -> 0.098726115 | I12: =I11/I10 -> 0.1
B13: 上振れ売上：合成石英 | C13: 億円 | E13: =D_半導体!E15 -> 0 | F13: =D_半導体!F15 -> 1.05 | G13: =D_半導体!G15 -> 11.223287 | H13: =D_半導体!H15 -> 14.675192 | I13: =D_半導体!I15 -> 18.133569
B14: 上振れ売上：リソマックス | C14: 億円 | E14: =D_半導体!E25 -> 0 | F14: =D_半導体!F25 -> 7.632 | G14: =D_半導体!G25 -> 14.722982 | H14: =D_半導体!H25 -> 18.795811 | I14: =D_半導体!I25 -> 22.764333
B15: 上振れ売上：Zoox | C15: 億円 | E15: =D_Zoox!E9 -> 0 | F15: =D_Zoox!F9 -> 100 | G15: =D_Zoox!G9 -> 100 | H15: =D_Zoox!H9 -> 100 | I15: =D_Zoox!I9 -> 100
B16: 上振れコア：合成石英 | C16: 億円 | E16: =D_半導体!E16 -> 0 | F16: =D_半導体!F16 -> 0.4725 | G16: =D_半導体!G16 -> 5.0504789 | H16: =D_半導体!H16 -> 6.6038366 | I16: =D_半導体!I16 -> 8.1601062
B17: 上振れコア：リソマックス | C17: 億円 | E17: =D_半導体!E26 -> 0 | F17: =D_半導体!F26 -> 2.6712 | G17: =D_半導体!G26 -> 5.1530438 | H17: =D_半導体!H26 -> 6.5785338 | I17: =D_半導体!I26 -> 7.9675166
B18: 上振れコア：Zoox | C18: 億円 | E18: =D_Zoox!E10 -> 0 | F18: =D_Zoox!F10 -> 15 | G18: =D_Zoox!G10 -> 15 | H18: =D_Zoox!H10 -> 15 | I18: =D_Zoox!I10 -> 15
B19: SM 売上 | C19: 億円 | E19: =E10+E13+E14+E15 -> 12370 | F19: =F10+F13+F14+F15 -> 13588.682 | G19: =G10+G13+G14+G15 -> 14715.946 | H19: =H10+H13+H14+H15 -> 15833.471 | I19: =I10+I13+I14+I15 -> 16468.898
B20: SM コア営業利益 | C20: 億円 | E20: =E11+E16+E17+E18 -> 900 | F20: =F11+F16+F17+F18 -> 1134.8104 | G20: =G11+G16+G17+G18 -> 1358.5369 | H20: =H11+H16+H17+H18 -> 1578.1824 | I20: =I11+I16+I17+I18 -> 1663.9276
B22: MMA&D・ベーシック・その他・産業ガス
B23: MMA&D 売上 | C23: 億円 | E23: =前提!$D$38 -> 3490 | F23: =E23*(1+前提!$D$54) -> 3524.9 | G23: =F23*(1+前提!$D$54) -> 3560.149 | H23: =G23*(1+前提!$D$54) -> 3595.7505 | I23: =H23*(1+前提!$D$54) -> 3631.708
B24: MMA&D コア営業利益 | C24: 億円 | E24: =前提!E11 -> 110 | F24: =前提!F11 -> 120 | G24: =前提!G11 -> 140 | H24: =前提!H11 -> 160 | I24: =前提!I11 -> 170
B25: BM 売上（連結範囲） | C25: 億円 | E25: =分社化・合併!E30 -> 6830 | F25: =分社化・合併!F30 -> 6330 | G25: =分社化・合併!G30 -> 0 | H25: =分社化・合併!H30 -> 0 | I25: =分社化・合併!I30 -> 0 | J25: 合併後はゼロ
B26: BM コア営業利益（連結範囲） | C26: 億円 | E26: =分社化・合併!E31 -> -50 | F26: =分社化・合併!F31 -> -119.63184 | G26: =分社化・合併!G31 -> 0 | H26: =分社化・合併!H31 -> 0 | I26: =分社化・合併!I31 -> 0
B27: BM 合弁の持分法利益（コアに含む） | C27: 億円 | E27: =分社化・合併!E34 -> 0 | F27: =分社化・合併!F34 -> 0 | G27: =分社化・合併!G34 -> -55.74229 | H27: =分社化・合併!H34 -> -6.7422902 | I27: =分社化・合併!I34 -> 45.628855
B28: その他 売上 | C28: 億円 | E28: =前提!$D$40 -> 1590 | F28: =E28*(1+前提!$D$55) -> 1590 | G28: =F28*(1+前提!$D$55) -> 1590 | H28: =G28*(1+前提!$D$55) -> 1590 | I28: =H28*(1+前提!$D$55) -> 1590 | J28: 成長率は仮定（0%）
B29: その他 コア営業利益 | C29: 億円 | E29: =前提!E16 -> 40 | F29: =前提!F16 -> 0 | G29: =前提!G16 -> 0 | H29: =前提!H16 -> 0 | I29: =前提!I16 -> 0
B30: 産業ガス 売上 | C30: 億円 | E30: =前提!$D$41 -> 13720 | F30: =E30*(1+前提!$D$56) -> 14268.8 | G30: =F30*(1+前提!$D$56) -> 14839.552 | H30: =G30*(1+前提!$D$56) -> 15433.134 | I30: =H30*(1+前提!$D$56) -> 16050.459
B31: 産業ガス コア営業利益 | C31: 億円 | E31: =前提!E15 -> 2050 | F31: =前提!F15 -> 2150 | G31: =前提!G15 -> 2260 | H31: =前提!H15 -> 2370 | I31: =前提!I15 -> 2480
B33: 連結（ケースA）
B34: 売上収益 計 | C34: 億円 | E34: =E19+E23+E25+E28+E30 -> 38000 | F34: =F19+F23+F25+F28+F30 -> 39302.382 | G34: =G19+G23+G25+G28+G30 -> 34705.647 | H34: =H19+H23+H25+H28+H30 -> 36452.356 | I34: =I19+I23+I25+I28+I30 -> 37741.065
B35: コア営業利益 計 | C35: 億円 | E35: =E20+E24+E26+E27+E29+E31 -> 3050 | F35: =F20+F24+F26+F27+F29+F31 -> 3285.1785 | G35: =G20+G24+G26+G27+G29+G31 -> 3702.7946 | H35: =H20+H24+H26+H27+H29+H31 -> 4101.4401 | I35: =I20+I24+I26+I27+I29+I31 -> 4359.5565
B36: コア営業利益率 | C36: % | E36: =E35/E34 -> 0.080263158 | F36: =F35/F34 -> 0.083587263 | G36: =G35/G34 -> 0.10669141 | H36: =H35/H34 -> 0.11251509 | I36: =I35/I34 -> 0.11551228
B38: 上振れの内訳（コア営業利益への寄与）
B39: 合成石英 | C39: 億円 | E39: =E16 -> 0 | F39: =F16 -> 0.4725 | G39: =G16 -> 5.0504789 | H39: =H16 -> 6.6038366 | I39: =I16 -> 8.1601062
B40: リソマックス | C40: 億円 | E40: =E17 -> 0 | F40: =F17 -> 2.6712 | G40: =G17 -> 5.1530438 | H40: =H17 -> 6.5785338 | I40: =I17 -> 7.9675166
B41: Zoox | C41: 億円 | E41: =E18 -> 0 | F41: =F18 -> 15 | G41: =G18 -> 15 | H41: =H18 -> 15 | I41: =I18 -> 15
B42: 丸善千葉停止 | C42: 億円 | E42: =D_石化!E8*IF(分社化・合併!E6=1,前提!$D$102*前提!$D$103*(1-前提!$D$105),1) -> 0 | F42: =D_石化!F8*IF(分社化・合併!F6=1,前提!$D$102*前提!$D$103*(1-前提!$D$105),1) -> 30.368157 | G42: =D_石化!G8*IF(分社化・合併!G6=1,前提!$D$102*前提!$D$103*(1-前提!$D$105),1) -> 21.25771 | H42: =D_石化!H8*IF(分社化・合併!H6=1,前提!$D$102*前提!$D$103*(1-前提!$D$105),1) -> 21.25771 | I42: =D_石化!I8*IF(分社化・合併!I6=1,前提!$D$102*前提!$D$103*(1-前提!$D$105),1) -> 21.25771 | J42: 合併後は持分法経由（×50%×2×(1−30%)）
B43: 水島停止 | C43: 億円 | E43: =D_石化!E12*IF(分社化・合併!E6=1,前提!$D$102*前提!$D$103*(1-前提!$D$105),1) -> 0 | F43: =D_石化!F12*IF(分社化・合併!F6=1,前提!$D$102*前提!$D$103*(1-前提!$D$105),1) -> 0 | G43: =D_石化!G12*IF(分社化・合併!G6=1,前提!$D$102*前提!$D$103*(1-前提!$D$105),1) -> 0 | H43: =D_石化!H12*IF(分社化・合併!H6=1,前提!$D$102*前提!$D$103*(1-前提!$D$105),1) -> 0 | I43: =D_石化!I12*IF(分社化・合併!I6=1,前提!$D$102*前提!$D$103*(1-前提!$D$105),1) -> 45.371145 | J43: 同上
B44: 合併統合効果 | C44: 億円 | E44: =分社化・合併!E32*前提!$D$102*(1-前提!$D$105) -> 0 | F44: =分社化・合併!F32*前提!$D$102*(1-前提!$D$105) -> 0 | G44: =分社化・合併!G32*前提!$D$102*(1-前提!$D$105) -> 0 | H44: =分社化・合併!H32*前提!$D$102*(1-前提!$D$105) -> 35 | I44: =分社化・合併!I32*前提!$D$102*(1-前提!$D$105) -> 35 | J44: 当社持分50%×(1−30%)
...

Sheet 連結PL
B1: 連結PL（ケースA＝JSRなし／ケースB＝JSRあり）
B2: 当期利益＝(コア＋非経常−金融費用)×(1−27%)＋合併除外損益×(1−30%)−非支配株主利益
B4: 項目 | C4: 単位 | D4: 2025年度 | E4: 2026年度 | F4: 2027年度 | G4: 2028年度 | H4: 2029年度 | I4: 2030年度 | J4: 出所・算式
B5: ケースA（JSRなし＝本体）
B6: 売上収益 | C6: 億円 | D6: =前提!$D$132 -> 37040 | E6: =セグメント!E34 -> 38000 | F6: =セグメント!F34 -> 39302.382 | G6: =セグメント!G34 -> 34705.647 | H6: =セグメント!H34 -> 36452.356 | I6: =セグメント!I34 -> 37741.065 | J6: 2025年度は実績（運転資本の計算用）
B7: コア営業利益 | C7: 億円 | E7: =セグメント!E35 -> 3050 | F7: =セグメント!F35 -> 3285.1785 | G7: =セグメント!G35 -> 3702.7946 | H7: =セグメント!H35 -> 4101.4401 | I7: =セグメント!I35 -> 4359.5565
B8: うち持分法利益 | C8: 億円 | E8: =セグメント!E27 -> 0 | F8: =セグメント!F27 -> 0 | G8: =セグメント!G27 -> -55.74229 | H8: =セグメント!H27 -> -6.7422902 | I8: =セグメント!I27 -> 45.628855
B9: 非経常損益（分社化・合併以外） | C9: 億円 | E9: =前提!E17 -> -50 | F9: =前提!F17 -> -350 | G9: =前提!G17 -> -400 | H9: =前提!H17 -> -300 | I9: =前提!I17 -> -300
B10: 分社化の一時費用 | C10: 億円 | E10: =分社化・合併!E9 -> 0 | F10: =分社化・合併!F9 -> -50 | G10: =分社化・合併!G9 -> 0 | H10: =分社化・合併!H9 -> 0 | I10: =分社化・合併!I9 -> 0
B11: 合併除外損益（税前） | C11: 億円 | E11: =分社化・合併!E23 -> 0 | F11: =分社化・合併!F23 -> 0 | G11: =分社化・合併!G23 -> -3852.4537 | H11: =分社化・合併!H23 -> 0 | I11: =分社化・合併!I23 -> 0
B12: 期首純有利子負債（期首取引後） | C12: 億円 | E12: =連結BS!D16-分社化・合併!E26 -> 14648 | F12: =連結BS!E16-分社化・合併!F26 -> 14001.465 | G12: =連結BS!F16-分社化・合併!G26 -> 12827.725 | H12: =連結BS!G16-分社化・合併!H26 -> 11733.496 | I12: =連結BS!H16-分社化・合併!I26 -> 10251.112 | J12: 合併の負債移転は期首
B13: 金融費用 | C13: 億円 | E13: =E12*前提!$D$121 -> 292.96 | F13: =F12*前提!$D$121 -> 280.02929 | G13: =G12*前提!$D$121 -> 256.5545 | H13: =H12*前提!$D$121 -> 234.66991 | I13: =I12*前提!$D$121 -> 205.02224 | J13: 期首純有利子負債×2.0%
B14: 税前利益（除外損益を除く） | C14: 億円 | E14: =E7+E9+E10-E13 -> 2707.04 | F14: =F7+F9+F10-F13 -> 2605.1492 | G14: =G7+G9+G10-G13 -> 3046.2401 | H14: =H7+H9+H10-H13 -> 3566.7702 | I14: =I7+I9+I10-I13 -> 3854.5342
B15: 法人税等（27%） | C15: 億円 | E15: =-E14*前提!$D$122 -> -730.9008 | F15: =-F14*前提!$D$122 -> -703.39029 | G15: =-G14*前提!$D$122 -> -822.48482 | H15: =-H14*前提!$D$122 -> -963.02795 | I15: =-I14*前提!$D$122 -> -1040.7242
B16: 持分法利益の二重課税の戻し（切替） | C16: 億円 | E16: =前提!$D$32*E8*前提!$D$122 -> 0 | F16: =前提!$D$32*F8*前提!$D$122 -> 0 | G16: =前提!$D$32*G8*前提!$D$122 -> -15.050418 | H16: =前提!$D$32*H8*前提!$D$122 -> -1.8204184 | I16: =前提!$D$32*I8*前提!$D$122 -> 12.319791 | J16: 既定0＝設計どおり
B17: 合併除外損益（税後30%） | C17: 億円 | E17: =E11*(1-前提!$D$108) -> 0 | F17: =F11*(1-前提!$D$108) -> 0 | G17: =G11*(1-前提!$D$108) -> -2696.7176 | H17: =H11*(1-前提!$D$108) -> 0 | I17: =I11*(1-前提!$D$108) -> 0
B18: 当期利益（非支配含む） | C18: 億円 | E18: =E14+E15+E16+E17 -> 1976.1392 | F18: =F14+F15+F16+F17 -> 1901.7589 | G18: =G14+G15+G16+G17 -> -488.01279 | H18: =H14+H15+H16+H17 -> 2601.9218 | I18: =I14+I15+I16+I17 -> 2826.1298
B19: 日本酸素 当期利益 | C19: 億円 | E19: =前提!$D$114*セグメント!E31/セグメント!$E$31 -> 1310 | F19: =前提!$D$114*セグメント!F31/セグメント!$E$31 -> 1373.9024 | G19: =前提!$D$114*セグメント!G31/セグメント!$E$31 -> 1444.1951 | H19: =前提!$D$114*セグメント!H31/セグメント!$E$31 -> 1514.4878 | I19: =前提!$D$114*セグメント!I31/セグメント!$E$31 -> 1584.7805 | J19: 2026＝1,310、以後コア比例
B20: 非支配株主利益 | C20: 億円 | E20: =前提!$D$115*E19+前提!$D$117 -> 697.271 | F20: =前提!$D$115*F19+前提!$D$117 -> 728.8452 | G20: =前提!$D$115*G19+前提!$D$117 -> 763.57681 | H20: =前提!$D$115*H19+前提!$D$117 -> 798.30842 | I20: =前提!$D$115*I19+前提!$D$117 -> 833.04004 | J20: 49.41%×日本酸素＋その他50
B21: 親会社の所有者に帰属する当期利益 | C21: 億円 | E21: =E18-E20 -> 1278.8682 | F21: =F18-F20 -> 1172.9137 | G21: =G18-G20 -> -1251.5896 | H21: =H18-H20 -> 1803.6134 | I21: =I18-I20 -> 1993.0897
B22: EPS | C22: 円 | E22: =E21/前提!$D$124*100 -> 94.124398 | F22: =F21/前提!$D$124*100 -> 86.326175 | G22: =G21/前提!$D$124*100 -> -92.1167 | H22: =H21/前提!$D$124*100 -> 132.74552 | I22: =I21/前提!$D$124*100 -> 146.69094 | J22: ÷1,358.7百万株
B23: 配当（親会社株主） | C23: 億円 | E23: =MAX(前提!$D$125*前提!$D$124/100,前提!$D$126*E21) -> 447.60387 | F23: =MAX(前提!$D$125*前提!$D$124/100,前提!$D$126*F21) -> 434.784 | G23: =MAX(前提!$D$125*前提!$D$124/100,前提!$D$126*G21) -> 434.784 | H23: =MAX(前提!$D$125*前提!$D$124/100,前提!$D$126*H21) -> 631.26468 | I23: =MAX(前提!$D$125*前提!$D$124/100,前提!$D$126*I21) -> 697.58141 | J23: MAX(32円×株数, 35%×当期利益)
B24: 配当（非支配株主） | C24: 億円 | E24: =前提!$D$118*E19/$E$19 -> 141 | F24: =前提!$D$118*F19/$E$19 -> 147.87805 | G24: =前提!$D$118*G19/$E$19 -> 155.4439 | H24: =前提!$D$118*H19/$E$19 -> 163.00976 | I24: =前提!$D$118*I19/$E$19 -> 170.57561 | J24: 2026＝141、以後当期利益比例
B25: ROIC | C25: % | E25: =((E7-前提!$D$32*E8)*(1-前提!$D$123)+前提!$D$32*E8)/AVERAGE(連結BS!D20,連結BS!E20) -> 0.048894436 | F25: =((F7-前提!$D$32*F8)*(1-前提!$D$123)+前提!$D$32*F8)/AVERAGE(連結BS!E20,連結BS!F20) -> 0.051841602 | G25: =((G7-前提!$D$32*G8)*(1-前提!$D$123)+前提!$D$32*G8)/AVERAGE(連結BS!F20,連結BS!G20) -> 0.059412302 | H25: =((H7-前提!$D$32*H8)*(1-前提!$D$123)+前提!$D$32*H8)/AVERAGE(連結BS!G20,連結BS!H20) -> 0.06803135 | I25: =((I7-前提!$D$32*I8)*(1-前提!$D$123)+前提!$D$32*I8)/AVERAGE(連結BS!H20,連結BS!I20) -> 0.072188341 | J25: （コア−持分法）×(1−30%)＋持分法、÷(資本合計＋有利子負債)の期首期末平均（切替0なら設計書当初式）
B26: ネットD/E | C26: 倍 | E26: =連結BS!E21 -> 0.75895837 | F26: =連結BS!F21 -> 0.6946446 | G26: =連結BS!G21 -> 0.67048468 | H26: =連結BS!H21 -> 0.54899901 | I26: =連結BS!I21 -> 0.42829163 | J26: 純有利子負債÷親会社持分（B はハイブリッド債の資本性調整後）
B28: ケースB（JSRあり）
B29: 売上収益 | C29: 億円 | D29: =D6 -> 37040 | E29: =E6+D_JSR!E47 -> 38000 | F29: =F6+D_JSR!F47 -> 39302.382 | G29: =G6+D_JSR!G47 -> 34705.647 | H29: =H6+D_JSR!H47 -> 36452.356 | I29: =I6+D_JSR!I47 -> 37741.065 | J29: ケースA＋JSR 連結売上
B30: コア営業利益 | C30: 億円 | E30: =E7+D_JSR!E44+D_JSR!E48 -> 3050 | F30: =F7+D_JSR!F44+D_JSR!F48 -> 3330.1768 | G30: =G7+D_JSR!G44+D_JSR!G48 -> 3809.7995 | H30: =H7+D_JSR!H44+D_JSR!H48 -> 4234.8575 | I30: =I7+D_JSR!I44+D_JSR!I48 -> 4643.2513 | J30: ケースA＋JSR 持分法利益＋JSR 連結コア
B31: うち持分法利益 | C31: 億円 | E31: =E8+D_JSR!E44 -> 0 | F31: =F8+D_JSR!F44 -> 44.998283 | G31: =G8+D_JSR!G44 -> 51.262617 | H31: =H8+D_JSR!H44 -> 126.67516 | I31: =I8+D_JSR!I44 -> 329.32368
B32: 非経常損益（分社化・合併以外） | C32: 億円 | E32: =前提!E17 -> -50 | F32: =前提!F17 -> -350 | G32: =前提!G17 -> -400 | H32: =前提!H17 -> -300 | I32: =前提!I17 -> -300
B33: 分社化の一時費用 | C33: 億円 | E33: =分社化・合併!E9 -> 0 | F33: =分社化・合併!F9 -> -50 | G33: =分社化・合併!G9 -> 0 | H33: =分社化・合併!H9 -> 0 | I33: =分社化・合併!I9 -> 0
B34: 合併除外損益（税前） | C34: 億円 | E34: =分社化・合併!E23 -> 0 | F34: =分社化・合併!F23 -> 0 | G34: =分社化・合併!G23 -> -3852.4537 | H34: =分社化・合併!H23 -> 0 | I34: =分社化・合併!I23 -> 0
B35: 期首純有利子負債（期首取引後） | C35: 億円 | E35: =連結BS!D38-分社化・合併!E26+D_JSR!E33+D_JSR!E34+D_JSR!E26*前提!$D$136 -> 14648 | F35: =連結BS!E38-分社化・合併!F26+D_JSR!F33+D_JSR!F34+D_JSR!F26*前提!$D$136 -> 14001.465 | G35: =連結BS!F38-分社化・合併!G26+D_JSR!G33+D_JSR!G34+D_JSR!G26*前提!$D$136 -> 14873.434 | H35: =連結BS!G38-分社化・合併!H26+D_JSR!H33+D_JSR!H34+D_JSR!H26*前提!$D$136 -> 14086.045 | I35: =連結BS!H38-分社化・合併!I26+D_JSR!I33+D_JSR!I34+D_JSR!I26*前提!$D$136 -> 15075.441 | J35: JSR の追加取得・全額取得は期首（代金＋連結時の JSR 純有利子負債）
B36: 金融費用 | C36: 億円 | E36: =E35*前提!$D$121+D_JSR!E32*前提!$D$121*前提!$D$141+D_JSR!E39 -> 292.96 | F36: =F35*前提!$D$121+D_JSR!F32*前提!$D$121*前提!$D$141+D_JSR!F39 -> 300.02929 | G36: =G35*前提!$D$121+D_JSR!G32*前提!$D$121*前提!$D$141+D_JSR!G39 -> 297.46868 | H36: =H35*前提!$D$121+D_JSR!H32*前提!$D$121*前提!$D$141+D_JSR!H39 -> 281.7209 | I36: =I35*前提!$D$121+D_JSR!I32*前提!$D$121*前提!$D$141+D_JSR!I39 -> 301.50881 | J36: ＋第1段取得（下期）の半年分＋ハイブリッド債の上乗せ金利
B37: 税前利益（除外損益を除く） | C37: 億円 | E37: =E30+E32+E33-E36 -> 2707.04 | F37: =F30+F32+F33-F36 -> 2630.1475 | G37: =G30+G32+G33-G36 -> 3112.3308 | H37: =H30+H32+H33-H36 -> 3653.1366 | I37: =I30+I32+I33-I36 -> 4041.7425
B38: 法人税等（27%） | C38: 億円 | E38: =-E37*前提!$D$122 -> -730.9008 | F38: =-F37*前提!$D$122 -> -710.13983 | G38: =-G37*前提!$D$122 -> -840.32931 | H38: =-H37*前提!$D$122 -> -986.34689 | I38: =-I37*前提!$D$122 -> -1091.2705
B39: 持分法利益の二重課税の戻し（切替） | C39: 億円 | E39: =前提!$D$32*E31*前提!$D$122 -> 0 | F39: =前提!$D$32*F31*前提!$D$122 -> 12.149536 | G39: =前提!$D$32*G31*前提!$D$122 -> 13.840907 | H39: =前提!$D$32*H31*前提!$D$122 -> 34.202293 | I39: =前提!$D$32*I31*前提!$D$122 -> 88.917393 | J39: 既定0＝設計どおり
B40: 合併除外損益（税後30%） | C40: 億円 | E40: =E34*(1-前提!$D$108) -> 0 | F40: =F34*(1-前提!$D$108) -> 0 | G40: =G34*(1-前提!$D$108) -> -2696.7176 | H40: =H34*(1-前提!$D$108) -> 0 | I40: =I34*(1-前提!$D$108) -> 0
B41: 当期利益（非支配含む） | C41: 億円 | E41: =E37+E38+E39+E40 -> 1976.1392 | F41: =F37+F38+F39+F40 -> 1932.1572 | G41: =G37+G38+G39+G40 -> -410.87523 | H41: =H37+H38+H39+H40 -> 2700.992 | I41: =I37+I38+I39+I40 -> 3039.3894
B42: 日本酸素 当期利益 | C42: 億円 | E42: =E19 -> 1310 | F42: =F19 -> 1373.9024 | G42: =G19 -> 1444.1951 | H42: =H19 -> 1514.4878 | I42: =I19 -> 1584.7805
...

Sheet 連結BS
B1: 連結BS（簡略：正味営業資産＝親会社持分＋非支配持分＋純有利子負債）
B2: 2025年度＝2026年3月末実績。純有利子負債は BS の差額で求め、連結CF の積み上げと一致するかを検証シートで確認
B4: 項目 | C4: 単位 | D4: 2025年度末 | E4: 2026年度 | F4: 2027年度 | G4: 2028年度 | H4: 2029年度 | I4: 2030年度 | J4: 出所・算式
B5: ケースA（JSRなし）
B6: ＋設備投資 | C6: 億円 | E6: =連結CF!E6 -> 3391 | F6: =連結CF!F6 -> 3300 | G6: =連結CF!G6 -> 2920 | H6: =連結CF!H6 -> 2720 | I6: =連結CF!I6 -> 2720
B7: −減価償却 | C7: 億円 | E7: =-連結CF!E7 -> -2794 | F7: =-連結CF!F7 -> -2850 | G7: =-連結CF!G7 -> -2600 | H7: =-連結CF!H7 -> -2650 | I7: =-連結CF!I7 -> -2700
B8: ＋運転資本の増加 | C8: 億円 | E8: =連結CF!E9 -> 144 | F8: =連結CF!F9 -> 195.3573 | G8: =連結CF!G9 -> 259.98979 | H8: =連結CF!H9 -> 262.00625 | I8: =連結CF!I9 -> 193.30647
B9: −合併で連結から外れる BM 正味営業資産 | C9: 億円 | E9: =-分社化・合併!E25 -> 0 | F9: =-分社化・合併!F25 -> 0 | G9: =-分社化・合併!G25 -> -5300 | H9: =-分社化・合併!H25 -> 0 | I9: =-分社化・合併!I25 -> 0
B10: ＋合弁株式（公正価値） | C10: 億円 | E10: =分社化・合併!E27 -> 0 | F10: =分社化・合併!F27 -> 0 | G10: =分社化・合併!G27 -> 947.54626 | H10: =分社化・合併!H27 -> 0 | I10: =分社化・合併!I27 -> 0
B11: ＋持分法損益の積み上げ | C11: 億円 | E11: =連結PL!E8 -> 0 | F11: =連結PL!F8 -> 0 | G11: =連結PL!G8 -> -55.74229 | H11: =連結PL!H8 -> -6.7422902 | I11: =連結PL!I8 -> 45.628855
B12: ＋繰延税金資産（合併除外損の税効果、非資金） | C12: 億円 | E12: =-連結PL!E11*前提!$D$108 -> 0 | F12: =-連結PL!F11*前提!$D$108 -> 0 | G12: =-連結PL!G11*前提!$D$108 -> 1155.7361 | H12: =-連結PL!H11*前提!$D$108 -> 0 | I12: =-連結PL!I11*前提!$D$108 -> 0
B13: 正味営業資産 | C13: 億円 | D13: =前提!$D$127+前提!$D$128+前提!$D$129 -> 38795 | E13: =D13+E6+E7+E8+E9+E10+E11+E12 -> 39536 | F13: =E13+F6+F7+F8+F9+F10+F11+F12 -> 40181.357 | G13: =F13+G6+G7+G8+G9+G10+G11+G12 -> 37508.887 | H13: =G13+H6+H7+H8+H9+H10+H11+H12 -> 37834.151 | I13: =H13+I6+I7+I8+I9+I10+I11+I12 -> 38093.086
B14: 親会社の所有者に帰属する持分 | C14: 億円 | D14: =前提!$D$127 -> 17617 | E14: =D14+連結PL!E21-連結PL!E23 -> 18448.264 | F14: =E14+連結PL!F21-連結PL!F23 -> 19186.394 | G14: =F14+連結PL!G21-連結PL!G23 -> 17500.02 | H14: =G14+連結PL!H21-連結PL!H23 -> 18672.369 | I14: =H14+連結PL!I21-連結PL!I23 -> 19967.878
B15: 非支配持分 | C15: 億円 | D15: =前提!$D$128 -> 6530 | E15: =D15+連結PL!E20-連結PL!E24 -> 7086.271 | F15: =E15+連結PL!F20-連結PL!F24 -> 7667.2381 | G15: =F15+連結PL!G20-連結PL!G24 -> 8275.3711 | H15: =G15+連結PL!H20-連結PL!H24 -> 8910.6697 | I15: =H15+連結PL!I20-連結PL!I24 -> 9573.1342
B16: 純有利子負債（BS 差額） | C16: 億円 | D16: =D13-D14-D15 -> 14648 | E16: =E13-E14-E15 -> 14001.465 | F16: =F13-F14-F15 -> 13327.725 | G16: =G13-G14-G15 -> 11733.496 | H16: =H13-H14-H15 -> 10251.112 | I16: =I13-I14-I15 -> 8552.0748
B17: 現金及び現金同等物 | C17: 億円 | D17: =前提!$D$130 -> 4500 | E17: =前提!$D$130 -> 4500 | F17: =前提!$D$130 -> 4500 | G17: =前提!$D$130 -> 4500 | H17: =前提!$D$130 -> 4500 | I17: =前提!$D$130 -> 4500
B18: 有利子負債（純有利子負債＋現金） | C18: 億円 | D18: =D16+D17 -> 19148 | E18: =E16+E17 -> 18501.465 | F18: =F16+F17 -> 17827.725 | G18: =G16+G17 -> 16233.496 | H18: =H16+H17 -> 14751.112 | I18: =I16+I17 -> 13052.075
B19: 資本合計 | C19: 億円 | D19: =D14+D15 -> 24147 | E19: =E14+E15 -> 25534.535 | F19: =F14+F15 -> 26853.632 | G19: =G14+G15 -> 25775.392 | H19: =H14+H15 -> 27583.039 | I19: =I14+I15 -> 29541.012
B20: 投下資本（資本合計＋有利子負債） | C20: 億円 | D20: =D19+D18 -> 43295 | E20: =E19+E18 -> 44036 | F20: =F19+F18 -> 44681.357 | G20: =G19+G18 -> 42008.887 | H20: =H19+H18 -> 42334.151 | I20: =I19+I18 -> 42593.086
B21: ネットD/E | C21: 倍 | D21: =D16/D14 -> 0.8314696 | E21: =E16/E14 -> 0.75895837 | F21: =F16/F14 -> 0.6946446 | G21: =G16/G14 -> 0.67048468 | H21: =H16/H14 -> 0.54899901 | I21: =I16/I14 -> 0.42829163
B22: 均衡差（正味営業資産−資本合計−純有利子負債） | C22: 億円 | D22: =D13-D19-D16 -> 0 | E22: =E13-E19-E16 -> 0 | F22: =F13-F19-F16 -> 0 | G22: =G13-G19-G16 -> 0 | H22: =H13-H19-H16 -> 0 | I22: =I13-I19-I16 -> 0
B24: ケースB（JSRあり）
B25: ＋設備投資 | C25: 億円 | E25: =連結CF!E28 -> 3391 | F25: =連結CF!F28 -> 3300 | G25: =連結CF!G28 -> 2920 | H25: =連結CF!H28 -> 2720 | I25: =連結CF!I28 -> 2720
B26: −減価償却 | C26: 億円 | E26: =-連結CF!E29 -> -2794 | F26: =-連結CF!F29 -> -2850 | G26: =-連結CF!G29 -> -2600 | H26: =-連結CF!H29 -> -2650 | I26: =-連結CF!I29 -> -2700
B27: ＋運転資本の増加 | C27: 億円 | E27: =連結CF!E31 -> 144 | F27: =連結CF!F31 -> 195.3573 | G27: =連結CF!G31 -> 259.98979 | H27: =連結CF!H31 -> 262.00625 | I27: =連結CF!I31 -> 193.30647
B28: −合併で連結から外れる BM 正味営業資産 | C28: 億円 | E28: =-分社化・合併!E25 -> 0 | F28: =-分社化・合併!F25 -> 0 | G28: =-分社化・合併!G25 -> -5300 | H28: =-分社化・合併!H25 -> 0 | I28: =-分社化・合併!I25 -> 0
B29: ＋合弁株式（公正価値） | C29: 億円 | E29: =分社化・合併!E27 -> 0 | F29: =分社化・合併!F27 -> 0 | G29: =分社化・合併!G27 -> 947.54626 | H29: =分社化・合併!H27 -> 0 | I29: =分社化・合併!I27 -> 0
B30: ＋持分法損益の積み上げ | C30: 億円 | E30: =連結PL!E31 -> 0 | F30: =連結PL!F31 -> 44.998283 | G30: =連結PL!G31 -> 51.262617 | H30: =連結PL!H31 -> 126.67516 | I30: =連結PL!I31 -> 329.32368
B31: ＋繰延税金資産（合併除外損の税効果、非資金） | C31: 億円 | E31: =-連結PL!E34*前提!$D$108 -> 0 | F31: =-連結PL!F34*前提!$D$108 -> 0 | G31: =-連結PL!G34*前提!$D$108 -> 1155.7361 | H31: =-連結PL!H34*前提!$D$108 -> 0 | I31: =-連結PL!I34*前提!$D$108 -> 0
B32: ＋JSR 株式の取得（持分法の期間） | C32: 億円 | E32: =D_JSR!E35 -> 0 | F32: =D_JSR!F35 -> 2000 | G32: =D_JSR!G35 -> 31.108804 | H32: =D_JSR!H35 -> 276.97324 | I32: =D_JSR!I35 -> 2402.7571
B33: −JSR 持分法投資の振替（連結時） | C33: 億円 | E33: =-D_JSR!E45 -> 0 | F33: =-D_JSR!F45 -> 0 | G33: =-D_JSR!G45 -> 0 | H33: =-D_JSR!H45 -> 0 | I33: =-D_JSR!I45 -> 0
B34: ＋JSR 連結（純資産・のれん・取込負債） | C34: 億円 | E34: =D_JSR!E45+D_JSR!E34+D_JSR!E26*前提!$D$136 -> 0 | F34: =D_JSR!F45+D_JSR!F34+D_JSR!F26*前提!$D$136 -> 0 | G34: =D_JSR!G45+D_JSR!G34+D_JSR!G26*前提!$D$136 -> 0 | H34: =D_JSR!H45+D_JSR!H34+D_JSR!H26*前提!$D$136 -> 0 | I34: =D_JSR!I45+D_JSR!I34+D_JSR!I26*前提!$D$136 -> 0
B35: 正味営業資産 | C35: 億円 | D35: =前提!$D$127+前提!$D$128+前提!$D$129 -> 38795 | E35: =D35+E25+E26+E27+E28+E29+E30+E31+E32+E33+E34 -> 39536 | F35: =E35+F25+F26+F27+F28+F29+F30+F31+F32+F33+F34 -> 42226.356 | G35: =F35+G25+G26+G27+G28+G29+G30+G31+G32+G33+G34 -> 39691.999 | H35: =G35+H25+H26+H27+H28+H29+H30+H31+H32+H33+H34 -> 40427.654 | I35: =H35+I25+I26+I27+I28+I29+I30+I31+I32+I33+I34 -> 43373.041
B36: 親会社の所有者に帰属する持分 | C36: 億円 | D36: =前提!$D$127 -> 17617 | E36: =D36+連結PL!E44-連結PL!E46 -> 18448.264 | F36: =E36+連結PL!F44-連結PL!F46 -> 19216.792 | G36: =F36+連結PL!G44-連結PL!G46 -> 17607.556 | H36: =G36+連結PL!H44-連結PL!H46 -> 18844.301 | I36: =H36+連結PL!I44-連結PL!I46 -> 20278.428
B37: 非支配持分 | C37: 億円 | D37: =前提!$D$128 -> 6530 | E37: =D37+連結PL!E43-連結PL!E47 -> 7086.271 | F37: =E37+連結PL!F43-連結PL!F47 -> 7667.2381 | G37: =F37+連結PL!G43-連結PL!G47 -> 8275.3711 | H37: =G37+連結PL!H43-連結PL!H47 -> 8910.6697 | I37: =H37+連結PL!I43-連結PL!I47 -> 9573.1342
B38: 純有利子負債（BS 差額） | C38: 億円 | D38: =D35-D36-D37 -> 14648 | E38: =E35-E36-E37 -> 14001.465 | F38: =F35-F36-F37 -> 15342.325 | G38: =G35-G36-G37 -> 13809.072 | H38: =H35-H36-H37 -> 12672.683 | I38: =I35-I36-I37 -> 13521.479
B39: 現金及び現金同等物 | C39: 億円 | D39: =前提!$D$130 -> 4500 | E39: =前提!$D$130 -> 4500 | F39: =前提!$D$130 -> 4500 | G39: =前提!$D$130 -> 4500 | H39: =前提!$D$130 -> 4500 | I39: =前提!$D$130 -> 4500
B40: 有利子負債（純有利子負債＋現金） | C40: 億円 | D40: =D38+D39 -> 19148 | E40: =E38+E39 -> 18501.465 | F40: =F38+F39 -> 19842.325 | G40: =G38+G39 -> 18309.072 | H40: =H38+H39 -> 17172.683 | I40: =I38+I39 -> 18021.479
B41: 資本合計 | C41: 億円 | D41: =D36+D37 -> 24147 | E41: =E36+E37 -> 25534.535 | F41: =F36+F37 -> 26884.031 | G41: =G36+G37 -> 25882.927 | H41: =H36+H37 -> 27754.97 | I41: =I36+I37 -> 29851.562
B42: 投下資本（資本合計＋有利子負債） | C42: 億円 | D42: =D41+D40 -> 43295 | E42: =E41+E40 -> 44036 | F42: =F41+F40 -> 46726.356 | G42: =G41+G40 -> 44191.999 | H42: =H41+H40 -> 44927.654 | I42: =I41+I40 -> 47873.041
...

Sheet 連結CF
B1: 連結CF（現金一定、借入増減で調整）
B2: 純有利子負債（CF 由来）＝期首＋借入増減＋非資金の負債増減
B4: 項目 | C4: 単位 | D4: 2025年度 | E4: 2026年度 | F4: 2027年度 | G4: 2028年度 | H4: 2029年度 | I4: 2030年度 | J4: 出所・算式
B5: ケースA（JSRなし）
B6: 設備投資（金額） | C6: 億円 | E6: =前提!E18+分社化・合併!E36 -> 3391 | F6: =前提!F18+分社化・合併!F36 -> 3300 | G6: =前提!G18+分社化・合併!G36 -> 2920 | H6: =前提!H18+分社化・合併!H36 -> 2720 | I6: =前提!I18+分社化・合併!I36 -> 2720 | J6: 合併年度以降は BM 分▲280
B7: 減価償却（金額） | C7: 億円 | E7: =前提!E19+分社化・合併!E37 -> 2794 | F7: =前提!F19+分社化・合併!F37 -> 2850 | G7: =前提!G19+分社化・合併!G37 -> 2600 | H7: =前提!H19+分社化・合併!H37 -> 2650 | I7: =前提!I19+分社化・合併!I37 -> 2700 | J7: 列は2028年度以降 BM 控除後。合併が2029年度なら2028年度に+270
B8: 前年売上（同一連結範囲） | C8: 億円 | E8: =連結PL!D6-分社化・合併!E7*N(D_石化!D14) -> 37040 | F8: =連結PL!E6-分社化・合併!F7*N(D_石化!E14) -> 38000 | G8: =連結PL!F6-分社化・合併!G7*N(D_石化!F14) -> 32972.382 | H8: =連結PL!G6-分社化・合併!H7*N(D_石化!G14) -> 34705.647 | I8: =連結PL!H6-分社化・合併!I7*N(D_石化!H14) -> 36452.356 | J8: 合併初年度は前年の BM 売上を除いて比べる
B9: 運転資本の増加 | C9: 億円 | E9: =前提!$D$131*(連結PL!E6-E8) -> 144 | F9: =前提!$D$131*(連結PL!F6-F8) -> 195.3573 | G9: =前提!$D$131*(連結PL!G6-G8) -> 259.98979 | H9: =前提!$D$131*(連結PL!H6-H8) -> 262.00625 | I9: =前提!$D$131*(連結PL!I6-I8) -> 193.30647 | J9: 売上増分×15%
B10: 当期利益（非支配含む） | C10: 億円 | E10: =連結PL!E18 -> 1976.1392 | F10: =連結PL!F18 -> 1901.7589 | G10: =連結PL!G18 -> -488.01279 | H10: =連結PL!H18 -> 2601.9218 | I10: =連結PL!I18 -> 2826.1298
B11: 減価償却 | C11: 億円 | E11: =E7 -> 2794 | F11: =F7 -> 2850 | G11: =G7 -> 2600 | H11: =H7 -> 2650 | I11: =I7 -> 2700
B12: 非資金の非経常（合併除外損益の戻し、税後） | C12: 億円 | E12: =-連結PL!E17 -> 0 | F12: =-連結PL!F17 -> 0 | G12: =-連結PL!G17 -> 2696.7176 | H12: =-連結PL!H17 -> 0 | I12: =-連結PL!I17 -> 0 | J12: 税効果は繰延税金資産（BS）で受け、現金の税負担減とはしない
B13: 持分法損益（非資金） | C13: 億円 | E13: =-連結PL!E8 -> 0 | F13: =-連結PL!F8 -> 0 | G13: =-連結PL!G8 -> 55.74229 | H13: =-連結PL!H8 -> 6.7422902 | I13: =-連結PL!I8 -> -45.628855
B14: 運転資本の増加 | C14: 億円 | E14: =-E9 -> -144 | F14: =-F9 -> -195.3573 | G14: =-G9 -> -259.98979 | H14: =-H9 -> -262.00625 | I14: =-I9 -> -193.30647
B15: 営業CF | C15: 億円 | E15: =E10+E11+E12+E13+E14 -> 4626.1392 | F15: =F10+F11+F12+F13+F14 -> 4556.4016 | G15: =G10+G11+G12+G13+G14 -> 4604.4573 | H15: =H10+H11+H12+H13+H14 -> 4996.6578 | I15: =I10+I11+I12+I13+I14 -> 5287.1945
B16: 設備投資 | C16: 億円 | E16: =-E6 -> -3391 | F16: =-F6 -> -3300 | G16: =-G6 -> -2920 | H16: =-H6 -> -2720 | I16: =-I6 -> -2720
B17: 投資CF | C17: 億円 | E17: =E16 -> -3391 | F17: =F16 -> -3300 | G17: =G16 -> -2920 | H17: =H16 -> -2720 | I17: =I16 -> -2720
B18: フリーCF | C18: 億円 | E18: =E15+E17 -> 1235.1392 | F18: =F15+F17 -> 1256.4016 | G18: =G15+G17 -> 1684.4573 | H18: =H15+H17 -> 2276.6578 | I18: =I15+I17 -> 2567.1945
B19: 配当（親会社株主） | C19: 億円 | E19: =-連結PL!E23 -> -447.60387 | F19: =-連結PL!F23 -> -434.784 | G19: =-連結PL!G23 -> -434.784 | H19: =-連結PL!H23 -> -631.26468 | I19: =-連結PL!I23 -> -697.58141
B20: 配当（非支配株主） | C20: 億円 | E20: =-連結PL!E24 -> -141 | F20: =-連結PL!F24 -> -147.87805 | G20: =-連結PL!G24 -> -155.4439 | H20: =-連結PL!H24 -> -163.00976 | I20: =-連結PL!I24 -> -170.57561
B21: 借入の増減（現金一定） | C21: 億円 | E21: =-(E18+E19+E20) -> -646.53533 | F21: =-(F18+F19+F20) -> -673.73959 | G21: =-(G18+G19+G20) -> -1094.2294 | H21: =-(H18+H19+H20) -> -1482.3834 | I21: =-(I18+I19+I20) -> -1699.0374
B22: 財務CF | C22: 億円 | E22: =E19+E20+E21 -> -1235.1392 | F22: =F19+F20+F21 -> -1256.4016 | G22: =G19+G20+G21 -> -1684.4573 | H22: =H19+H20+H21 -> -2276.6578 | I22: =I19+I20+I21 -> -2567.1945
B23: 現金の増減 | C23: 億円 | E23: =E15+E17+E22 -> 0 | F23: =F15+F17+F22 -> 0 | G23: =G15+G17+G22 -> 0 | H23: =H15+H17+H22 -> 0 | I23: =I15+I17+I22 -> 0
B24: 非資金：合弁へ移る有利子負債 | C24: 億円 | E24: =-分社化・合併!E26 -> 0 | F24: =-分社化・合併!F26 -> 0 | G24: =-分社化・合併!G26 -> -500 | H24: =-分社化・合併!H26 -> 0 | I24: =-分社化・合併!I26 -> 0
B25: 純有利子負債（CF 由来） | C25: 億円 | D25: =前提!$D$129 -> 14648 | E25: =D25+E21+E24 -> 14001.465 | F25: =E25+F21+F24 -> 13327.725 | G25: =F25+G21+G24 -> 11733.496 | H25: =G25+H21+H24 -> 10251.112 | I25: =H25+I21+I24 -> 8552.0748
B27: ケースB（JSRあり）
B28: 設備投資（金額） | C28: 億円 | E28: =E6+D_JSR!E29*前提!$D$152 -> 3391 | F28: =F6+D_JSR!F29*前提!$D$152 -> 3300 | G28: =G6+D_JSR!G29*前提!$D$152 -> 2920 | H28: =H6+D_JSR!H29*前提!$D$152 -> 2720 | I28: =I6+D_JSR!I29*前提!$D$152 -> 2720 | J28: ＋JSR 連結後300
B29: 減価償却（金額） | C29: 億円 | E29: =E7+D_JSR!E29*前提!$D$151 -> 2794 | F29: =F7+D_JSR!F29*前提!$D$151 -> 2850 | G29: =G7+D_JSR!G29*前提!$D$151 -> 2600 | H29: =H7+D_JSR!H29*前提!$D$151 -> 2650 | I29: =I7+D_JSR!I29*前提!$D$151 -> 2700 | J29: ＋JSR 492
B30: 前年売上（同一連結範囲） | C30: 億円 | E30: =連結PL!D29-分社化・合併!E7*N(D_石化!D14)+D_JSR!E26*N(D_JSR!D14) -> 37040 | F30: =連結PL!E29-分社化・合併!F7*N(D_石化!E14)+D_JSR!F26*N(D_JSR!E14) -> 38000 | G30: =連結PL!F29-分社化・合併!G7*N(D_石化!F14)+D_JSR!G26*N(D_JSR!F14) -> 32972.382 | H30: =連結PL!G29-分社化・合併!H7*N(D_石化!G14)+D_JSR!H26*N(D_JSR!G14) -> 34705.647 | I30: =連結PL!H29-分社化・合併!I7*N(D_石化!H14)+D_JSR!I26*N(D_JSR!H14) -> 36452.356 | J30: 全額取得年度は前年の JSR 売上を足して比べる
B31: 運転資本の増加 | C31: 億円 | E31: =前提!$D$131*(連結PL!E29-E30) -> 144 | F31: =前提!$D$131*(連結PL!F29-F30) -> 195.3573 | G31: =前提!$D$131*(連結PL!G29-G30) -> 259.98979 | H31: =前提!$D$131*(連結PL!H29-H30) -> 262.00625 | I31: =前提!$D$131*(連結PL!I29-I30) -> 193.30647 | J31: 売上増分×15%
B32: 当期利益（非支配含む） | C32: 億円 | E32: =連結PL!E41 -> 1976.1392 | F32: =連結PL!F41 -> 1932.1572 | G32: =連結PL!G41 -> -410.87523 | H32: =連結PL!H41 -> 2700.992 | I32: =連結PL!I41 -> 3039.3894
B33: 減価償却 | C33: 億円 | E33: =E29 -> 2794 | F33: =F29 -> 2850 | G33: =G29 -> 2600 | H33: =H29 -> 2650 | I33: =I29 -> 2700
B34: 非資金の非経常（合併除外損益の戻し、税後） | C34: 億円 | E34: =-連結PL!E40 -> 0 | F34: =-連結PL!F40 -> 0 | G34: =-連結PL!G40 -> 2696.7176 | H34: =-連結PL!H40 -> 0 | I34: =-連結PL!I40 -> 0 | J34: 税効果は繰延税金資産（BS）で受け、現金の税負担減とはしない
B35: 持分法損益（非資金） | C35: 億円 | E35: =-連結PL!E31 -> 0 | F35: =-連結PL!F31 -> -44.998283 | G35: =-連結PL!G31 -> -51.262617 | H35: =-連結PL!H31 -> -126.67516 | I35: =-連結PL!I31 -> -329.32368
B36: 運転資本の増加 | C36: 億円 | E36: =-E31 -> -144 | F36: =-F31 -> -195.3573 | G36: =-G31 -> -259.98979 | H36: =-H31 -> -262.00625 | I36: =-I31 -> -193.30647
B37: 営業CF | C37: 億円 | E37: =E32+E33+E34+E35+E36 -> 4626.1392 | F37: =F32+F33+F34+F35+F36 -> 4541.8016 | G37: =G32+G33+G34+G35+G36 -> 4574.59 | H37: =H32+H33+H34+H35+H36 -> 4962.3106 | I37: =I32+I33+I34+I35+I36 -> 5216.7593
B38: 設備投資 | C38: 億円 | E38: =-E28 -> -3391 | F38: =-F28 -> -3300 | G38: =-G28 -> -2920 | H38: =-H28 -> -2720 | I38: =-I28 -> -2720
B39: JSR 株式の取得（第1段・追加取得） | C39: 億円 | E39: =-D_JSR!E35 -> 0 | F39: =-D_JSR!F35 -> -2000 | G39: =-D_JSR!G35 -> -31.108804 | H39: =-D_JSR!H35 -> -276.97324 | I39: =-D_JSR!I35 -> -2402.7571
B40: JSR 全額取得（残り株式） | C40: 億円 | E40: =-D_JSR!E34 -> 0 | F40: =-D_JSR!F34 -> 0 | G40: =-D_JSR!G34 -> 0 | H40: =-D_JSR!H34 -> 0 | I40: =-D_JSR!I34 -> 0
B41: 投資CF | C41: 億円 | E41: =E38+E39+E40 -> -3391 | F41: =F38+F39+F40 -> -5300 | G41: =G38+G39+G40 -> -2951.1088 | H41: =H38+H39+H40 -> -2996.9732 | I41: =I38+I39+I40 -> -5122.7571
B42: フリーCF | C42: 億円 | E42: =E37+E41 -> 1235.1392 | F42: =F37+F41 -> -758.19836 | G42: =G37+G41 -> 1623.4812 | H42: =H37+H41 -> 1965.3374 | I42: =I37+I41 -> 94.002184
...

Sheet 分社化・合併
B1: 分社化・合併（BM の切り出しと持分法化）
B2: 分社化（2027年度、会社分割で子会社化と仮定）は連結 BS 不変。合併（期首）で BM を連結除外し、合弁株式を公正価値で計上
B4: 項目 | C4: 単位 | D4: 2025年度 | E4: 2026年度 | F4: 2027年度 | G4: 2028年度 | H4: 2029年度 | I4: 2030年度 | J4: 出所・算式
B5: 年度判定
B6: 合併後フラグ（1＝持分法） | E6: =IF(前提!E$6>=前提!$D$25,1,0) -> 0 | F6: =IF(前提!F$6>=前提!$D$25,1,0) -> 0 | G6: =IF(前提!G$6>=前提!$D$25,1,0) -> 1 | H6: =IF(前提!H$6>=前提!$D$25,1,0) -> 1 | I6: =IF(前提!I$6>=前提!$D$25,1,0) -> 1 | J6: 前提の合併年度で切替
B7: 合併初年度フラグ | E7: =IF(前提!E$6=前提!$D$25,1,0) -> 0 | F7: =IF(前提!F$6=前提!$D$25,1,0) -> 0 | G7: =IF(前提!G$6=前提!$D$25,1,0) -> 1 | H7: =IF(前提!H$6=前提!$D$25,1,0) -> 0 | I7: =IF(前提!I$6=前提!$D$25,1,0) -> 0
B8: 分社化年度フラグ | E8: =IF(前提!E$6=前提!$D$97,1,0) -> 0 | F8: =IF(前提!F$6=前提!$D$97,1,0) -> 1 | G8: =IF(前提!G$6=前提!$D$97,1,0) -> 0 | H8: =IF(前提!H$6=前提!$D$97,1,0) -> 0 | I8: =IF(前提!I$6=前提!$D$97,1,0) -> 0
B9: 分社化の一時費用（非経常） | C9: 億円 | E9: =E8*前提!$D$98 -> 0 | F9: =F8*前提!$D$98 -> -50 | G9: =G8*前提!$D$98 -> 0 | H9: =H8*前提!$D$98 -> 0 | I9: =I8*前提!$D$98 -> 0
B11: 切り出し BS（2025年度末ベース、仮定）
B12: 資産 | C12: 億円 | D12: =前提!$D$99 -> 6000 | J12: BM&P セグメント資産6,999から炭素分を控除
B13: 営業負債 | C13: 億円 | D13: =前提!$D$100 -> 700
B14: 配分する有利子負債 | C14: 億円 | D14: =前提!$D$101 -> 500
B15: 純資産 | C15: 億円 | D15: =D12-D13-D14 -> 4800
B16: 正味営業資産（資産−営業負債） | C16: 億円 | D16: =D12-D13 -> 5300
B18: 合弁の公正価値と除外損益
B19: BM の中間 EBITDA（2026〜30年度のコア平均＋減価償却） | C19: 億円 | D19: =AVERAGE(D_石化!$E$13:$I$13)+前提!$D$106 -> 241.25771 | J19: 「中間」は5年平均と解釈（追加の仮定）
B20: 合弁 EV（2×中間EBITDA×倍率） | C20: 億円 | D20: =前提!$D$103*D19*前提!$D$107 -> 2895.0925
B21: 合弁株式の公正価値（倍率法：50%×EV−配分負債） | C21: 億円 | D21: =前提!$D$102*D20-D14 -> 947.54626
B22: 合弁株式の計上額（切替後） | C22: 億円 | D22: =IF(前提!$D$26=1,D21,D15) -> 947.54626 | J22: 1＝倍率法、2＝簿価
B23: 合併除外損益（税前、非経常） | C23: 億円 | E23: =E7*($D$22-$D$15) -> 0 | F23: =F7*($D$22-$D$15) -> 0 | G23: =G7*($D$22-$D$15) -> -3852.4537 | H23: =H7*($D$22-$D$15) -> 0 | I23: =I7*($D$22-$D$15) -> 0 | J23: IFRS10：残存持分の再測定。公正価値−除外純資産
B24: 合併除外損益（税後、税効果30%） | C24: 億円 | E24: =E23*(1-前提!$D$108) -> 0 | F24: =F23*(1-前提!$D$108) -> 0 | G24: =G23*(1-前提!$D$108) -> -2696.7176 | H24: =H23*(1-前提!$D$108) -> 0 | I24: =I23*(1-前提!$D$108) -> 0
B25: 連結から外れる正味営業資産 | C25: 億円 | E25: =E7*$D$16 -> 0 | F25: =F7*$D$16 -> 0 | G25: =G7*$D$16 -> 5300 | H25: =H7*$D$16 -> 0 | I25: =I7*$D$16 -> 0
B26: 合弁へ移る有利子負債（非資金） | C26: 億円 | E26: =E7*$D$14 -> 0 | F26: =F7*$D$14 -> 0 | G26: =G7*$D$14 -> 500 | H26: =H7*$D$14 -> 0 | I26: =I7*$D$14 -> 0
B27: 合弁株式の計上 | C27: 億円 | E27: =E7*$D$22 -> 0 | F27: =F7*$D$22 -> 0 | G27: =G7*$D$22 -> 947.54626 | H27: =H7*$D$22 -> 0 | I27: =I7*$D$22 -> 0
B29: 連結範囲と持分法利益
B30: 連結に含める BM 売上 | C30: 億円 | E30: =D_石化!E14*(1-E6) -> 6830 | F30: =D_石化!F14*(1-F6) -> 6330 | G30: =D_石化!G14*(1-G6) -> 0 | H30: =D_石化!H14*(1-H6) -> 0 | I30: =D_石化!I14*(1-I6) -> 0
B31: 連結に含める BM コア営業利益 | C31: 億円 | E31: =D_石化!E13*(1-E6) -> -50 | F31: =D_石化!F13*(1-F6) -> -119.63184 | G31: =D_石化!G13*(1-G6) -> 0 | H31: =D_石化!H13*(1-H6) -> 0 | I31: =D_石化!I13*(1-I6) -> 0
B32: 統合効果（初年度0、2年目以降） | C32: 億円 | E32: =IF(前提!E$6>前提!$D$25,前提!$D$104,0) -> 0 | F32: =IF(前提!F$6>前提!$D$25,前提!$D$104,0) -> 0 | G32: =IF(前提!G$6>前提!$D$25,前提!$D$104,0) -> 0 | H32: =IF(前提!H$6>前提!$D$25,前提!$D$104,0) -> 100 | I32: =IF(前提!I$6>前提!$D$25,前提!$D$104,0) -> 100
B33: 合弁の利益（当社 BM コア×2＋統合効果） | C33: 億円 | E33: =E6*(前提!$D$103*D_石化!E13+E32) -> 0 | F33: =F6*(前提!$D$103*D_石化!F13+F32) -> 0 | G33: =G6*(前提!$D$103*D_石化!G13+G32) -> -159.26369 | H33: =H6*(前提!$D$103*D_石化!H13+H32) -> -19.263686 | I33: =I6*(前提!$D$103*D_石化!I13+I32) -> 130.36816
B34: 当社持分法利益（50%×合弁利益×(1−30%)、コアに含む） | C34: 億円 | E34: =前提!$D$102*E33*(1-前提!$D$105) -> 0 | F34: =前提!$D$102*F33*(1-前提!$D$105) -> 0 | G34: =前提!$D$102*G33*(1-前提!$D$105) -> -55.74229 | H34: =前提!$D$102*H33*(1-前提!$D$105) -> -6.7422902 | I34: =前提!$D$102*I33*(1-前提!$D$105) -> 45.628855
B35: 合弁株式の残高（配当なし、持分法損益を積み上げ） | C35: 億円 | E35: =N(D35)+E27+E34 -> 0 | F35: =N(E35)+F27+F34 -> 0 | G35: =N(F35)+G27+G34 -> 891.80397 | H35: =N(G35)+H27+H34 -> 885.06168 | I35: =N(H35)+I27+I34 -> 930.69053
B36: 設備投資の控除（BM 分） | C36: 億円 | E36: =-E6*前提!$D$109 -> 0 | F36: =-F6*前提!$D$109 -> 0 | G36: =-G6*前提!$D$109 -> -280 | H36: =-H6*前提!$D$109 -> -280 | I36: =-I6*前提!$D$109 -> -280
B37: 減価償却の調整（列は2028年度以降 BM 控除後。合併前の年度は BM 分を足し戻す） | C37: 億円 | E37: =(1-E6)*IF(前提!E$6>=前提!$D$111,前提!$D$110,0) -> 0 | F37: =(1-F6)*IF(前提!F$6>=前提!$D$111,前提!$D$110,0) -> 0 | G37: =(1-G6)*IF(前提!G$6>=前提!$D$111,前提!$D$110,0) -> 0 | H37: =(1-H6)*IF(前提!H$6>=前提!$D$111,前提!$D$110,0) -> 0 | I37: =(1-I6)*IF(前提!I$6>=前提!$D$111,前提!$D$110,0) -> 0
B38: 注1：合弁は配当を出さないと仮定し、持分法損益は合弁株式の残高に積み上げる（CF では非資金として控除）。
