Workbook
Name ERW_DCF_PRICE: 計算_DCF!$C$53
Name ERW_EXPECTED: 計算_シナリオ!$D$8
Name ERW_FCF1: 計算_DCF!$C$41
Name ERW_FM_CHECKS: データ_整合検査!$D$6:$K$11
Name ERW_FM_OP1: '3_Forecast'!$I$14
Name ERW_LIVE: 検証!$F$18:$F$29
Name ERW_LIVE_LABELS: 検証!$B$18:$B$29
Name ERW_PRICE_BASE: 計算_シナリオ!$C$67
Name ERW_PRICE_BEAR: 計算_シナリオ!$C$189
Name ERW_PRICE_BULL: 計算_シナリオ!$C$128
Name ERW_REV1: 計算_DCF!$C$33
Name ERW_SCEN: '2_投資判断'!$C$4
Name ERW_SENS1: 計算_DCF!$E$66
Name ERW_SENS2: 計算_DCF!$E$76
Name ERW_TARGET: '2_投資判断'!$C$150

Sheet 表紙
B2: 企業調査レポート
B4: Texas Instruments（TXN）
B6: 証券コード | C6: TXN
B7: 基準日 | C7: 2026-10-23
B8: 作成日 | C8: 2026-10-24
B9: レーティング | C9: ='2_投資判断'!$C$8 -> 回避
B10: 目標株価 | C10: ='2_投資判断'!$C$12 -> 128.72754
B11: 現在株価 | C11: ='2_投資判断'!$C$11 -> 279.5
B12: 上昇余地 | C12: ='2_投資判断'!$C$12/'2_投資判断'!$C$11-1 -> -0.53943637
B14: 作成:
B16: 目次
B17: シート | C17: 内容
B18: 1_企業分析 | C18: 企業概要・株価とバリュエーション推移・類似企業比較・事業内容（セグメント構成比・主力製品と世界シェア）・社長の来歴・SWOT・関連市況
B19: 2_投資判断 | C19: 投資判断・市場の注目点・伸びる点と懸念点・目標株価と倍率翻訳・DCF の要約と感応度
B20: 3_Summary | C20: 業績予想：主要財務の要約（0054 財務モデル）
B21: 3_PL | C21: 業績予想：損益計算書
B22: 3_BS | C22: 業績予想：貸借対照表
B23: 3_CF | C23: 業績予想：キャッシュフロー計算書
B24: 3_セグメント売上 | C24: 業績予想：セグメント別売上
B25: 3_地域別売上 | C25: 業績予想：地域別売上
B26: 3_Forecast | C26: 業績予想：3期予測の計算
B27: 3_Assumptions | C27: 業績予想の前提（シナリオ別入力を含む）
B28: 計算_DCF | C28: 計算：WACC・DCF・感応度表・SOTP の計算過程
... B37: 検証 | C37: 検証：再計算・数式・静的検査の結果と計算上の取り扱い
B39: 本資料は情報提供を目的として作成したもので、投資勧誘や投資助言ではありません。

Sheet 1_企業分析
B1: TXN Texas Instruments 企業分析
B2: 基準日 2026-10-23／決算期末 12月／出所列の ID は「出典」シートを参照
B4: ① 企業概要 | M4: 出所
B5: 項目 | C5: 内容 | K5: 備考
B6: 社名／ティッカー／上場市場 | C6: Texas Instruments Incorporated（TI、デラウェア州法人）／TXN／Nasdaq Global Select Market | K6: SEC CIK 0000097476。アナログ・組込みプロセッサ半導体の設計・製造・販売 | M6: F1-S1,F1-S4
B7: 本社・設立 | C7: 米国テキサス州ダラス（12500 TI Boulevard）。30か国超で設計・製造・販売拠点を持つ。事業開始は1930年 | K7: 2025年12月31日時点。10-K Item 1 の記載 | M7: F1-S1,F1-S4
B8: 従業員数 | C8: 約33,000人（約90%が R&D・営業・製造）。2025年の離職率10.1% | K8: 2025年12月31日時点 | M8: F1-S1
B9: 決算期 | C9: 12月（暦年） | K9: 直近四半期は2026年7〜9月期（Q3'26）。決算発表は2026-10-21引け後 | M9: F1-S1
B10: 事業の一言 | C10: 電源・信号処理などのアナログ半導体（売上の約79%）と、マイコン・プロセッサなどの組込みプロセッサ（約15%）を、300mmウエハーの自社工場で作り、80%超を直販する。顧客10万社超、製品8万点超 | K10: FY2025。売上構成はアナログ$14,006M・組込み$2,697M・その他$979M（その他にDLP・電卓・ASIC） | M10: F1-S1
B11: 直近通期業績（FY2025：2025年12月期） | C11: 売上高$17,682M（前年比+13.0%）、営業利益$6,023M（営業利益率34.1%）、純利益$5,001M、希薄化後EPS $5.45 | K11: 粗利率57.0%（前年58.1%）。営業利益にはリストラ費用等$117M（150mm工場2拠点閉鎖計画・ASIC関連のれん減損を含む）を含む | M11: F1-S1
B12: 直近四半期（Q3'26：2026年7〜9月期） | C12: 売上高$6,055M（前年同期比+28%、前期比+11%）、粗利率64.2%（前年同期57.4%）、営業利益$2,874M（営業利益率47.5%、前年同期35.1%、営業利益+73%）、純利益$2,425M、EPS $2.62 | K12: 粗利率・営業利益率は売上・粗利・営業利益から算出（推定ではなく算術）。EPSには会社ガイダンス外の$0.01のマイナス（離散税項目）を含む。Q4'26ガイダンス：売上$5.80〜6.30B、EPS $2.45〜2.79（レンジ中央の売上$6.05B） | M12: F1-S2,F1-S6
B13: セグメント別（Q3'26） | C13: アナログ売上$4,911M（前年比+32%、営業利益率51.0%）、組込み$858M（+21%、26.5%）、その他$286M（-6%） | K13: 営業利益率はセグメント営業利益÷売上から算出。アナログ営業利益$2,505M、組込み$227M、その他$142M（買収費用・リストラ費用を含む） | M13: F1-S2
B14: 最終市場構成（FY2025、10-K） | C14: 産業33%、車載33%、パーソナルエレクトロニクス21%、データセンター9%、通信機器3%（ほかに電卓が約1%） | K14: FY2025推計売上比。2025年に市場区分を組み替え済み（データセンターを独立区分化） | M14: F1-S1
B15: 最終市場の直近動向（Q3'26） | C15: 産業は前年比+40%超で約4年ぶりのピーク更新、車載は+10%台半ば、データセンターは約+95%で売上の約13%、パーソナルエレクトロニクスはほぼ横ばい、通信機器は前年比・前期比とも増 | K15: （二次・未確認）の部分：具体的な伸び率と構成比13%は決算コール書き起こし（二次）の記載。TI公式の決算リリースは『産業・車載・データセンターで広範な成長』とのみ記載 | M15: F1-S6,F1-S2
B16: 地域別売上（顧客本社所在地ベース、FY2025） | C16: 米国38%($6,763M)、中国21%($3,781M)、欧州・中東・アフリカ21%($3,747M、うちドイツ顧客10%)、アジア他11%、日本7%($1,173M)、その他2%。出荷先ベースでは中国向けが約50% | K16: 顧客本社が米国外の売上は約60%。中国比率は本社所在地ベース（約20〜21%）と出荷先ベース（約50%）で大きく異なる点に注意 | M16: F1-S1
B17: 配当 | C17: 四半期配当$1.42（Q3'26宣言額）から$1.52へ7%増額予定（年換算$6.08）、23年連続の増配。支払日2026-11-10、基準日2026-10-30 | K17: 増額は10月の取締役会での正式宣言が条件（9/17付8-K）。直近12か月の配当支払$5,174M・自社株買い$636M、合計還元$5,810M。会社方針は長期にフリーキャッシュフローの全額還元 | M17: F1-S4,F1-S2
B18: 係属中のM&A：Silicon Labs（SLAB）買収 | C18: 1株$231現金、企業価値約$7.5B、2027年上期の完了見込み。約1,200製品の無線接続製品群を獲得し、完了後3年以内に年$450M規模の製造・運営シナジーを見込む。連結数値には未反映 | K18: 資金は手元資金と負債（2026年6月に最大$5Bの364日つなぎ融資枠を設定、6/30時点で未借入）。SLAB株主総会は2026-04-30に承認（二次）、米HSRは2026-05-22に待機期間満了（SLAB 8-K、ミラー経由）、中国など他の規制承認の状況は未確認 | M18: F1-S5,F1-S3,F1-S7
B37: 図1：1930年創業・8万品目・顧客10万社超（TI at a glance）（出所：会社資料 3） | M37: F7-S1
B39: ② 株価・バリュエーション推移 | M39: 出所
B40: 現在値と過去レンジ（月次）
B41: 指標 | C41: 現在値 | D41: 最小 | E41: 中央値 | F41: 最大 | G41: 現在の位置 | H41: 観測数
B42: 株価（ドル、調整後月末） | C42: =IF(ISNUMBER(データ_株価!$C$6),データ_株価!$C$6,"n.a.") -> 279.5 | D42: =IF(COUNT(データ_株価!$H$5:$H$65)=0,"n.a.",MIN(データ_株価!$H$5:$H$65)) -> 131.5218 | E42: =IF(COUNT(データ_株価!$H$5:$H$65)=0,"n.a.",MEDIAN(データ_株価!$H$5:$H$65)) -> 165.1917 | F42: =IF(COUNT(データ_株価!$H$5:$H$65)=0,"n.a.",MAX(データ_株価!$H$5:$H$65)) -> 304.1229 | G42: =IF(AND(COUNT(データ_株価!$H$5:$H$65)>0,ISNUMBER(C42)),COUNTIF(データ_株価!$H$5:$H$65,"<="&C42)/COUNT(データ_株価!$H$5:$H$65),"n.a.") -> 0.95081967 | H42: =COUNT(データ_株価!$H$5:$H$65) -> 61
B43: PER（実績） | C43: =IF(ISNUMBER(データ_株価!$N$65),データ_株価!$N$65,"n.a.") -> 36.251621 | D43: =IF(COUNT(データ_株価!$N$5:$N$65)=0,"n.a.",MIN(データ_株価!$N$5:$N$65)) -> 16.837527 | E43: =IF(COUNT(データ_株価!$N$5:$N$65)=0,"n.a.",MEDIAN(データ_株価!$N$5:$N$65)) -> 27.522621 | F43: =IF(COUNT(データ_株価!$N$5:$N$65)=0,"n.a.",MAX(データ_株価!$N$5:$N$65)) -> 52.342464 | G43: =IF(AND(COUNT(データ_株価!$N$5:$N$65)>0,ISNUMBER(C43)),COUNTIF(データ_株価!$N$5:$N$65,"<="&C43)/COUNT(データ_株価!$N$5:$N$65),"n.a.") -> 0.7704918 | H43: =COUNT(データ_株価!$N$5:$N$65) -> 61
B44: PBR | C44: =IF(ISNUMBER(データ_株価!$C$15),データ_株価!$C$15,"n.a.") -> 13.304807 | D44: =IF(COUNT(データ_株価!$O$5:$O$65)=0,"n.a.",MIN(データ_株価!$O$5:$O$65)) -> 7.7550393 | E44: =IF(COUNT(データ_株価!$O$5:$O$65)=0,"n.a.",MEDIAN(データ_株価!$O$5:$O$65)) -> 10.658502 | F44: =IF(COUNT(データ_株価!$O$5:$O$65)=0,"n.a.",MAX(データ_株価!$O$5:$O$65)) -> 16.581068 | G44: =IF(AND(COUNT(データ_株価!$O$5:$O$65)>0,ISNUMBER(C44)),COUNTIF(データ_株価!$O$5:$O$65,"<="&C44)/COUNT(データ_株価!$O$5:$O$65),"n.a.") -> 0.85245902 | H44: =COUNT(データ_株価!$O$5:$O$65) -> 61
B45: 配当利回り（実績TTM） | C45: =IF(ISNUMBER(データ_株価!$C$16),データ_株価!$C$16,"n.a.") -> 0.020322004 | D45: =IF(COUNT(データ_株価!$P$5:$P$65)=0,"n.a.",MIN(データ_株価!$P$5:$P$65)) -> 0.018188956 | E45: =IF(COUNT(データ_株価!$P$5:$P$65)=0,"n.a.",MEDIAN(データ_株価!$P$5:$P$65)) -> 0.026570526 | F45: =IF(COUNT(データ_株価!$P$5:$P$65)=0,"n.a.",MAX(データ_株価!$P$5:$P$65)) -> 0.034927119 | G45: =IF(AND(COUNT(データ_株価!$P$5:$P$65)>0,ISNUMBER(C45)),COUNTIF(データ_株価!$P$5:$P$65,"<="&C45)/COUNT(データ_株価!$P$5:$P$65),"n.a.") -> 0.081967213 | H45: =COUNT(データ_株価!$P$5:$P$65) -> 61
B46: EV/EBITDA | C46: =IF(ISNUMBER(データ_株価!$C$17),データ_株価!$C$17,"n.a.") -> 24.487152 | D46: =IF(COUNT(データ_株価!$Q$5:$Q$65)=0,"n.a.",MIN(データ_株価!$Q$5:$Q$65)) -> 12.750617 | E46: =IF(COUNT(データ_株価!$Q$5:$Q$65)=0,"n.a.",MEDIAN(データ_株価!$Q$5:$Q$65)) -> 20.140637 | F46: =IF(COUNT(データ_株価!$Q$5:$Q$65)=0,"n.a.",MAX(データ_株価!$Q$5:$Q$65)) -> 33.615565 | G46: =IF(AND(COUNT(データ_株価!$Q$5:$Q$65)>0,ISNUMBER(C46)),COUNTIF(データ_株価!$Q$5:$Q$65,"<="&C46)/COUNT(データ_株価!$Q$5:$Q$65),"n.a.") -> 0.68852459 | H46: =COUNT(データ_株価!$Q$5:$Q$65) -> 61
B47: 注1：現在値はスナップショット（PER 実績は月次の最新値）。現在の位置は月次観測のうち現在値以下の割合
B48: 注2：会社予想 EPS が開示されないため PER（予想）は掲載しない。PER・配当利回りは実績 TTM
B50: 株式の概要
B51: 項目 | C51: 値
B52: 時価総額（百万ドル） | C52: =IF(ISNUMBER(データ_株価!$C$9),データ_株価!$C$9/1000000,"n.a.") -> 255252.73
B53: 売買代金 60日平均（百万ドル） | C53: =IF(ISNUMBER(データ_株価!$C$10),データ_株価!$C$10/1000000,"n.a.") -> 1676.2836
B54: 売買代金 60日平均（億円、円換算） | C54: =IF(ISNUMBER(データ_株価!$C$11),データ_株価!$C$11/100000000,"n.a.") -> 2648.528
B55: 発行済株式数（百万株、自己株控除後） | C55: =IF(ISNUMBER(データ_株価!$C$7),データ_株価!$C$7/1000000,"n.a.") -> 913.24769
B56: 純有利子負債（百万ドル） | C56: =IF(ISNUMBER(データ_株価!$C$12),データ_株価!$C$12/1000000,"n.a.") -> 5413
B73: 出所：Yahoo Finance（yfinance）・SEC EDGAR より作成
B90: 出所：Yahoo Finance（yfinance）・SEC EDGAR より作成
B92: ・過去5年の株価は3局面。2021-10-21の終値$201.29(5年窓の起点付近の高値)から下落し、2023-10-30に$140.50(同-30%)、2025-04-21に$145.61まで調整。その後2026年に急回復し、2026-06-22の終値$332.28が窓内の最高値。2026-10-22の$279.50は最高値比約-16%。 | M92: F4-S4 ※二次
B93: ・2026年の上昇は決算で段階的に起きた。2025年末$173.49→Q1決算翌日(4/23)に+19.4%→6月高値。7月決算後(7/23)は-3.1%で下落基調となり、2026-09-01に$253.34(高値比-24%)まで調整、10月に$280台へ戻した。2026年初来は10/22時点で約+61%。 | M93: F4-S4 ※二次
B94: ・直近の決算反応は非対称。Q3'26は売上・EPS・Q4ガイダンスのいずれもコンセンサス超え(売上$6,055M対約$5.92B、EPS$2.62対約$2.42、Q4中央値も上回る)だったが、10/22は-1.81%で出来高は直前20日平均の約2.5倍。7月(Q2)も-3.1%と、期待が高い局面でビートが売りで返される傾向がある。 | M94: F4-S1,F4-S4,F4-S10
...

Sheet 2_投資判断
B1: TXN Texas Instruments 投資判断・目標株価
B2: 基準日 2026-10-23／金額は百万ドル（株価はドル）／計算過程は 計算_DCF・計算_シナリオ を参照
B4: シナリオ切替（1=base, 2=bull, 3=bear） | C4: 1 | D4: =CHOOSE(C4,"base","bull","bear") -> base | E4: 表示中シナリオ（切替セル）のDCF理論株価 | I4: =計算_DCF!$C$53 -> 128.72754
B6: ① 投資判断 | N6: 出所
B7: 項目 | C7: 値
B8: レーティング | C8: 回避
B9: 確信度（1〜5） | C9: 3
B10: 投資期間 | C10: 6〜18か月（2027年1月の Q4 決算・2月の資本管理説明会から、2027年後半のサイクル判定まで）
B11: 現在株価（2026-10-22） | C11: =データ_株価!$C$6 -> 279.5
B12: 目標株価（＝DCF理論株価 base） | C12: ='2_投資判断'!$C$150 -> 128.72754
B13: 上昇余地 | C13: ='2_投資判断'!$C$150/'2_投資判断'!$C$11-1 -> -0.53943637
B14: 確率加重期待値（base/bull/bear、各0ドル下限） | C14: =計算_シナリオ!$D$8 -> 128.8847
B15: 期待値ベースの上昇余地 | C15: =計算_シナリオ!$D$8/'2_投資判断'!$C$11-1 -> -0.53887408
B16: 注1：目標株価は base の DCF理論株価（シナリオ切替に依存しない）。切替は 3_Assumptions の上書き仮定と 計算_DCF に連動
B17: 注2：確率加重は各シナリオを0ドルで下限処理（株主の有限責任）。シナリオ表の理論株価は下限処理前の値
B18: 投資判断の要旨
B19: ・事業の質は高く、Q3'26 は売上 +28%・営業利益率 47.5% と回復は本物。ただし株価 $279.50 は直近12か月 EPS の約36倍・EV/EBITDA 24.5倍。米10年国債 5.13% を前提にした DCF は base $129・bull $173・bear $85（確率加重 $129）で、WACC を 8% まで下げても base は約 $179 にとどまる。逆DCFでは、現在株価は base の業績なら WACC 約 6.4%（β1.2 なら ERP 約1.1% 相当）を必要とし、2028年 +13%・粗利率 65% が続く強い業績パスでも約 8.2% を要する。市場は強い業績と低い割引率を同時に織り込んでおり、どちらか一方が外れれば下値余地が大きい。新規の買いは見送り、既存保有は下記の条件で縮小を検討する。なお「回避」は DCF の前提の幅には頑健だが、倍率法（PER 30倍）を採れば逆転するため、評価方法の選択には依存する。投資助言ではない。
B20: 反証条件（これが起きたら判断を撤回）
B21: ・【回避が誤りとなる条件 → Buy 再検討】株価が bull シナリオの理論株価（約 $173）以下に下落（現値比 約 −38%。実質的には見送りに近い条件）。 | N21: S2-S4 ※二次
B22: ・【再評価を起動（いずれか1つ、期限 2027年1月の Q4 決算日）】FQ1'27 売上ガイダンス中央値が $6.3B 以上。 | N22: F6-S1
B23: ・【同上】2027年の値上げを中位一桁%以上と開示。 | N23: F6-S4,F4-S2 ※二次
B24: ・【同上】粗利率 64% 以上を2四半期続けて維持（bull の粗利率前提が実現）。 | N24: F1-S2
B25: ・【前提の反証】米10年国債が 5% を超えたまま、TXN の EV/EBITDA が 20倍超で4四半期続き、業績が base 並みなら、市場の割引率は当方の想定（β1.2・ERP 4.2%）より構造的に低い。β・ERP の組合せを見直して DCF を再計算する。 | N25: S2-S1,S2-S2,S2-S4
B26: ・【既存保有者の売却を急ぐ条件（いずれか1つ）】FQ1'27 売上ガイダンス中央値が $5.6B 未満、在庫日数が2四半期連続で上昇し 210日超、または粗利率が2四半期連続で低下し 60% 割れ。 | N26: F6-S1,F6-S4
B27: ・【同上】補助金除き FCF の直近12か月売上比が 25% 割れ、または配当が補助金除き FCF の 100% 超。 | N27: F6-S1
B28: ・【同上】中国商務部が反ダンピング調査で暫定措置・延長を公告、または米中の停止措置が 2027-01-10 に延長されず失効。 | N28: F6-S7,F6-S13
B29: カタリスト
B30: 時期 | C30: イベント
B31: 2026-10-29 | C31: STMicroelectronics Q3 決算（受注・book-to-bill でダブルオーダーの程度を確認）
B32: 2026-10 下旬〜11 上旬 | C32: NXP（流通在庫週数）・Microchip の決算
B33: 2026-11 中旬 | C33: ADI FQ4'26 決算（需要と値上げの外部確認。日付未確認）
B34: 2026-12 | C34: WSTS 秋季予測（アナログ 2027年の成長率）
B35: 2027-01-10 | C35: 米中の関税・非関税措置の停止期限（反ダンピング調査の分岐点）
B36: 2027-01 下旬 | C36: Q4'26 決算と 2027年の価格交渉結果の開示（日付未確認）
B37: 2027-02 | C37: 資本管理説明会・2027年設備投資の設定（日付未確認）
B38: 2027 上期 | C38: Silicon Labs 買収の完了見込み（中国 SAMR の承認が条件）
B40: ② 市場の注目点（市場の見方と当社の見方） | N40: 出所
B41: テーマ | C41: 市場の見方 | H41: 当社の見方
B42: Q4'26ガイダンスと季節性（需要の強さ） | C42: Q4'26(10-12月期)売上ガイダンスは$5.80〜6.30B(中央値$6.05B)、EPSは$2.45〜2.79(中央値$2.62)。決算前のコンセンサスは売上約$5.73〜5.75B・EPS約$2.27〜2.29（二次・未確認）で、レンジ下限が市場予想を上回った。会社は「季節性を上回る」と説明し、理由にデータセンター、産業回復、車載を挙げた（二次の通話記録）。Q3'26実績は売上$6,055M(前年比+28%、前期比+11%)、EPS$2.62(税の離散項目で-$0.01)。ただしレンジ幅は$500Mと広く、中央値より下限が重要との指摘がある（二次）。 | H42: ガイダンスは市場予想を上回ったが、中央値は Q3 並み。前四半期比で横ばいを示した点を、成長の頭打ちの初期サインとみる。2027年の base は +7% と置き、FQ1'27 ガイダンス（1月）で確かめる。 | N42: F4-S1,F4-S2,F4-S10,F4-S11
B43: 粗利率と増分利益率（稼働率・300mm） | C43: Q3'26の粗利率は64.2%（粗利$3,887M÷売上$6,055M）、前期比+280bp。会社は主因を売上増とし、工場稼働、価格、製品・最終市場ミックスも寄与と説明した（二次の通話記録）。前期比の増分粗利率は約90%（Q2'26粗利率61.4%・売上$5,463Mは既知、司令塔計算）で、会社の長期目安75〜85%（二次）を上回る。Morgan Stanleyは粗利率のポジティブサプライズを指摘する一方、在庫水準が高くアナログの完全回復と呼ぶのは時期尚早とした（二次）。営業利益率は47.5%（営業利益$2,874M）。 | H43: 増分粗利率 約90% は稼働率の回復によるもので、毎期は続かない。減価償却が売上比 10% 超に増えたため、売上が下を向くと利益率の落ちも大きい。粗利率は 2027年 63% を上限に、2028年は 60.5% に戻すのが base。 | N43: F4-S1,F4-S2,F4-S3,F4-S8,F4-S20,F6-S5
...

Sheet 3_Summary
C2: TEXAS INSTRUMENTS INC Summary
C4: USD 百万単位。年次・連結実績。n.a. = 未抽出／対象外
C5: 項目 | D5: 2021-12-31 A | E5: 2022-12-31 A | F5: 2023-12-31 A | G5: 2024-12-31 A | H5: 2025-12-31 A | I5: 2026-12-31 E | J5: 2027-12-31 E | K5: 2028-12-31 E
C6: 売上高 | D6: =IF(AND(ISNUMBER('3_PL'!D6)),'3_PL'!D6,"n.a.") -> 18344 | E6: =IF(AND(ISNUMBER('3_PL'!E6)),'3_PL'!E6,"n.a.") -> 20028 | F6: =IF(AND(ISNUMBER('3_PL'!F6)),'3_PL'!F6,"n.a.") -> 17519 | G6: =IF(AND(ISNUMBER('3_PL'!G6)),'3_PL'!G6,"n.a.") -> 15641 | H6: =IF(AND(ISNUMBER('3_PL'!H6)),'3_PL'!H6,"n.a.") -> 17682 | I6: ='3_Forecast'!I8 -> 22387.166 | J6: ='3_Forecast'!J8 -> 23954.268 | K6: ='3_Forecast'!K8 -> 24912.438
C7: 営業利益 | D7: =IF(AND(ISNUMBER('3_PL'!D12)),'3_PL'!D12,"n.a.") -> 8960 | E7: =IF(AND(ISNUMBER('3_PL'!E12)),'3_PL'!E12,"n.a.") -> 10140 | F7: =IF(AND(ISNUMBER('3_PL'!F12)),'3_PL'!F12,"n.a.") -> 7331 | G7: =IF(AND(ISNUMBER('3_PL'!G12)),'3_PL'!G12,"n.a.") -> 5465 | H7: =IF(AND(ISNUMBER('3_PL'!H12)),'3_PL'!H12,"n.a.") -> 6023 | I7: ='3_Forecast'!I14 -> 9850.353 | J7: ='3_Forecast'!J14 -> 10923.146 | K7: ='3_Forecast'!K14 -> 10537.961
C8: 親会社株主帰属利益 | D8: =IF(AND(ISNUMBER('3_PL'!D17)),'3_PL'!D17,"n.a.") -> 7769 | E8: =IF(AND(ISNUMBER('3_PL'!E17)),'3_PL'!E17,"n.a.") -> 8749 | F8: =IF(AND(ISNUMBER('3_PL'!F17)),'3_PL'!F17,"n.a.") -> 6510 | G8: =IF(AND(ISNUMBER('3_PL'!G17)),'3_PL'!G17,"n.a.") -> 4799 | H8: =IF(AND(ISNUMBER('3_PL'!H17)),'3_PL'!H17,"n.a.") -> 5001 | I8: ='3_Forecast'!I21 -> 8392.8707 | J8: ='3_Forecast'!J21 -> 9177.7763 | K8: ='3_Forecast'!K21 -> 8844.5916
C9: 総資産 | D9: =IF(AND(ISNUMBER('3_BS'!D12)),'3_BS'!D12,"n.a.") -> 24676 | E9: =IF(AND(ISNUMBER('3_BS'!E12)),'3_BS'!E12,"n.a.") -> 27207 | F9: =IF(AND(ISNUMBER('3_BS'!F12)),'3_BS'!F12,"n.a.") -> 32348 | G9: =IF(AND(ISNUMBER('3_BS'!G12)),'3_BS'!G12,"n.a.") -> 35509 | H9: =IF(AND(ISNUMBER('3_BS'!H12)),'3_BS'!H12,"n.a.") -> 34585 | I9: ='3_Forecast'!I56 -> 38069.217 | J9: ='3_Forecast'!J56 -> 42283.406 | K9: ='3_Forecast'!K56 -> 46223.555
C10: 資本合計（非支配持分含む） | D10: =IF(AND(ISNUMBER('3_BS'!D16)),'3_BS'!D16,"n.a.") -> 13333 | E10: =IF(AND(ISNUMBER('3_BS'!E16)),'3_BS'!E16,"n.a.") -> 14577 | F10: =IF(AND(ISNUMBER('3_BS'!F16)),'3_BS'!F16,"n.a.") -> 16897 | G10: =IF(AND(ISNUMBER('3_BS'!G16)),'3_BS'!G16,"n.a.") -> 16903 | H10: =IF(AND(ISNUMBER('3_BS'!H16)),'3_BS'!H16,"n.a.") -> 16273 | I10: ='3_Forecast'!I60 -> 19666.871 | J10: ='3_Forecast'!J60 -> 23845.647 | K10: ='3_Forecast'!K60 -> 27691.239
C11: 営業活動によるCF | D11: =IF(AND(ISNUMBER('3_CF'!D6)),'3_CF'!D6,"n.a.") -> 8756 | E11: =IF(AND(ISNUMBER('3_CF'!E6)),'3_CF'!E6,"n.a.") -> 8720 | F11: =IF(AND(ISNUMBER('3_CF'!F6)),'3_CF'!F6,"n.a.") -> 6420 | G11: =IF(AND(ISNUMBER('3_CF'!G6)),'3_CF'!G6,"n.a.") -> 6318 | H11: =IF(AND(ISNUMBER('3_CF'!H6)),'3_CF'!H6,"n.a.") -> 7153 | I11: ='3_Forecast'!I37 -> 10102.427 | J11: ='3_Forecast'!J37 -> 10970.419 | K11: ='3_Forecast'!K37 -> 10488.636
C12: 投資活動によるCF | D12: =IF(AND(ISNUMBER('3_CF'!D10)),'3_CF'!D10,"n.a.") -> -4095 | E12: =IF(AND(ISNUMBER('3_CF'!E10)),'3_CF'!E10,"n.a.") -> -3583 | F12: =IF(AND(ISNUMBER('3_CF'!F10)),'3_CF'!F10,"n.a.") -> -4362 | G12: =IF(AND(ISNUMBER('3_CF'!G10)),'3_CF'!G10,"n.a.") -> -3202 | H12: =IF(AND(ISNUMBER('3_CF'!H10)),'3_CF'!H10,"n.a.") -> -1439 | I12: ='3_Forecast'!I38 -> -2798.3958 | J12: ='3_Forecast'!J38 -> -2395.4268 | K12: ='3_Forecast'!K38 -> -2242.1194
C13: 財務活動によるCF | D13: =IF(AND(ISNUMBER('3_CF'!D12)),'3_CF'!D12,"n.a.") -> -3137 | E13: =IF(AND(ISNUMBER('3_CF'!E12)),'3_CF'!E12,"n.a.") -> -6718 | F13: =IF(AND(ISNUMBER('3_CF'!F12)),'3_CF'!F12,"n.a.") -> -2144 | G13: =IF(AND(ISNUMBER('3_CF'!G12)),'3_CF'!G12,"n.a.") -> -2880 | H13: =IF(AND(ISNUMBER('3_CF'!H12)),'3_CF'!H12,"n.a.") -> -5689 | I13: ='3_Forecast'!I45 -> -4999 | J13: ='3_Forecast'!J45 -> -4999 | K13: ='3_Forecast'!K45 -> -4999
C14: 現金同等物の期末残高（CF定義） | D14: =IF(AND(ISNUMBER('3_CF'!D16)),'3_CF'!D16,"n.a.") -> 4631 | E14: =IF(AND(ISNUMBER('3_CF'!E16)),'3_CF'!E16,"n.a.") -> 3050 | F14: =IF(AND(ISNUMBER('3_CF'!F16)),'3_CF'!F16,"n.a.") -> 2964 | G14: =IF(AND(ISNUMBER('3_CF'!G16)),'3_CF'!G16,"n.a.") -> 3200 | H14: =IF(AND(ISNUMBER('3_CF'!H16)),'3_CF'!H16,"n.a.") -> 3225 | I14: ='3_Forecast'!I48 -> 5530.0311 | J14: ='3_Forecast'!J48 -> 9106.0235 | K14: ='3_Forecast'!K48 -> 12353.54
C17: 営業利益率 | D17: =IF(AND(ISNUMBER('3_PL'!D12),ISNUMBER('3_PL'!D6),'3_PL'!D6<>0),'3_PL'!D12/'3_PL'!D6,"n.a.") -> 0.48844309 | E17: =IF(AND(ISNUMBER('3_PL'!E12),ISNUMBER('3_PL'!E6),'3_PL'!E6<>0),'3_PL'!E12/'3_PL'!E6,"n.a.") -> 0.50629119 | F17: =IF(AND(ISNUMBER('3_PL'!F12),ISNUMBER('3_PL'!F6),'3_PL'!F6<>0),'3_PL'!F12/'3_PL'!F6,"n.a.") -> 0.41845996 | G17: =IF(AND(ISNUMBER('3_PL'!G12),ISNUMBER('3_PL'!G6),'3_PL'!G6<>0),'3_PL'!G12/'3_PL'!G6,"n.a.") -> 0.34940221 | H17: =IF(AND(ISNUMBER('3_PL'!H12),ISNUMBER('3_PL'!H6),'3_PL'!H6<>0),'3_PL'!H12/'3_PL'!H6,"n.a.") -> 0.34062889 | I17: =IF(AND(ISNUMBER('3_Forecast'!I14),ISNUMBER('3_Forecast'!I8),'3_Forecast'!I8<>0),'3_Forecast'!I14/'3_Forecast'!I8,"n.a.") -> 0.44 | J17: =IF(AND(ISNUMBER('3_Forecast'!J14),ISNUMBER('3_Forecast'!J8),'3_Forecast'!J8<>0),'3_Forecast'!J14/'3_Forecast'!J8,"n.a.") -> 0.456 | K17: =IF(AND(ISNUMBER('3_Forecast'!K14),ISNUMBER('3_Forecast'!K8),'3_Forecast'!K8<>0),'3_Forecast'!K14/'3_Forecast'!K8,"n.a.") -> 0.423
C18: 純利益率 | D18: =IF(AND(ISNUMBER('3_PL'!D17),ISNUMBER('3_PL'!D6),'3_PL'!D6<>0),'3_PL'!D17/'3_PL'!D6,"n.a.") -> 0.42351723 | E18: =IF(AND(ISNUMBER('3_PL'!E17),ISNUMBER('3_PL'!E6),'3_PL'!E6<>0),'3_PL'!E17/'3_PL'!E6,"n.a.") -> 0.43683843 | F18: =IF(AND(ISNUMBER('3_PL'!F17),ISNUMBER('3_PL'!F6),'3_PL'!F6<>0),'3_PL'!F17/'3_PL'!F6,"n.a.") -> 0.37159655 | G18: =IF(AND(ISNUMBER('3_PL'!G17),ISNUMBER('3_PL'!G6),'3_PL'!G6<>0),'3_PL'!G17/'3_PL'!G6,"n.a.") -> 0.30682181 | H18: =IF(AND(ISNUMBER('3_PL'!H17),ISNUMBER('3_PL'!H6),'3_PL'!H6<>0),'3_PL'!H17/'3_PL'!H6,"n.a.") -> 0.28283 | I18: =IF(AND(ISNUMBER('3_Forecast'!I21),ISNUMBER('3_Forecast'!I8),'3_Forecast'!I8<>0),'3_Forecast'!I21/'3_Forecast'!I8,"n.a.") -> 0.37489652 | J18: =IF(AND(ISNUMBER('3_Forecast'!J21),ISNUMBER('3_Forecast'!J8),'3_Forecast'!J8<>0),'3_Forecast'!J21/'3_Forecast'!J8,"n.a.") -> 0.38313742 | K18: =IF(AND(ISNUMBER('3_Forecast'!K21),ISNUMBER('3_Forecast'!K8),'3_Forecast'!K8<>0),'3_Forecast'!K21/'3_Forecast'!K8,"n.a.") -> 0.35502714
C19: 営業CF / 売上高 | D19: =IF(AND(ISNUMBER('3_CF'!D6),ISNUMBER('3_PL'!D6),'3_PL'!D6<>0),'3_CF'!D6/'3_PL'!D6,"n.a.") -> 0.47732229 | E19: =IF(AND(ISNUMBER('3_CF'!E6),ISNUMBER('3_PL'!E6),'3_PL'!E6<>0),'3_CF'!E6/'3_PL'!E6,"n.a.") -> 0.43539045 | F19: =IF(AND(ISNUMBER('3_CF'!F6),ISNUMBER('3_PL'!F6),'3_PL'!F6<>0),'3_CF'!F6/'3_PL'!F6,"n.a.") -> 0.36645927 | G19: =IF(AND(ISNUMBER('3_CF'!G6),ISNUMBER('3_PL'!G6),'3_PL'!G6<>0),'3_CF'!G6/'3_PL'!G6,"n.a.") -> 0.40393837 | H19: =IF(AND(ISNUMBER('3_CF'!H6),ISNUMBER('3_PL'!H6),'3_PL'!H6<>0),'3_CF'!H6/'3_PL'!H6,"n.a.") -> 0.40453569 | I19: =IF(AND(ISNUMBER('3_Forecast'!I37),ISNUMBER('3_Forecast'!I8),'3_Forecast'!I8<>0),'3_Forecast'!I37/'3_Forecast'!I8,"n.a.") -> 0.45125975 | J19: =IF(AND(ISNUMBER('3_Forecast'!J37),ISNUMBER('3_Forecast'!J8),'3_Forecast'!J8<>0),'3_Forecast'!J37/'3_Forecast'!J8,"n.a.") -> 0.45797347 | K19: =IF(AND(ISNUMBER('3_Forecast'!K37),ISNUMBER('3_Forecast'!K8),'3_Forecast'!K8<>0),'3_Forecast'!K37/'3_Forecast'!K8,"n.a.") -> 0.42102004
C20: 売上高成長率 | D20: n.a. | E20: =IF(AND(ISNUMBER('3_PL'!E6),ISNUMBER('3_PL'!D6),'3_PL'!D6<>0),'3_PL'!E6/'3_PL'!D6-1,"n.a.") -> 0.091801134 | F20: =IF(AND(ISNUMBER('3_PL'!F6),ISNUMBER('3_PL'!E6),'3_PL'!E6<>0),'3_PL'!F6/'3_PL'!E6-1,"n.a.") -> -0.12527462 | G20: =IF(AND(ISNUMBER('3_PL'!G6),ISNUMBER('3_PL'!F6),'3_PL'!F6<>0),'3_PL'!G6/'3_PL'!F6-1,"n.a.") -> -0.1071979 | H20: =IF(AND(ISNUMBER('3_PL'!H6),ISNUMBER('3_PL'!G6),'3_PL'!G6<>0),'3_PL'!H6/'3_PL'!G6-1,"n.a.") -> 0.13049038 | I20: =IF(AND(ISNUMBER('3_Forecast'!I8),ISNUMBER('3_Forecast'!H8),'3_Forecast'!H8<>0),'3_Forecast'!I8/'3_Forecast'!H8-1,"n.a.") -> 0.2660992 | J20: =IF(AND(ISNUMBER('3_Forecast'!J8),ISNUMBER('3_Forecast'!I8),'3_Forecast'!I8<>0),'3_Forecast'!J8/'3_Forecast'!I8-1,"n.a.") -> 0.07 | K20: =IF(AND(ISNUMBER('3_Forecast'!K8),ISNUMBER('3_Forecast'!J8),'3_Forecast'!J8<>0),'3_Forecast'!K8/'3_Forecast'!J8-1,"n.a.") -> 0.04
C23: 対象と読み方
C24: TXN: 取得関連無形資産の残高はFY2021〜FY2025の10-K貸借対照表に独立表示なし、取得関連無形資産償却はFY2024・FY2025の10-K CF計算書に表示なし（該当行はn.a.のまま）。無形資産・D&Aは司令塔判断（案A）により資産計上ソフトウェアの表示値で代替。代替宣言：理想＝0054定義の無形資産・純粋D&A／10-K FY2021-25のBSに取得関連無形資産の行が無いことを確認済み／代替＝資産計上ソフトウェア（Capitalized software licenses）の表示値とその償却／バイアス＝無形資産の過小は軽微、償却率は有形中心の値になる
C25: 異なる年度のセグメント再編・会計基準変更は自動で組み替えない。比較値は出典の定義を確認。
C26: 年次連結実績。将来予測は別のモデル仮定で設定。会社予想と区別する。
C27: 財務整理用。投資助言ではありません。
C28: 予測3年は機械的初期仮定によるモデル予測E。会社予想ではありません。
C29: 未抽出の三表セル: 2。すべての空欄を未開示と解釈しない。
C30: 青字：原数値。緑字：他シート参照。黒字：計算・Summary。A：実績。
C31: BSの現預金とCFの現金同等物は範囲が異なる場合があります。差額をゼロに強制しません。

Sheet 3_PL
C2: TEXAS INSTRUMENTS INC PL
C4: USD 百万単位。年次・連結実績。n.a. = 未抽出／対象外
C5: 項目 | D5: 2021-12-31 A | E5: 2022-12-31 A | F5: 2023-12-31 A | G5: 2024-12-31 A | H5: 2025-12-31 A | I5: 2026-12-31 E | J5: 2027-12-31 E | K5: 2028-12-31 E
C6: 売上高 | D6: =IF(AND(ISNUMBER(データ_財務!F6)),データ_財務!F6/1000000,"n.a.") -> 18344 | E6: =IF(AND(ISNUMBER(データ_財務!F7)),データ_財務!F7/1000000,"n.a.") -> 20028 | F6: =IF(AND(ISNUMBER(データ_財務!F8)),データ_財務!F8/1000000,"n.a.") -> 17519 | G6: =IF(AND(ISNUMBER(データ_財務!F9)),データ_財務!F9/1000000,"n.a.") -> 15641 | H6: =IF(AND(ISNUMBER(データ_財務!F10)),データ_財務!F10/1000000,"n.a.") -> 17682 | I6: ='3_Forecast'!I8 -> 22387.166 | J6: ='3_Forecast'!J8 -> 23954.268 | K6: ='3_Forecast'!K8 -> 24912.438
C7: 売上原価 | D7: =IF(AND(ISNUMBER(データ_財務!F11)),データ_財務!F11/1000000,"n.a.") -> 5968 | E7: =IF(AND(ISNUMBER(データ_財務!F12)),データ_財務!F12/1000000,"n.a.") -> 6257 | F7: =IF(AND(ISNUMBER(データ_財務!F13)),データ_財務!F13/1000000,"n.a.") -> 6500 | G7: =IF(AND(ISNUMBER(データ_財務!F14)),データ_財務!F14/1000000,"n.a.") -> 6547 | H7: =IF(AND(ISNUMBER(データ_財務!F15)),データ_財務!F15/1000000,"n.a.") -> 7599 | I7: ='3_Forecast'!I9 -> 8507.1231 | J7: ='3_Forecast'!J9 -> 8863.079 | K7: ='3_Forecast'!K9 -> 9840.4131
C8: 売上総利益 | D8: =IF(AND(ISNUMBER(データ_財務!F16)),データ_財務!F16/1000000,"n.a.") -> 12376 | E8: =IF(AND(ISNUMBER(データ_財務!F17)),データ_財務!F17/1000000,"n.a.") -> 13771 | F8: =IF(AND(ISNUMBER(データ_財務!F18)),データ_財務!F18/1000000,"n.a.") -> 11019 | G8: =IF(AND(ISNUMBER(データ_財務!F19)),データ_財務!F19/1000000,"n.a.") -> 9094 | H8: =IF(AND(ISNUMBER(データ_財務!F20)),データ_財務!F20/1000000,"n.a.") -> 10083 | I8: ='3_Forecast'!I10 -> 13880.043 | J8: ='3_Forecast'!J10 -> 15091.189 | K8: ='3_Forecast'!K10 -> 15072.025
C9: 販売費及び一般管理費 | D9: =IF(AND(ISNUMBER(データ_財務!F21)),データ_財務!F21/1000000,"n.a.") -> 1666 | E9: =IF(AND(ISNUMBER(データ_財務!F22)),データ_財務!F22/1000000,"n.a.") -> 1704 | F9: =IF(AND(ISNUMBER(データ_財務!F23)),データ_財務!F23/1000000,"n.a.") -> 1825 | G9: =IF(AND(ISNUMBER(データ_財務!F24)),データ_財務!F24/1000000,"n.a.") -> 1794 | H9: =IF(AND(ISNUMBER(データ_財務!F25)),データ_財務!F25/1000000,"n.a.") -> 1860 | I9: ='3_Forecast'!I11 -> 1880.5219 | J9: ='3_Forecast'!J11 -> 1964.2499 | K9: ='3_Forecast'!K11 -> 2142.4697
C10: 研究開発費（内数の場合あり） | D10: =IF(AND(ISNUMBER(データ_財務!F26)),データ_財務!F26/1000000,"n.a.") -> 1554 | E10: =IF(AND(ISNUMBER(データ_財務!F27)),データ_財務!F27/1000000,"n.a.") -> 1670 | F10: =IF(AND(ISNUMBER(データ_財務!F28)),データ_財務!F28/1000000,"n.a.") -> 1863 | G10: =IF(AND(ISNUMBER(データ_財務!F29)),データ_財務!F29/1000000,"n.a.") -> 1959 | H10: =IF(AND(ISNUMBER(データ_財務!F30)),データ_財務!F30/1000000,"n.a.") -> 2083 | I10: ='3_Forecast'!I12 -> 2149.1679 | J10: ='3_Forecast'!J12 -> 2203.7926 | K10: ='3_Forecast'!K12 -> 2391.5941
C11: その他営業費用・損益調整（計算値） | D11: =IF(AND(ISNUMBER(D8),ISNUMBER(D9),ISNUMBER(D12),ISNUMBER(D10)),D8-D9-D12-D10,"n.a.") -> 196 | E11: =IF(AND(ISNUMBER(E8),ISNUMBER(E9),ISNUMBER(E12),ISNUMBER(E10)),E8-E9-E12-E10,"n.a.") -> 257 | F11: =IF(AND(ISNUMBER(F8),ISNUMBER(F9),ISNUMBER(F12),ISNUMBER(F10)),F8-F9-F12-F10,"n.a.") -> 0 | G11: =IF(AND(ISNUMBER(G8),ISNUMBER(G9),ISNUMBER(G12),ISNUMBER(G10)),G8-G9-G12-G10,"n.a.") -> -124 | H11: =IF(AND(ISNUMBER(H8),ISNUMBER(H9),ISNUMBER(H12),ISNUMBER(H10)),H8-H9-H12-H10,"n.a.") -> 117 | I11: ='3_Forecast'!I13 -> 0 | J11: ='3_Forecast'!J13 -> 0 | K11: ='3_Forecast'!K13 -> 0
C12: 営業利益 | D12: =IF(AND(ISNUMBER(データ_財務!F31)),データ_財務!F31/1000000,"n.a.") -> 8960 | E12: =IF(AND(ISNUMBER(データ_財務!F32)),データ_財務!F32/1000000,"n.a.") -> 10140 | F12: =IF(AND(ISNUMBER(データ_財務!F33)),データ_財務!F33/1000000,"n.a.") -> 7331 | G12: =IF(AND(ISNUMBER(データ_財務!F34)),データ_財務!F34/1000000,"n.a.") -> 5465 | H12: =IF(AND(ISNUMBER(データ_財務!F35)),データ_財務!F35/1000000,"n.a.") -> 6023 | I12: ='3_Forecast'!I14 -> 9850.353 | J12: ='3_Forecast'!J14 -> 10923.146 | K12: ='3_Forecast'!K14 -> 10537.961
C13: 税引前利益 | D13: =IF(AND(ISNUMBER(データ_財務!F36)),データ_財務!F36/1000000,"n.a.") -> 8919 | E13: =IF(AND(ISNUMBER(データ_財務!F37)),データ_財務!F37/1000000,"n.a.") -> 10032 | F13: =IF(AND(ISNUMBER(データ_財務!F38)),データ_財務!F38/1000000,"n.a.") -> 7418 | G13: =IF(AND(ISNUMBER(データ_財務!F39)),データ_財務!F39/1000000,"n.a.") -> 5453 | H13: =IF(AND(ISNUMBER(データ_財務!F40)),データ_財務!F40/1000000,"n.a.") -> 5710 | I13: ='3_Forecast'!I17 -> 9537.353 | J13: ='3_Forecast'!J17 -> 10610.146 | K13: ='3_Forecast'!K17 -> 10224.961
C14: 法人所得税 | D14: =IF(AND(ISNUMBER(データ_財務!F41)),データ_財務!F41/1000000,"n.a.") -> 1150 | E14: =IF(AND(ISNUMBER(データ_財務!F42)),データ_財務!F42/1000000,"n.a.") -> 1283 | F14: =IF(AND(ISNUMBER(データ_財務!F43)),データ_財務!F43/1000000,"n.a.") -> 908 | G14: =IF(AND(ISNUMBER(データ_財務!F44)),データ_財務!F44/1000000,"n.a.") -> 654 | H14: =IF(AND(ISNUMBER(データ_財務!F45)),データ_財務!F45/1000000,"n.a.") -> 709 | I14: ='3_Forecast'!I18 -> 1144.4824 | J14: ='3_Forecast'!J18 -> 1432.3697 | K14: ='3_Forecast'!K18 -> 1380.3698
C15: 当期利益（非支配持分含む） | D15: =IF(AND(ISNUMBER(データ_財務!F151)),データ_財務!F151/1000000,"n.a.") -> 7769 | E15: =IF(AND(ISNUMBER(データ_財務!F152)),データ_財務!F152/1000000,"n.a.") -> 8749 | F15: =IF(AND(ISNUMBER(データ_財務!F153)),データ_財務!F153/1000000,"n.a.") -> 6510 | G15: =IF(AND(ISNUMBER(データ_財務!F154)),データ_財務!F154/1000000,"n.a.") -> 4799 | H15: =IF(AND(ISNUMBER(データ_財務!F155)),データ_財務!F155/1000000,"n.a.") -> 5001 | I15: ='3_Forecast'!I19 -> 8392.8707 | J15: ='3_Forecast'!J19 -> 9177.7763 | K15: ='3_Forecast'!K19 -> 8844.5916
C16: 非支配持分帰属利益 | D16: =IF(AND(ISNUMBER(データ_財務!F141)),データ_財務!F141/1000000,"n.a.") -> 0 | E16: =IF(AND(ISNUMBER(データ_財務!F142)),データ_財務!F142/1000000,"n.a.") -> 0 | F16: =IF(AND(ISNUMBER(データ_財務!F143)),データ_財務!F143/1000000,"n.a.") -> 0 | G16: =IF(AND(ISNUMBER(データ_財務!F144)),データ_財務!F144/1000000,"n.a.") -> 0 | H16: =IF(AND(ISNUMBER(データ_財務!F145)),データ_財務!F145/1000000,"n.a.") -> 0 | I16: ='3_Forecast'!I20 -> 0 | J16: ='3_Forecast'!J20 -> 0 | K16: ='3_Forecast'!K20 -> 0
C17: 親会社株主帰属利益 | D17: =IF(AND(ISNUMBER(データ_財務!F46)),データ_財務!F46/1000000,"n.a.") -> 7769 | E17: =IF(AND(ISNUMBER(データ_財務!F47)),データ_財務!F47/1000000,"n.a.") -> 8749 | F17: =IF(AND(ISNUMBER(データ_財務!F48)),データ_財務!F48/1000000,"n.a.") -> 6510 | G17: =IF(AND(ISNUMBER(データ_財務!F49)),データ_財務!F49/1000000,"n.a.") -> 4799 | H17: =IF(AND(ISNUMBER(データ_財務!F50)),データ_財務!F50/1000000,"n.a.") -> 5001 | I17: ='3_Forecast'!I21 -> 8392.8707 | J17: ='3_Forecast'!J21 -> 9177.7763 | K17: ='3_Forecast'!K21 -> 8844.5916

Sheet 3_BS
C2: TEXAS INSTRUMENTS INC BS
C4: USD 百万単位。年次・連結実績。n.a. = 未抽出／対象外
C5: 項目 | D5: 2021-12-31 A | E5: 2022-12-31 A | F5: 2023-12-31 A | G5: 2024-12-31 A | H5: 2025-12-31 A | I5: 2026-12-31 E | J5: 2027-12-31 E | K5: 2028-12-31 E
C6: 現金及び預金・現金同等物（BS定義） | D6: =IF(AND(ISNUMBER(データ_財務!F51)),データ_財務!F51/1000000,"n.a.") -> 4631 | E6: =IF(AND(ISNUMBER(データ_財務!F52)),データ_財務!F52/1000000,"n.a.") -> 3050 | F6: =IF(AND(ISNUMBER(データ_財務!F53)),データ_財務!F53/1000000,"n.a.") -> 2964 | G6: =IF(AND(ISNUMBER(データ_財務!F54)),データ_財務!F54/1000000,"n.a.") -> 3200 | H6: =IF(AND(ISNUMBER(データ_財務!F55)),データ_財務!F55/1000000,"n.a.") -> 3225 | I6: ='3_Forecast'!I52 -> 5530.0311 | J6: ='3_Forecast'!J52 -> 9106.0235 | K6: ='3_Forecast'!K52 -> 12353.54
C7: 売上債権 | D7: =IF(AND(ISNUMBER(データ_財務!F56)),データ_財務!F56/1000000,"n.a.") -> 1701 | E7: =IF(AND(ISNUMBER(データ_財務!F57)),データ_財務!F57/1000000,"n.a.") -> 1895 | F7: =IF(AND(ISNUMBER(データ_財務!F58)),データ_財務!F58/1000000,"n.a.") -> 1787 | G7: =IF(AND(ISNUMBER(データ_財務!F59)),データ_財務!F59/1000000,"n.a.") -> 1719 | H7: =IF(AND(ISNUMBER(データ_財務!F60)),データ_財務!F60/1000000,"n.a.") -> 1963 | I7: ='3_Forecast'!I24 -> 2485.3527 | J7: ='3_Forecast'!J24 -> 2659.3274 | K7: ='3_Forecast'!K24 -> 2758.144
C8: 棚卸資産 | D8: =IF(AND(ISNUMBER(データ_財務!F61)),データ_財務!F61/1000000,"n.a.") -> 1910 | E8: =IF(AND(ISNUMBER(データ_財務!F62)),データ_財務!F62/1000000,"n.a.") -> 2757 | F8: =IF(AND(ISNUMBER(データ_財務!F63)),データ_財務!F63/1000000,"n.a.") -> 3999 | G8: =IF(AND(ISNUMBER(データ_財務!F64)),データ_財務!F64/1000000,"n.a.") -> 4527 | H8: =IF(AND(ISNUMBER(データ_財務!F65)),データ_財務!F65/1000000,"n.a.") -> 4804 | I8: ='3_Forecast'!I25 -> 4661.4373 | J8: ='3_Forecast'!J25 -> 4856.4817 | K8: ='3_Forecast'!K25 -> 5377.2749
C9: 流動資産 | D9: =IF(AND(ISNUMBER(データ_財務!F66)),データ_財務!F66/1000000,"n.a.") -> 13685 | E9: =IF(AND(ISNUMBER(データ_財務!F67)),データ_財務!F67/1000000,"n.a.") -> 14021 | F9: =IF(AND(ISNUMBER(データ_財務!F68)),データ_財務!F68/1000000,"n.a.") -> 15122 | G9: =IF(AND(ISNUMBER(データ_財務!F69)),データ_財務!F69/1000000,"n.a.") -> 15026 | H9: =IF(AND(ISNUMBER(データ_財務!F70)),データ_財務!F70/1000000,"n.a.") -> 13750 | I9: ='3_Forecast'!I54 -> 16434.821 | J9: ='3_Forecast'!J54 -> 20379.833 | K9: ='3_Forecast'!K54 -> 24246.959
C10: 有形固定資産 | D10: =IF(AND(ISNUMBER(データ_財務!F71)),データ_財務!F71/1000000,"n.a.") -> 5141 | E10: =IF(AND(ISNUMBER(データ_財務!F72)),データ_財務!F72/1000000,"n.a.") -> 6876 | F10: =IF(AND(ISNUMBER(データ_財務!F73)),データ_財務!F73/1000000,"n.a.") -> 9999 | G10: =IF(AND(ISNUMBER(データ_財務!F74)),データ_財務!F74/1000000,"n.a.") -> 11347 | H10: =IF(AND(ISNUMBER(データ_財務!F75)),データ_財務!F75/1000000,"n.a.") -> 12320 | I10: ='3_Forecast'!I33 -> 13104.246 | J10: ='3_Forecast'!J33 -> 13368.322 | K10: ='3_Forecast'!K33 -> 13439.96
C11: 無形資産（のれんを除く場合あり） | D11: =IF(AND(ISNUMBER(データ_財務!F146)),データ_財務!F146/1000000,"n.a.") -> 85 | E11: =IF(AND(ISNUMBER(データ_財務!F147)),データ_財務!F147/1000000,"n.a.") -> 152 | F11: =IF(AND(ISNUMBER(データ_財務!F148)),データ_財務!F148/1000000,"n.a.") -> 223 | G11: =IF(AND(ISNUMBER(データ_財務!F149)),データ_財務!F149/1000000,"n.a.") -> 257 | H11: =IF(AND(ISNUMBER(データ_財務!F150)),データ_財務!F150/1000000,"n.a.") -> 238 | I11: ='3_Forecast'!I34 -> 253.1502 | J11: ='3_Forecast'!J34 -> 258.25167 | K11: ='3_Forecast'!K34 -> 259.6356
C12: 総資産 | D12: =IF(AND(ISNUMBER(データ_財務!F76)),データ_財務!F76/1000000,"n.a.") -> 24676 | E12: =IF(AND(ISNUMBER(データ_財務!F77)),データ_財務!F77/1000000,"n.a.") -> 27207 | F12: =IF(AND(ISNUMBER(データ_財務!F78)),データ_財務!F78/1000000,"n.a.") -> 32348 | G12: =IF(AND(ISNUMBER(データ_財務!F79)),データ_財務!F79/1000000,"n.a.") -> 35509 | H12: =IF(AND(ISNUMBER(データ_財務!F80)),データ_財務!F80/1000000,"n.a.") -> 34585 | I12: ='3_Forecast'!I56 -> 38069.217 | J12: ='3_Forecast'!J56 -> 42283.406 | K12: ='3_Forecast'!K56 -> 46223.555
C13: 仕入債務 | D13: =IF(AND(ISNUMBER(データ_財務!F81)),データ_財務!F81/1000000,"n.a.") -> 571 | E13: =IF(AND(ISNUMBER(データ_財務!F82)),データ_財務!F82/1000000,"n.a.") -> 851 | F13: =IF(AND(ISNUMBER(データ_財務!F83)),データ_財務!F83/1000000,"n.a.") -> 802 | G13: =IF(AND(ISNUMBER(データ_財務!F84)),データ_財務!F84/1000000,"n.a.") -> 820 | H13: =IF(AND(ISNUMBER(データ_財務!F85)),データ_財務!F85/1000000,"n.a.") -> 756 | I13: ='3_Forecast'!I26 -> 846.34624 | J13: ='3_Forecast'!J26 -> 881.75914 | K13: ='3_Forecast'!K26 -> 976.31612
C14: 流動負債 | D14: =IF(AND(ISNUMBER(データ_財務!F86)),データ_財務!F86/1000000,"n.a.") -> 2569 | E14: =IF(AND(ISNUMBER(データ_財務!F87)),データ_財務!F87/1000000,"n.a.") -> 2985 | F14: =IF(AND(ISNUMBER(データ_財務!F88)),データ_財務!F88/1000000,"n.a.") -> 3320 | G14: =IF(AND(ISNUMBER(データ_財務!F89)),データ_財務!F89/1000000,"n.a.") -> 3643 | H14: =IF(AND(ISNUMBER(データ_財務!F90)),データ_財務!F90/1000000,"n.a.") -> 3159 | I14: ='3_Forecast'!I58 -> 3249.3462 | J14: ='3_Forecast'!J58 -> 3284.7591 | K14: ='3_Forecast'!K58 -> 3379.3161
C15: 負債合計 | D15: =IF(AND(ISNUMBER(データ_財務!F91)),データ_財務!F91/1000000,"n.a.") -> 11343 | E15: =IF(AND(ISNUMBER(データ_財務!F92)),データ_財務!F92/1000000,"n.a.") -> 12630 | F15: =IF(AND(ISNUMBER(データ_財務!F93)),データ_財務!F93/1000000,"n.a.") -> 15451 | G15: =IF(AND(ISNUMBER(データ_財務!F94)),データ_財務!F94/1000000,"n.a.") -> 18606 | H15: =IF(AND(ISNUMBER(データ_財務!F95)),データ_財務!F95/1000000,"n.a.") -> 18312 | I15: ='3_Forecast'!I59 -> 18402.346 | J15: ='3_Forecast'!J59 -> 18437.759 | K15: ='3_Forecast'!K59 -> 18532.316
C16: 資本合計（非支配持分含む） | D16: =IF(AND(ISNUMBER(データ_財務!F96)),データ_財務!F96/1000000,"n.a.") -> 13333 | E16: =IF(AND(ISNUMBER(データ_財務!F97)),データ_財務!F97/1000000,"n.a.") -> 14577 | F16: =IF(AND(ISNUMBER(データ_財務!F98)),データ_財務!F98/1000000,"n.a.") -> 16897 | G16: =IF(AND(ISNUMBER(データ_財務!F99)),データ_財務!F99/1000000,"n.a.") -> 16903 | H16: =IF(AND(ISNUMBER(データ_財務!F100)),データ_財務!F100/1000000,"n.a.") -> 16273 | I16: ='3_Forecast'!I60 -> 19666.871 | J16: ='3_Forecast'!J60 -> 23845.647 | K16: ='3_Forecast'!K60 -> 27691.239

Sheet 3_CF
C2: TEXAS INSTRUMENTS INC CF
C4: USD 百万単位。年次・連結実績。n.a. = 未抽出／対象外
C5: 項目 | D5: 2021-12-31 A | E5: 2022-12-31 A | F5: 2023-12-31 A | G5: 2024-12-31 A | H5: 2025-12-31 A | I5: 2026-12-31 E | J5: 2027-12-31 E | K5: 2028-12-31 E
C6: 営業活動によるCF | D6: =IF(AND(ISNUMBER(データ_財務!F101)),データ_財務!F101/1000000,"n.a.") -> 8756 | E6: =IF(AND(ISNUMBER(データ_財務!F102)),データ_財務!F102/1000000,"n.a.") -> 8720 | F6: =IF(AND(ISNUMBER(データ_財務!F103)),データ_財務!F103/1000000,"n.a.") -> 6420 | G6: =IF(AND(ISNUMBER(データ_財務!F104)),データ_財務!F104/1000000,"n.a.") -> 6318 | H6: =IF(AND(ISNUMBER(データ_財務!F105)),データ_財務!F105/1000000,"n.a.") -> 7153 | I6: ='3_Forecast'!I37 -> 10102.427 | J6: ='3_Forecast'!J37 -> 10970.419 | K6: ='3_Forecast'!K37 -> 10488.636
C7: 減価償却・償却費 | D7: =IF(AND(ISNUMBER(データ_財務!F131)),データ_財務!F131/1000000,"n.a.") -> 954 | E7: =IF(AND(ISNUMBER(データ_財務!F132)),データ_財務!F132/1000000,"n.a.") -> 979 | F7: =IF(AND(ISNUMBER(データ_財務!F133)),データ_財務!F133/1000000,"n.a.") -> 1238 | G7: =IF(AND(ISNUMBER(データ_財務!F134)),データ_財務!F134/1000000,"n.a.") -> 1580 | H7: =IF(AND(ISNUMBER(データ_財務!F135)),データ_財務!F135/1000000,"n.a.") -> 1999 | I7: ='3_Forecast'!I32 -> 1999 | J7: ='3_Forecast'!J32 -> 2126.2489 | K7: ='3_Forecast'!K32 -> 2169.097
C8: 減価償却費（有形資産） | D8: =IF(AND(ISNUMBER(データ_財務!F156)),データ_財務!F156/1000000,"n.a.") -> 755 | E8: =IF(AND(ISNUMBER(データ_財務!F157)),データ_財務!F157/1000000,"n.a.") -> 925 | F8: =IF(AND(ISNUMBER(データ_財務!F158)),データ_財務!F158/1000000,"n.a.") -> 1175 | G8: =IF(AND(ISNUMBER(データ_財務!F159)),データ_財務!F159/1000000,"n.a.") -> 1508 | H8: =IF(AND(ISNUMBER(データ_財務!F160)),データ_財務!F160/1000000,"n.a.") -> 1918 | I8: n.a. | J8: n.a. | K8: n.a.
C9: 無形資産償却費 | D9: =IF(AND(ISNUMBER(データ_財務!F161)),データ_財務!F161/1000000,"n.a.") -> 142 | E9: =IF(AND(ISNUMBER(データ_財務!F162)),データ_財務!F162/1000000,"n.a.") -> 0 | F9: =IF(AND(ISNUMBER(データ_財務!F163)),データ_財務!F163/1000000,"n.a.") -> 0 | G9: n.a. | H9: n.a. | I9: n.a. | J9: n.a. | K9: n.a.
C10: 投資活動によるCF | D10: =IF(AND(ISNUMBER(データ_財務!F106)),データ_財務!F106/1000000,"n.a.") -> -4095 | E10: =IF(AND(ISNUMBER(データ_財務!F107)),データ_財務!F107/1000000,"n.a.") -> -3583 | F10: =IF(AND(ISNUMBER(データ_財務!F108)),データ_財務!F108/1000000,"n.a.") -> -4362 | G10: =IF(AND(ISNUMBER(データ_財務!F109)),データ_財務!F109/1000000,"n.a.") -> -3202 | H10: =IF(AND(ISNUMBER(データ_財務!F110)),データ_財務!F110/1000000,"n.a.") -> -1439 | I10: ='3_Forecast'!I38 -> -2798.3958 | J10: ='3_Forecast'!J38 -> -2395.4268 | K10: ='3_Forecast'!K38 -> -2242.1194
C11: 設備投資支出（正額） | D11: =IF(AND(ISNUMBER(データ_財務!F136)),ABS(データ_財務!F136)/1000000,"n.a.") -> 2462 | E11: =IF(AND(ISNUMBER(データ_財務!F137)),ABS(データ_財務!F137)/1000000,"n.a.") -> 2797 | F11: =IF(AND(ISNUMBER(データ_財務!F138)),ABS(データ_財務!F138)/1000000,"n.a.") -> 5071 | G11: =IF(AND(ISNUMBER(データ_財務!F139)),ABS(データ_財務!F139)/1000000,"n.a.") -> 4820 | H11: =IF(AND(ISNUMBER(データ_財務!F140)),ABS(データ_財務!F140)/1000000,"n.a.") -> 4550 | I11: =IF(AND(ISNUMBER('3_Forecast'!I31),ISNUMBER('3_Assumptions'!D19),'3_Assumptions'!D19>=0,'3_Assumptions'!D19<=1),'3_Forecast'!I31*'3_Assumptions'!D19,"n.a.") -> 2745.3604 | J11: =IF(AND(ISNUMBER('3_Forecast'!J31),ISNUMBER('3_Assumptions'!E19),'3_Assumptions'!E19>=0,'3_Assumptions'!E19<=1),'3_Forecast'!J31*'3_Assumptions'!E19,"n.a.") -> 2350.0285 | K11: =IF(AND(ISNUMBER('3_Forecast'!K31),ISNUMBER('3_Assumptions'!F19),'3_Assumptions'!F19>=0,'3_Assumptions'!F19<=1),'3_Forecast'!K31*'3_Assumptions'!F19,"n.a.") -> 2199.6267
C12: 財務活動によるCF | D12: =IF(AND(ISNUMBER(データ_財務!F111)),データ_財務!F111/1000000,"n.a.") -> -3137 | E12: =IF(AND(ISNUMBER(データ_財務!F112)),データ_財務!F112/1000000,"n.a.") -> -6718 | F12: =IF(AND(ISNUMBER(データ_財務!F113)),データ_財務!F113/1000000,"n.a.") -> -2144 | G12: =IF(AND(ISNUMBER(データ_財務!F114)),データ_財務!F114/1000000,"n.a.") -> -2880 | H12: =IF(AND(ISNUMBER(データ_財務!F115)),データ_財務!F115/1000000,"n.a.") -> -5689 | I12: ='3_Forecast'!I45 -> -4999 | J12: ='3_Forecast'!J45 -> -4999 | K12: ='3_Forecast'!K45 -> -4999
C13: 親会社配当支払額（正額） | D13: =IF(AND(ISNUMBER(データ_財務!F164)),ABS(データ_財務!F164)/1000000,"n.a.") -> 3886 | E13: =IF(AND(ISNUMBER(データ_財務!F165)),ABS(データ_財務!F165)/1000000,"n.a.") -> 4297 | F13: =IF(AND(ISNUMBER(データ_財務!F166)),ABS(データ_財務!F166)/1000000,"n.a.") -> 4557 | G13: =IF(AND(ISNUMBER(データ_財務!F167)),ABS(データ_財務!F167)/1000000,"n.a.") -> 4795 | H13: =IF(AND(ISNUMBER(データ_財務!F168)),ABS(データ_財務!F168)/1000000,"n.a.") -> 4999 | I13: ='3_Forecast'!I39 -> 4999 | J13: ='3_Forecast'!J39 -> 4999 | K13: ='3_Forecast'!K39 -> 4999
C14: 現金同等物の為替換算差額 | D14: =IF(AND(ISNUMBER(データ_財務!F116)),データ_財務!F116/1000000,"n.a.") -> 0 | E14: =IF(AND(ISNUMBER(データ_財務!F117)),データ_財務!F117/1000000,"n.a.") -> 0 | F14: =IF(AND(ISNUMBER(データ_財務!F118)),データ_財務!F118/1000000,"n.a.") -> 0 | G14: =IF(AND(ISNUMBER(データ_財務!F119)),データ_財務!F119/1000000,"n.a.") -> 0 | H14: =IF(AND(ISNUMBER(データ_財務!F120)),データ_財務!F120/1000000,"n.a.") -> 0 | I14: ='3_Forecast'!I46 -> 0 | J14: ='3_Forecast'!J46 -> 0 | K14: ='3_Forecast'!K46 -> 0
C15: 現金同等物の増減（会社発表） | D15: =IF(AND(ISNUMBER(データ_財務!F121)),データ_財務!F121/1000000,"n.a.") -> 1524 | E15: =IF(AND(ISNUMBER(データ_財務!F122)),データ_財務!F122/1000000,"n.a.") -> -1581 | F15: =IF(AND(ISNUMBER(データ_財務!F123)),データ_財務!F123/1000000,"n.a.") -> -86 | G15: =IF(AND(ISNUMBER(データ_財務!F124)),データ_財務!F124/1000000,"n.a.") -> 236 | H15: =IF(AND(ISNUMBER(データ_財務!F125)),データ_財務!F125/1000000,"n.a.") -> 25 | I15: ='3_Forecast'!I47 -> 2305.0311 | J15: ='3_Forecast'!J47 -> 3575.9924 | K15: ='3_Forecast'!K47 -> 3247.5164
C16: 現金同等物の期末残高（CF定義） | D16: =IF(AND(ISNUMBER(データ_財務!F126)),データ_財務!F126/1000000,"n.a.") -> 4631 | E16: =IF(AND(ISNUMBER(データ_財務!F127)),データ_財務!F127/1000000,"n.a.") -> 3050 | F16: =IF(AND(ISNUMBER(データ_財務!F128)),データ_財務!F128/1000000,"n.a.") -> 2964 | G16: =IF(AND(ISNUMBER(データ_財務!F129)),データ_財務!F129/1000000,"n.a.") -> 3200 | H16: =IF(AND(ISNUMBER(データ_財務!F130)),データ_財務!F130/1000000,"n.a.") -> 3225 | I16: ='3_Forecast'!I48 -> 5530.0311 | J16: ='3_Forecast'!J48 -> 9106.0235 | K16: ='3_Forecast'!K48 -> 12353.54

Sheet 3_セグメント売上
C2: TEXAS INSTRUMENTS INC セグメント売上
C4: USD 百万単位。年次・連結実績。n.a. = 未抽出／対象外
C5: 項目 | D5: 2021-12-31 A | E5: 2022-12-31 A | F5: 2023-12-31 A | G5: 2024-12-31 A | H5: 2025-12-31 A | I5: 2026-12-31 E | J5: 2027-12-31 E | K5: 2028-12-31 E
C6: Analog | D6: =IF(AND(ISNUMBER(データ_財務!F213)),データ_財務!F213/1000000,"n.a.") -> 14050 | E6: =IF(AND(ISNUMBER(データ_財務!F202)),データ_財務!F202/1000000,"n.a.") -> 15359 | F6: =IF(AND(ISNUMBER(データ_財務!F175)),データ_財務!F175/1000000,"n.a.") -> 13040 | G6: =IF(AND(ISNUMBER(データ_財務!F172)),データ_財務!F172/1000000,"n.a.") -> 12161 | H6: =IF(AND(ISNUMBER(データ_財務!F169)),データ_財務!F169/1000000,"n.a.") -> 14006 | I6: =IF(AND(ISNUMBER(H6),ISNUMBER('3_Assumptions'!D6),ISNUMBER('3_Assumptions'!D29),'3_Assumptions'!D6>=-1,1+'3_Assumptions'!D6+'3_Assumptions'!D29>=0),H6*(1+'3_Assumptions'!D6+'3_Assumptions'!D29),"n.a.") -> 18291.836 | J6: =IF(AND(ISNUMBER(I6),ISNUMBER('3_Assumptions'!E6),ISNUMBER('3_Assumptions'!E29),'3_Assumptions'!E6>=-1,1+'3_Assumptions'!E6+'3_Assumptions'!E29>=0),I6*(1+'3_Assumptions'!E6+'3_Assumptions'!E29),"n.a.") -> 19572.265 | K6: =IF(AND(ISNUMBER(J6),ISNUMBER('3_Assumptions'!F6),ISNUMBER('3_Assumptions'!F29),'3_Assumptions'!F6>=-1,1+'3_Assumptions'!F6+'3_Assumptions'!F29>=0),J6*(1+'3_Assumptions'!F6+'3_Assumptions'!F29),"n.a.") -> 20355.155
C7: Embedded Processing | D7: =IF(AND(ISNUMBER(データ_財務!F214)),データ_財務!F214/1000000,"n.a.") -> 3049 | E7: =IF(AND(ISNUMBER(データ_財務!F203)),データ_財務!F203/1000000,"n.a.") -> 3261 | F7: =IF(AND(ISNUMBER(データ_財務!F176)),データ_財務!F176/1000000,"n.a.") -> 3368 | G7: =IF(AND(ISNUMBER(データ_財務!F173)),データ_財務!F173/1000000,"n.a.") -> 2533 | H7: =IF(AND(ISNUMBER(データ_財務!F170)),データ_財務!F170/1000000,"n.a.") -> 2697 | I7: =IF(AND(ISNUMBER(H7),ISNUMBER('3_Assumptions'!D6),ISNUMBER('3_Assumptions'!D30),'3_Assumptions'!D6>=-1,1+'3_Assumptions'!D6+'3_Assumptions'!D30>=0),H7*(1+'3_Assumptions'!D6+'3_Assumptions'!D30),"n.a.") -> 3155.49 | J7: =IF(AND(ISNUMBER(I7),ISNUMBER('3_Assumptions'!E6),ISNUMBER('3_Assumptions'!E30),'3_Assumptions'!E6>=-1,1+'3_Assumptions'!E6+'3_Assumptions'!E30>=0),I7*(1+'3_Assumptions'!E6+'3_Assumptions'!E30),"n.a.") -> 3376.3743 | K7: =IF(AND(ISNUMBER(J7),ISNUMBER('3_Assumptions'!F6),ISNUMBER('3_Assumptions'!F30),'3_Assumptions'!F6>=-1,1+'3_Assumptions'!F6+'3_Assumptions'!F30>=0),J7*(1+'3_Assumptions'!F6+'3_Assumptions'!F30),"n.a.") -> 3511.4293
C8: Other | D8: =IF(AND(ISNUMBER(データ_財務!F215)),データ_財務!F215/1000000,"n.a.") -> 1245 | E8: =IF(AND(ISNUMBER(データ_財務!F204)),データ_財務!F204/1000000,"n.a.") -> 1408 | F8: =IF(AND(ISNUMBER(データ_財務!F177)),データ_財務!F177/1000000,"n.a.") -> 1111 | G8: =IF(AND(ISNUMBER(データ_財務!F174)),データ_財務!F174/1000000,"n.a.") -> 947 | H8: =IF(AND(ISNUMBER(データ_財務!F171)),データ_財務!F171/1000000,"n.a.") -> 979 | I8: =IF(AND(ISNUMBER(H8),ISNUMBER('3_Assumptions'!D6),ISNUMBER('3_Assumptions'!D31),'3_Assumptions'!D6>=-1,1+'3_Assumptions'!D6+'3_Assumptions'!D31>=0),H8*(1+'3_Assumptions'!D6+'3_Assumptions'!D31),"n.a.") -> 939.84 | J8: =IF(AND(ISNUMBER(I8),ISNUMBER('3_Assumptions'!E6),ISNUMBER('3_Assumptions'!E31),'3_Assumptions'!E6>=-1,1+'3_Assumptions'!E6+'3_Assumptions'!E31>=0),I8*(1+'3_Assumptions'!E6+'3_Assumptions'!E31),"n.a.") -> 1005.6288 | K8: =IF(AND(ISNUMBER(J8),ISNUMBER('3_Assumptions'!F6),ISNUMBER('3_Assumptions'!F31),'3_Assumptions'!F6>=-1,1+'3_Assumptions'!F6+'3_Assumptions'!F31>=0),J8*(1+'3_Assumptions'!F6+'3_Assumptions'!F31),"n.a.") -> 1045.854
C9: Total revenue | D9: =IF(AND(ISNUMBER(データ_財務!F216)),データ_財務!F216/1000000,"n.a.") -> 18344 | E9: =IF(AND(ISNUMBER(データ_財務!F205)),データ_財務!F205/1000000,"n.a.") -> 20028 | F9: =IF(AND(ISNUMBER(データ_財務!F180)),データ_財務!F180/1000000,"n.a.") -> 17519 | G9: =IF(AND(ISNUMBER(データ_財務!F178)),データ_財務!F178/1000000,"n.a.") -> 15641 | H9: =IF(AND(ISNUMBER(データ_財務!F179)),データ_財務!F179/1000000,"n.a.") -> 17682 | I9: =IF(AND(ISNUMBER('3_セグメント売上'!I6),ISNUMBER('3_セグメント売上'!I7),ISNUMBER('3_セグメント売上'!I8)),'3_セグメント売上'!I6+'3_セグメント売上'!I7+'3_セグメント売上'!I8,"n.a.") -> 22387.166 | J9: =IF(AND(ISNUMBER('3_セグメント売上'!J6),ISNUMBER('3_セグメント売上'!J7),ISNUMBER('3_セグメント売上'!J8)),'3_セグメント売上'!J6+'3_セグメント売上'!J7+'3_セグメント売上'!J8,"n.a.") -> 23954.268 | K9: =IF(AND(ISNUMBER('3_セグメント売上'!K6),ISNUMBER('3_セグメント売上'!K7),ISNUMBER('3_セグメント売上'!K8)),'3_セグメント売上'!K6+'3_セグメント売上'!K7+'3_セグメント売上'!K8,"n.a.") -> 24912.438
C11: 内数を除いた抽出売上合計 | D11: =IF(AND(ISNUMBER(D6),ISNUMBER(D7),ISNUMBER(D8)),D6+D7+D8,"n.a.") -> 18344 | E11: =IF(AND(ISNUMBER(E6),ISNUMBER(E7),ISNUMBER(E8)),E6+E7+E8,"n.a.") -> 20028 | F11: =IF(AND(ISNUMBER(F6),ISNUMBER(F7),ISNUMBER(F8)),F6+F7+F8,"n.a.") -> 17519 | G11: =IF(AND(ISNUMBER(G6),ISNUMBER(G7),ISNUMBER(G8)),G6+G7+G8,"n.a.") -> 15641 | H11: =IF(AND(ISNUMBER(H6),ISNUMBER(H7),ISNUMBER(H8)),H6+H7+H8,"n.a.") -> 17682 | I11: =IF(AND(ISNUMBER('3_セグメント売上'!I6),ISNUMBER('3_セグメント売上'!I7),ISNUMBER('3_セグメント売上'!I8)),'3_セグメント売上'!I6+'3_セグメント売上'!I7+'3_セグメント売上'!I8,"n.a.") -> 22387.166 | J11: =IF(AND(ISNUMBER('3_セグメント売上'!J6),ISNUMBER('3_セグメント売上'!J7),ISNUMBER('3_セグメント売上'!J8)),'3_セグメント売上'!J6+'3_セグメント売上'!J7+'3_セグメント売上'!J8,"n.a.") -> 23954.268 | K11: =IF(AND(ISNUMBER('3_セグメント売上'!K6),ISNUMBER('3_セグメント売上'!K7),ISNUMBER('3_セグメント売上'!K8)),'3_セグメント売上'!K6+'3_セグメント売上'!K7+'3_セグメント売上'!K8,"n.a.") -> 24912.438
C14: 報告セグメントAnalog・Embedded Processing＋Other（報告セグメント外の事業）。10-K表示名

Sheet 3_地域別売上
C2: TEXAS INSTRUMENTS INC 地域別売上
C4: USD 百万単位。年次・連結実績。n.a. = 未抽出／対象外
C5: 項目 | D5: 2021-12-31 A | E5: 2022-12-31 A | F5: 2023-12-31 A | G5: 2024-12-31 A | H5: 2025-12-31 A | I5: 2026-12-31 E | J5: 2027-12-31 E | K5: 2028-12-31 E
C6: United States | D6: =IF(AND(ISNUMBER(データ_財務!F217)),データ_財務!F217/1000000,"n.a.") -> 6237 | E6: =IF(AND(ISNUMBER(データ_財務!F206)),データ_財務!F206/1000000,"n.a.") -> 6609 | F6: =IF(AND(ISNUMBER(データ_財務!F183)),データ_財務!F183/1000000,"n.a.") -> 5814 | G6: =IF(AND(ISNUMBER(データ_財務!F182)),データ_財務!F182/1000000,"n.a.") -> 5957 | H6: =IF(AND(ISNUMBER(データ_財務!F181)),データ_財務!F181/1000000,"n.a.") -> 6763 | I6: =IF(AND(ISNUMBER('3_Forecast'!I8),ISNUMBER('3_Assumptions'!D33),ISNUMBER('3_Assumptions'!D34),ISNUMBER('3_Assumptions'!D35),ISNUMBER('3_Assumptions'!D36),ISNUMBER('3_Assumptions'!D37),ISNUMBER('3_Assumptions'!D38),'3_Assumptions'!D33>=0,'3_Assumptions'!D34>=0,'3_Assumptions'!D35>=0,'3_Assumptions'!D36>=0,'3_Assumptions'!D37>=0,'3_Assumptions'!D38>=0,('3_Assumptions'!D33+'3_Assumptions'!D34+'3_Assumptions'!D35+'3_Assumptions'!D36+'3_Assumptions'!D37+'3_Assumptions'!D38)>0),'3_Forecast'!I8*'3_Assumptions'!D33/('3_Assumptions'!D33+'3_Assumptions'!D34+'3_Assumptions'!D35+'3_Assumptions'!D36+'3_Assumptions'!D37+'3_Assumptions'!D38),"n.a.") -> 8562.6289 | J6: =IF(AND(ISNUMBER('3_Forecast'!J8),ISNUMBER('3_Assumptions'!E33),ISNUMBER('3_Assumptions'!E34),ISNUMBER('3_Assumptions'!E35),ISNUMBER('3_Assumptions'!E36),ISNUMBER('3_Assumptions'!E37),ISNUMBER('3_Assumptions'!E38),'3_Assumptions'!E33>=0,'3_Assumptions'!E34>=0,'3_Assumptions'!E35>=0,'3_Assumptions'!E36>=0,'3_Assumptions'!E37>=0,'3_Assumptions'!E38>=0,('3_Assumptions'!E33+'3_Assumptions'!E34+'3_Assumptions'!E35+'3_Assumptions'!E36+'3_Assumptions'!E37+'3_Assumptions'!E38)>0),'3_Forecast'!J8*'3_Assumptions'!E33/('3_Assumptions'!E33+'3_Assumptions'!E34+'3_Assumptions'!E35+'3_Assumptions'!E36+'3_Assumptions'!E37+'3_Assumptions'!E38),"n.a.") -> 9162.0129 | K6: =IF(AND(ISNUMBER('3_Forecast'!K8),ISNUMBER('3_Assumptions'!F33),ISNUMBER('3_Assumptions'!F34),ISNUMBER('3_Assumptions'!F35),ISNUMBER('3_Assumptions'!F36),ISNUMBER('3_Assumptions'!F37),ISNUMBER('3_Assumptions'!F38),'3_Assumptions'!F33>=0,'3_Assumptions'!F34>=0,'3_Assumptions'!F35>=0,'3_Assumptions'!F36>=0,'3_Assumptions'!F37>=0,'3_Assumptions'!F38>=0,('3_Assumptions'!F33+'3_Assumptions'!F34+'3_Assumptions'!F35+'3_Assumptions'!F36+'3_Assumptions'!F37+'3_Assumptions'!F38)>0),'3_Forecast'!K8*'3_Assumptions'!F33/('3_Assumptions'!F33+'3_Assumptions'!F34+'3_Assumptions'!F35+'3_Assumptions'!F36+'3_Assumptions'!F37+'3_Assumptions'!F38),"n.a.") -> 9528.4934
C7: China | D7: =IF(AND(ISNUMBER(データ_財務!F218)),データ_財務!F218/1000000,"n.a.") -> 4586 | E7: =IF(AND(ISNUMBER(データ_財務!F207)),データ_財務!F207/1000000,"n.a.") -> 4807 | F7: =IF(AND(ISNUMBER(データ_財務!F186)),データ_財務!F186/1000000,"n.a.") -> 3293 | G7: =IF(AND(ISNUMBER(データ_財務!F185)),データ_財務!F185/1000000,"n.a.") -> 3012 | H7: =IF(AND(ISNUMBER(データ_財務!F184)),データ_財務!F184/1000000,"n.a.") -> 3781 | I7: =IF(AND(ISNUMBER('3_Forecast'!I8),ISNUMBER('3_Assumptions'!D33),ISNUMBER('3_Assumptions'!D34),ISNUMBER('3_Assumptions'!D35),ISNUMBER('3_Assumptions'!D36),ISNUMBER('3_Assumptions'!D37),ISNUMBER('3_Assumptions'!D38),'3_Assumptions'!D33>=0,'3_Assumptions'!D34>=0,'3_Assumptions'!D35>=0,'3_Assumptions'!D36>=0,'3_Assumptions'!D37>=0,'3_Assumptions'!D38>=0,('3_Assumptions'!D33+'3_Assumptions'!D34+'3_Assumptions'!D35+'3_Assumptions'!D36+'3_Assumptions'!D37+'3_Assumptions'!D38)>0),'3_Forecast'!I8*'3_Assumptions'!D34/('3_Assumptions'!D33+'3_Assumptions'!D34+'3_Assumptions'!D35+'3_Assumptions'!D36+'3_Assumptions'!D37+'3_Assumptions'!D38),"n.a.") -> 4787.1211 | J7: =IF(AND(ISNUMBER('3_Forecast'!J8),ISNUMBER('3_Assumptions'!E33),ISNUMBER('3_Assumptions'!E34),ISNUMBER('3_Assumptions'!E35),ISNUMBER('3_Assumptions'!E36),ISNUMBER('3_Assumptions'!E37),ISNUMBER('3_Assumptions'!E38),'3_Assumptions'!E33>=0,'3_Assumptions'!E34>=0,'3_Assumptions'!E35>=0,'3_Assumptions'!E36>=0,'3_Assumptions'!E37>=0,'3_Assumptions'!E38>=0,('3_Assumptions'!E33+'3_Assumptions'!E34+'3_Assumptions'!E35+'3_Assumptions'!E36+'3_Assumptions'!E37+'3_Assumptions'!E38)>0),'3_Forecast'!J8*'3_Assumptions'!E34/('3_Assumptions'!E33+'3_Assumptions'!E34+'3_Assumptions'!E35+'3_Assumptions'!E36+'3_Assumptions'!E37+'3_Assumptions'!E38),"n.a.") -> 5122.2195 | K7: =IF(AND(ISNUMBER('3_Forecast'!K8),ISNUMBER('3_Assumptions'!F33),ISNUMBER('3_Assumptions'!F34),ISNUMBER('3_Assumptions'!F35),ISNUMBER('3_Assumptions'!F36),ISNUMBER('3_Assumptions'!F37),ISNUMBER('3_Assumptions'!F38),'3_Assumptions'!F33>=0,'3_Assumptions'!F34>=0,'3_Assumptions'!F35>=0,'3_Assumptions'!F36>=0,'3_Assumptions'!F37>=0,'3_Assumptions'!F38>=0,('3_Assumptions'!F33+'3_Assumptions'!F34+'3_Assumptions'!F35+'3_Assumptions'!F36+'3_Assumptions'!F37+'3_Assumptions'!F38)>0),'3_Forecast'!K8*'3_Assumptions'!F34/('3_Assumptions'!F33+'3_Assumptions'!F34+'3_Assumptions'!F35+'3_Assumptions'!F36+'3_Assumptions'!F37+'3_Assumptions'!F38),"n.a.") -> 5327.1083
C8: Rest of Asia | D8: =IF(AND(ISNUMBER(データ_財務!F219)),データ_財務!F219/1000000,"n.a.") -> 2018 | E8: =IF(AND(ISNUMBER(データ_財務!F208)),データ_財務!F208/1000000,"n.a.") -> 2003 | F8: =IF(AND(ISNUMBER(データ_財務!F189)),データ_財務!F189/1000000,"n.a.") -> 1721 | G8: =IF(AND(ISNUMBER(データ_財務!F188)),データ_財務!F188/1000000,"n.a.") -> 1681 | H8: =IF(AND(ISNUMBER(データ_財務!F187)),データ_財務!F187/1000000,"n.a.") -> 1887 | I8: =IF(AND(ISNUMBER('3_Forecast'!I8),ISNUMBER('3_Assumptions'!D33),ISNUMBER('3_Assumptions'!D34),ISNUMBER('3_Assumptions'!D35),ISNUMBER('3_Assumptions'!D36),ISNUMBER('3_Assumptions'!D37),ISNUMBER('3_Assumptions'!D38),'3_Assumptions'!D33>=0,'3_Assumptions'!D34>=0,'3_Assumptions'!D35>=0,'3_Assumptions'!D36>=0,'3_Assumptions'!D37>=0,'3_Assumptions'!D38>=0,('3_Assumptions'!D33+'3_Assumptions'!D34+'3_Assumptions'!D35+'3_Assumptions'!D36+'3_Assumptions'!D37+'3_Assumptions'!D38)>0),'3_Forecast'!I8*'3_Assumptions'!D35/('3_Assumptions'!D33+'3_Assumptions'!D34+'3_Assumptions'!D35+'3_Assumptions'!D36+'3_Assumptions'!D37+'3_Assumptions'!D38),"n.a.") -> 2389.1292 | J8: =IF(AND(ISNUMBER('3_Forecast'!J8),ISNUMBER('3_Assumptions'!E33),ISNUMBER('3_Assumptions'!E34),ISNUMBER('3_Assumptions'!E35),ISNUMBER('3_Assumptions'!E36),ISNUMBER('3_Assumptions'!E37),ISNUMBER('3_Assumptions'!E38),'3_Assumptions'!E33>=0,'3_Assumptions'!E34>=0,'3_Assumptions'!E35>=0,'3_Assumptions'!E36>=0,'3_Assumptions'!E37>=0,'3_Assumptions'!E38>=0,('3_Assumptions'!E33+'3_Assumptions'!E34+'3_Assumptions'!E35+'3_Assumptions'!E36+'3_Assumptions'!E37+'3_Assumptions'!E38)>0),'3_Forecast'!J8*'3_Assumptions'!E35/('3_Assumptions'!E33+'3_Assumptions'!E34+'3_Assumptions'!E35+'3_Assumptions'!E36+'3_Assumptions'!E37+'3_Assumptions'!E38),"n.a.") -> 2556.3682 | K8: =IF(AND(ISNUMBER('3_Forecast'!K8),ISNUMBER('3_Assumptions'!F33),ISNUMBER('3_Assumptions'!F34),ISNUMBER('3_Assumptions'!F35),ISNUMBER('3_Assumptions'!F36),ISNUMBER('3_Assumptions'!F37),ISNUMBER('3_Assumptions'!F38),'3_Assumptions'!F33>=0,'3_Assumptions'!F34>=0,'3_Assumptions'!F35>=0,'3_Assumptions'!F36>=0,'3_Assumptions'!F37>=0,'3_Assumptions'!F38>=0,('3_Assumptions'!F33+'3_Assumptions'!F34+'3_Assumptions'!F35+'3_Assumptions'!F36+'3_Assumptions'!F37+'3_Assumptions'!F38)>0),'3_Forecast'!K8*'3_Assumptions'!F35/('3_Assumptions'!F33+'3_Assumptions'!F34+'3_Assumptions'!F35+'3_Assumptions'!F36+'3_Assumptions'!F37+'3_Assumptions'!F38),"n.a.") -> 2658.623
C9: Europe, Middle East and Africa | D9: =IF(AND(ISNUMBER(データ_財務!F220)),データ_財務!F220/1000000,"n.a.") -> 3852 | E9: =IF(AND(ISNUMBER(データ_財務!F209)),データ_財務!F209/1000000,"n.a.") -> 4807 | F9: =IF(AND(ISNUMBER(データ_財務!F192)),データ_財務!F192/1000000,"n.a.") -> 4642 | G9: =IF(AND(ISNUMBER(データ_財務!F191)),データ_財務!F191/1000000,"n.a.") -> 3519 | H9: =IF(AND(ISNUMBER(データ_財務!F190)),データ_財務!F190/1000000,"n.a.") -> 3747 | I9: =IF(AND(ISNUMBER('3_Forecast'!I8),ISNUMBER('3_Assumptions'!D33),ISNUMBER('3_Assumptions'!D34),ISNUMBER('3_Assumptions'!D35),ISNUMBER('3_Assumptions'!D36),ISNUMBER('3_Assumptions'!D37),ISNUMBER('3_Assumptions'!D38),'3_Assumptions'!D33>=0,'3_Assumptions'!D34>=0,'3_Assumptions'!D35>=0,'3_Assumptions'!D36>=0,'3_Assumptions'!D37>=0,'3_Assumptions'!D38>=0,('3_Assumptions'!D33+'3_Assumptions'!D34+'3_Assumptions'!D35+'3_Assumptions'!D36+'3_Assumptions'!D37+'3_Assumptions'!D38)>0),'3_Forecast'!I8*'3_Assumptions'!D36/('3_Assumptions'!D33+'3_Assumptions'!D34+'3_Assumptions'!D35+'3_Assumptions'!D36+'3_Assumptions'!D37+'3_Assumptions'!D38),"n.a.") -> 4744.0737 | J9: =IF(AND(ISNUMBER('3_Forecast'!J8),ISNUMBER('3_Assumptions'!E33),ISNUMBER('3_Assumptions'!E34),ISNUMBER('3_Assumptions'!E35),ISNUMBER('3_Assumptions'!E36),ISNUMBER('3_Assumptions'!E37),ISNUMBER('3_Assumptions'!E38),'3_Assumptions'!E33>=0,'3_Assumptions'!E34>=0,'3_Assumptions'!E35>=0,'3_Assumptions'!E36>=0,'3_Assumptions'!E37>=0,'3_Assumptions'!E38>=0,('3_Assumptions'!E33+'3_Assumptions'!E34+'3_Assumptions'!E35+'3_Assumptions'!E36+'3_Assumptions'!E37+'3_Assumptions'!E38)>0),'3_Forecast'!J8*'3_Assumptions'!E36/('3_Assumptions'!E33+'3_Assumptions'!E34+'3_Assumptions'!E35+'3_Assumptions'!E36+'3_Assumptions'!E37+'3_Assumptions'!E38),"n.a.") -> 5076.1588 | K9: =IF(AND(ISNUMBER('3_Forecast'!K8),ISNUMBER('3_Assumptions'!F33),ISNUMBER('3_Assumptions'!F34),ISNUMBER('3_Assumptions'!F35),ISNUMBER('3_Assumptions'!F36),ISNUMBER('3_Assumptions'!F37),ISNUMBER('3_Assumptions'!F38),'3_Assumptions'!F33>=0,'3_Assumptions'!F34>=0,'3_Assumptions'!F35>=0,'3_Assumptions'!F36>=0,'3_Assumptions'!F37>=0,'3_Assumptions'!F38>=0,('3_Assumptions'!F33+'3_Assumptions'!F34+'3_Assumptions'!F35+'3_Assumptions'!F36+'3_Assumptions'!F37+'3_Assumptions'!F38)>0),'3_Forecast'!K8*'3_Assumptions'!F36/('3_Assumptions'!F33+'3_Assumptions'!F34+'3_Assumptions'!F35+'3_Assumptions'!F36+'3_Assumptions'!F37+'3_Assumptions'!F38),"n.a.") -> 5279.2052
C10: Japan | D10: =IF(AND(ISNUMBER(データ_財務!F221)),データ_財務!F221/1000000,"n.a.") -> 1468 | E10: =IF(AND(ISNUMBER(データ_財務!F210)),データ_財務!F210/1000000,"n.a.") -> 1602 | F10: =IF(AND(ISNUMBER(データ_財務!F195)),データ_財務!F195/1000000,"n.a.") -> 1782 | G10: =IF(AND(ISNUMBER(データ_財務!F194)),データ_財務!F194/1000000,"n.a.") -> 1212 | H10: =IF(AND(ISNUMBER(データ_財務!F193)),データ_財務!F193/1000000,"n.a.") -> 1173 | I10: =IF(AND(ISNUMBER('3_Forecast'!I8),ISNUMBER('3_Assumptions'!D33),ISNUMBER('3_Assumptions'!D34),ISNUMBER('3_Assumptions'!D35),ISNUMBER('3_Assumptions'!D36),ISNUMBER('3_Assumptions'!D37),ISNUMBER('3_Assumptions'!D38),'3_Assumptions'!D33>=0,'3_Assumptions'!D34>=0,'3_Assumptions'!D35>=0,'3_Assumptions'!D36>=0,'3_Assumptions'!D37>=0,'3_Assumptions'!D38>=0,('3_Assumptions'!D33+'3_Assumptions'!D34+'3_Assumptions'!D35+'3_Assumptions'!D36+'3_Assumptions'!D37+'3_Assumptions'!D38)>0),'3_Forecast'!I8*'3_Assumptions'!D37/('3_Assumptions'!D33+'3_Assumptions'!D34+'3_Assumptions'!D35+'3_Assumptions'!D36+'3_Assumptions'!D37+'3_Assumptions'!D38),"n.a.") -> 1485.1344 | J10: =IF(AND(ISNUMBER('3_Forecast'!J8),ISNUMBER('3_Assumptions'!E33),ISNUMBER('3_Assumptions'!E34),ISNUMBER('3_Assumptions'!E35),ISNUMBER('3_Assumptions'!E36),ISNUMBER('3_Assumptions'!E37),ISNUMBER('3_Assumptions'!E38),'3_Assumptions'!E33>=0,'3_Assumptions'!E34>=0,'3_Assumptions'!E35>=0,'3_Assumptions'!E36>=0,'3_Assumptions'!E37>=0,'3_Assumptions'!E38>=0,('3_Assumptions'!E33+'3_Assumptions'!E34+'3_Assumptions'!E35+'3_Assumptions'!E36+'3_Assumptions'!E37+'3_Assumptions'!E38)>0),'3_Forecast'!J8*'3_Assumptions'!E37/('3_Assumptions'!E33+'3_Assumptions'!E34+'3_Assumptions'!E35+'3_Assumptions'!E36+'3_Assumptions'!E37+'3_Assumptions'!E38),"n.a.") -> 1589.0938 | K10: =IF(AND(ISNUMBER('3_Forecast'!K8),ISNUMBER('3_Assumptions'!F33),ISNUMBER('3_Assumptions'!F34),ISNUMBER('3_Assumptions'!F35),ISNUMBER('3_Assumptions'!F36),ISNUMBER('3_Assumptions'!F37),ISNUMBER('3_Assumptions'!F38),'3_Assumptions'!F33>=0,'3_Assumptions'!F34>=0,'3_Assumptions'!F35>=0,'3_Assumptions'!F36>=0,'3_Assumptions'!F37>=0,'3_Assumptions'!F38>=0,('3_Assumptions'!F33+'3_Assumptions'!F34+'3_Assumptions'!F35+'3_Assumptions'!F36+'3_Assumptions'!F37+'3_Assumptions'!F38)>0),'3_Forecast'!K8*'3_Assumptions'!F37/('3_Assumptions'!F33+'3_Assumptions'!F34+'3_Assumptions'!F35+'3_Assumptions'!F36+'3_Assumptions'!F37+'3_Assumptions'!F38),"n.a.") -> 1652.6575
C11: Rest of world | D11: =IF(AND(ISNUMBER(データ_財務!F222)),データ_財務!F222/1000000,"n.a.") -> 183 | E11: =IF(AND(ISNUMBER(データ_財務!F211)),データ_財務!F211/1000000,"n.a.") -> 200 | F11: =IF(AND(ISNUMBER(データ_財務!F198)),データ_財務!F198/1000000,"n.a.") -> 267 | G11: =IF(AND(ISNUMBER(データ_財務!F197)),データ_財務!F197/1000000,"n.a.") -> 260 | H11: =IF(AND(ISNUMBER(データ_財務!F196)),データ_財務!F196/1000000,"n.a.") -> 331 | I11: =IF(AND(ISNUMBER('3_Forecast'!I8),ISNUMBER('3_Assumptions'!D33),ISNUMBER('3_Assumptions'!D34),ISNUMBER('3_Assumptions'!D35),ISNUMBER('3_Assumptions'!D36),ISNUMBER('3_Assumptions'!D37),ISNUMBER('3_Assumptions'!D38),'3_Assumptions'!D33>=0,'3_Assumptions'!D34>=0,'3_Assumptions'!D35>=0,'3_Assumptions'!D36>=0,'3_Assumptions'!D37>=0,'3_Assumptions'!D38>=0,('3_Assumptions'!D33+'3_Assumptions'!D34+'3_Assumptions'!D35+'3_Assumptions'!D36+'3_Assumptions'!D37+'3_Assumptions'!D38)>0),'3_Forecast'!I8*'3_Assumptions'!D38/('3_Assumptions'!D33+'3_Assumptions'!D34+'3_Assumptions'!D35+'3_Assumptions'!D36+'3_Assumptions'!D37+'3_Assumptions'!D38),"n.a.") -> 419.07883 | J11: =IF(AND(ISNUMBER('3_Forecast'!J8),ISNUMBER('3_Assumptions'!E33),ISNUMBER('3_Assumptions'!E34),ISNUMBER('3_Assumptions'!E35),ISNUMBER('3_Assumptions'!E36),ISNUMBER('3_Assumptions'!E37),ISNUMBER('3_Assumptions'!E38),'3_Assumptions'!E33>=0,'3_Assumptions'!E34>=0,'3_Assumptions'!E35>=0,'3_Assumptions'!E36>=0,'3_Assumptions'!E37>=0,'3_Assumptions'!E38>=0,('3_Assumptions'!E33+'3_Assumptions'!E34+'3_Assumptions'!E35+'3_Assumptions'!E36+'3_Assumptions'!E37+'3_Assumptions'!E38)>0),'3_Forecast'!J8*'3_Assumptions'!E38/('3_Assumptions'!E33+'3_Assumptions'!E34+'3_Assumptions'!E35+'3_Assumptions'!E36+'3_Assumptions'!E37+'3_Assumptions'!E38),"n.a.") -> 448.41435 | K11: =IF(AND(ISNUMBER('3_Forecast'!K8),ISNUMBER('3_Assumptions'!F33),ISNUMBER('3_Assumptions'!F34),ISNUMBER('3_Assumptions'!F35),ISNUMBER('3_Assumptions'!F36),ISNUMBER('3_Assumptions'!F37),ISNUMBER('3_Assumptions'!F38),'3_Assumptions'!F33>=0,'3_Assumptions'!F34>=0,'3_Assumptions'!F35>=0,'3_Assumptions'!F36>=0,'3_Assumptions'!F37>=0,'3_Assumptions'!F38>=0,('3_Assumptions'!F33+'3_Assumptions'!F34+'3_Assumptions'!F35+'3_Assumptions'!F36+'3_Assumptions'!F37+'3_Assumptions'!F38)>0),'3_Forecast'!K8*'3_Assumptions'!F38/('3_Assumptions'!F33+'3_Assumptions'!F34+'3_Assumptions'!F35+'3_Assumptions'!F36+'3_Assumptions'!F37+'3_Assumptions'!F38),"n.a.") -> 466.35093
C12: Total revenue | D12: =IF(AND(ISNUMBER(データ_財務!F223)),データ_財務!F223/1000000,"n.a.") -> 18344 | E12: =IF(AND(ISNUMBER(データ_財務!F212)),データ_財務!F212/1000000,"n.a.") -> 20028 | F12: =IF(AND(ISNUMBER(データ_財務!F201)),データ_財務!F201/1000000,"n.a.") -> 17519 | G12: =IF(AND(ISNUMBER(データ_財務!F200)),データ_財務!F200/1000000,"n.a.") -> 15641 | H12: =IF(AND(ISNUMBER(データ_財務!F199)),データ_財務!F199/1000000,"n.a.") -> 17682 | I12: ='3_Forecast'!I8 -> 22387.166 | J12: ='3_Forecast'!J8 -> 23954.268 | K12: ='3_Forecast'!K8 -> 24912.438
C14: 内数を除いた抽出売上合計 | D14: =IF(AND(ISNUMBER(D6),ISNUMBER(D7),ISNUMBER(D8),ISNUMBER(D9),ISNUMBER(D10),ISNUMBER(D11)),D6+D7+D8+D9+D10+D11,"n.a.") -> 18344 | E14: =IF(AND(ISNUMBER(E6),ISNUMBER(E7),ISNUMBER(E8),ISNUMBER(E9),ISNUMBER(E10),ISNUMBER(E11)),E6+E7+E8+E9+E10+E11,"n.a.") -> 20028 | F14: =IF(AND(ISNUMBER(F6),ISNUMBER(F7),ISNUMBER(F8),ISNUMBER(F9),ISNUMBER(F10),ISNUMBER(F11)),F6+F7+F8+F9+F10+F11,"n.a.") -> 17519 | G14: =IF(AND(ISNUMBER(G6),ISNUMBER(G7),ISNUMBER(G8),ISNUMBER(G9),ISNUMBER(G10),ISNUMBER(G11)),G6+G7+G8+G9+G10+G11,"n.a.") -> 15641 | H14: =IF(AND(ISNUMBER(H6),ISNUMBER(H7),ISNUMBER(H8),ISNUMBER(H9),ISNUMBER(H10),ISNUMBER(H11)),H6+H7+H8+H9+H10+H11,"n.a.") -> 17682 | I14: =IF(AND(ISNUMBER(I6),ISNUMBER(I7),ISNUMBER(I8),ISNUMBER(I9),ISNUMBER(I10),ISNUMBER(I11)),I6+I7+I8+I9+I10+I11,"n.a.") -> 22387.166 | J14: =IF(AND(ISNUMBER(J6),ISNUMBER(J7),ISNUMBER(J8),ISNUMBER(J9),ISNUMBER(J10),ISNUMBER(J11)),J6+J7+J8+J9+J10+J11,"n.a.") -> 23954.268 | K14: =IF(AND(ISNUMBER(K6),ISNUMBER(K7),ISNUMBER(K8),ISNUMBER(K9),ISNUMBER(K10),ISNUMBER(K11)),K6+K7+K8+K9+K10+K11,"n.a.") -> 24912.438
C17: TI推計：エンドカスタマー本社所在地ベース（出荷先ベースとは別表・混在させない）。内数行なし（ドイツは脚注の比率のみ）

Sheet 3_Forecast
C2: TEXAS INSTRUMENTS INC Forecast
C4: USD 百万単位。年次・連結実績。n.a. = 未抽出／対象外
C5: 項目 | D5: 2021-12-31 A | E5: 2022-12-31 A | F5: 2023-12-31 A | G5: 2024-12-31 A | H5: 2025-12-31 A | I5: 2026-12-31 E | J5: 2027-12-31 E | K5: 2028-12-31 E
C6: 予測期間の日数 | I6: 365 | J6: 365 | K6: 366
